2024-06-06 05:31:11,025 - discord.client - ERROR - Attempting a reconnect in 287.71s
Traceback (most recent call last):
  File "/usr/lib/python3/dist-packages/aiohttp/connector.py", line 1152, in _create_direct_connection
    hosts = await asyncio.shield(host_resolved)
            ^^^^^^^^^^^^^^^^^^^^^^^^^^^^^^^^^^^
  File "/usr/lib/python3/dist-packages/aiohttp/connector.py", line 874, in _resolve_host
    addrs = await self._resolver.resolve(host, port, family=self._family)
            ^^^^^^^^^^^^^^^^^^^^^^^^^^^^^^^^^^^^^^^^^^^^^^^^^^^^^^^^^^^^^
  File "/usr/lib/python3/dist-packages/aiohttp/resolver.py", line 33, in resolve
    infos = await self._loop.getaddrinfo(
            ^^^^^^^^^^^^^^^^^^^^^^^^^^^^^
  File "/usr/lib/python3.11/asyncio/base_events.py", line 867, in getaddrinfo
    return await self.run_in_executor(
           ^^^^^^^^^^^^^^^^^^^^^^^^^^^
  File "/usr/lib/python3.11/concurrent/futures/thread.py", line 58, in run
    result = self.fn(*self.args, **self.kwargs)
             ^^^^^^^^^^^^^^^^^^^^^^^^^^^^^^^^^^
  File "/usr/lib/python3.11/socket.py", line 962, in getaddrinfo
    for res in _socket.getaddrinfo(host, port, family, type, proto, flags):
               ^^^^^^^^^^^^^^^^^^^^^^^^^^^^^^^^^^^^^^^^^^^^^^^^^^^^^^^^^^^
socket.gaierror: [Errno -3] Temporary failure in name resolution

The above exception was the direct cause of the following exception:

Traceback (most recent call last):
  File "/usr/lib/python3/dist-packages/discord/client.py", line 656, in connect
    self.ws = await asyncio.wait_for(coro, timeout=60.0)
              ^^^^^^^^^^^^^^^^^^^^^^^^^^^^^^^^^^^^^^^^^^
  File "/usr/lib/python3.11/asyncio/tasks.py", line 479, in wait_for
    return fut.result()
           ^^^^^^^^^^^^
  File "/usr/lib/python3/dist-packages/discord/gateway.py", line 372, in from_client
    socket = await client.http.ws_connect(str(url))
             ^^^^^^^^^^^^^^^^^^^^^^^^^^^^^^^^^^^^^^
  File "/usr/lib/python3/dist-packages/discord/http.py", line 536, in ws_connect
    return await self.__session.ws_connect(url, **kwargs)
           ^^^^^^^^^^^^^^^^^^^^^^^^^^^^^^^^^^^^^^^^^^^^^^
  File "/usr/lib/python3/dist-packages/aiohttp/client.py", line 779, in _ws_connect
    resp = await self.request(
           ^^^^^^^^^^^^^^^^^^^
  File "/usr/lib/python3/dist-packages/aiohttp/client.py", line 536, in _request
    conn = await self._connector.connect(
           ^^^^^^^^^^^^^^^^^^^^^^^^^^^^^^
  File "/usr/lib/python3/dist-packages/aiohttp/connector.py", line 540, in connect
    proto = await self._create_connection(req, traces, timeout)
            ^^^^^^^^^^^^^^^^^^^^^^^^^^^^^^^^^^^^^^^^^^^^^^^^^^^
  File "/usr/lib/python3/dist-packages/aiohttp/connector.py", line 901, in _create_connection
    _, proto = await self._create_direct_connection(req, traces, timeout)
               ^^^^^^^^^^^^^^^^^^^^^^^^^^^^^^^^^^^^^^^^^^^^^^^^^^^^^^^^^^
  File "/usr/lib/python3/dist-packages/aiohttp/connector.py", line 1166, in _create_direct_connection
    raise ClientConnectorError(req.connection_key, exc) from exc
aiohttp.client_exceptions.ClientConnectorError: Cannot connect to host gateway-us-east1-c.discord.gg:443 ssl:default [Temporary failure in name resolution]
2024-06-06 05:31:39,155 - discord_bot - ERROR - Failed to purge or send message in people-in-studio: Cannot connect to host discord.com:443 ssl:default [Temporary failure in name resolution]
2024-06-06 05:33:39,159 - discord_bot - ERROR - Failed to purge or send message in people-in-studio: Cannot connect to host discord.com:443 ssl:default [Temporary failure in name resolution]
2024-06-06 05:35:39,162 - discord_bot - ERROR - Failed to purge or send message in people-in-studio: Cannot connect to host discord.com:443 ssl:default [Temporary failure in name resolution]
2024-06-06 05:35:58,779 - discord.client - ERROR - Attempting a reconnect in 212.66s
Traceback (most recent call last):
  File "/usr/lib/python3/dist-packages/aiohttp/connector.py", line 1152, in _create_direct_connection
    hosts = await asyncio.shield(host_resolved)
            ^^^^^^^^^^^^^^^^^^^^^^^^^^^^^^^^^^^
  File "/usr/lib/python3/dist-packages/aiohttp/connector.py", line 874, in _resolve_host
    addrs = await self._resolver.resolve(host, port, family=self._family)
            ^^^^^^^^^^^^^^^^^^^^^^^^^^^^^^^^^^^^^^^^^^^^^^^^^^^^^^^^^^^^^
  File "/usr/lib/python3/dist-packages/aiohttp/resolver.py", line 33, in resolve
    infos = await self._loop.getaddrinfo(
            ^^^^^^^^^^^^^^^^^^^^^^^^^^^^^
  File "/usr/lib/python3.11/asyncio/base_events.py", line 867, in getaddrinfo
    return await self.run_in_executor(
           ^^^^^^^^^^^^^^^^^^^^^^^^^^^
  File "/usr/lib/python3.11/concurrent/futures/thread.py", line 58, in run
    result = self.fn(*self.args, **self.kwargs)
             ^^^^^^^^^^^^^^^^^^^^^^^^^^^^^^^^^^
  File "/usr/lib/python3.11/socket.py", line 962, in getaddrinfo
    for res in _socket.getaddrinfo(host, port, family, type, proto, flags):
               ^^^^^^^^^^^^^^^^^^^^^^^^^^^^^^^^^^^^^^^^^^^^^^^^^^^^^^^^^^^
socket.gaierror: [Errno -3] Temporary failure in name resolution

The above exception was the direct cause of the following exception:

Traceback (most recent call last):
  File "/usr/lib/python3/dist-packages/discord/client.py", line 656, in connect
    self.ws = await asyncio.wait_for(coro, timeout=60.0)
              ^^^^^^^^^^^^^^^^^^^^^^^^^^^^^^^^^^^^^^^^^^
  File "/usr/lib/python3.11/asyncio/tasks.py", line 479, in wait_for
    return fut.result()
           ^^^^^^^^^^^^
  File "/usr/lib/python3/dist-packages/discord/gateway.py", line 372, in from_client
    socket = await client.http.ws_connect(str(url))
             ^^^^^^^^^^^^^^^^^^^^^^^^^^^^^^^^^^^^^^
  File "/usr/lib/python3/dist-packages/discord/http.py", line 536, in ws_connect
    return await self.__session.ws_connect(url, **kwargs)
           ^^^^^^^^^^^^^^^^^^^^^^^^^^^^^^^^^^^^^^^^^^^^^^
  File "/usr/lib/python3/dist-packages/aiohttp/client.py", line 779, in _ws_connect
    resp = await self.request(
           ^^^^^^^^^^^^^^^^^^^
  File "/usr/lib/python3/dist-packages/aiohttp/client.py", line 536, in _request
    conn = await self._connector.connect(
           ^^^^^^^^^^^^^^^^^^^^^^^^^^^^^^
  File "/usr/lib/python3/dist-packages/aiohttp/connector.py", line 540, in connect
    proto = await self._create_connection(req, traces, timeout)
            ^^^^^^^^^^^^^^^^^^^^^^^^^^^^^^^^^^^^^^^^^^^^^^^^^^^
  File "/usr/lib/python3/dist-packages/aiohttp/connector.py", line 901, in _create_connection
    _, proto = await self._create_direct_connection(req, traces, timeout)
               ^^^^^^^^^^^^^^^^^^^^^^^^^^^^^^^^^^^^^^^^^^^^^^^^^^^^^^^^^^
  File "/usr/lib/python3/dist-packages/aiohttp/connector.py", line 1166, in _create_direct_connection
    raise ClientConnectorError(req.connection_key, exc) from exc
aiohttp.client_exceptions.ClientConnectorError: Cannot connect to host gateway-us-east1-c.discord.gg:443 ssl:default [Temporary failure in name resolution]
2024-06-06 05:37:39,167 - discord_bot - ERROR - Failed to purge or send message in people-in-studio: Cannot connect to host discord.com:443 ssl:default [Temporary failure in name resolution]
2024-06-06 05:39:31,520 - discord.client - ERROR - Attempting a reconnect in 682.61s
Traceback (most recent call last):
  File "/usr/lib/python3/dist-packages/aiohttp/connector.py", line 1152, in _create_direct_connection
    hosts = await asyncio.shield(host_resolved)
            ^^^^^^^^^^^^^^^^^^^^^^^^^^^^^^^^^^^
  File "/usr/lib/python3/dist-packages/aiohttp/connector.py", line 874, in _resolve_host
    addrs = await self._resolver.resolve(host, port, family=self._family)
            ^^^^^^^^^^^^^^^^^^^^^^^^^^^^^^^^^^^^^^^^^^^^^^^^^^^^^^^^^^^^^
  File "/usr/lib/python3/dist-packages/aiohttp/resolver.py", line 33, in resolve
    infos = await self._loop.getaddrinfo(
            ^^^^^^^^^^^^^^^^^^^^^^^^^^^^^
  File "/usr/lib/python3.11/asyncio/base_events.py", line 867, in getaddrinfo
    return await self.run_in_executor(
           ^^^^^^^^^^^^^^^^^^^^^^^^^^^
  File "/usr/lib/python3.11/concurrent/futures/thread.py", line 58, in run
    result = self.fn(*self.args, **self.kwargs)
             ^^^^^^^^^^^^^^^^^^^^^^^^^^^^^^^^^^
  File "/usr/lib/python3.11/socket.py", line 962, in getaddrinfo
    for res in _socket.getaddrinfo(host, port, family, type, proto, flags):
               ^^^^^^^^^^^^^^^^^^^^^^^^^^^^^^^^^^^^^^^^^^^^^^^^^^^^^^^^^^^
socket.gaierror: [Errno -3] Temporary failure in name resolution

The above exception was the direct cause of the following exception:

Traceback (most recent call last):
  File "/usr/lib/python3/dist-packages/discord/client.py", line 656, in connect
    self.ws = await asyncio.wait_for(coro, timeout=60.0)
              ^^^^^^^^^^^^^^^^^^^^^^^^^^^^^^^^^^^^^^^^^^
  File "/usr/lib/python3.11/asyncio/tasks.py", line 479, in wait_for
    return fut.result()
           ^^^^^^^^^^^^
  File "/usr/lib/python3/dist-packages/discord/gateway.py", line 372, in from_client
    socket = await client.http.ws_connect(str(url))
             ^^^^^^^^^^^^^^^^^^^^^^^^^^^^^^^^^^^^^^
  File "/usr/lib/python3/dist-packages/discord/http.py", line 536, in ws_connect
    return await self.__session.ws_connect(url, **kwargs)
           ^^^^^^^^^^^^^^^^^^^^^^^^^^^^^^^^^^^^^^^^^^^^^^
  File "/usr/lib/python3/dist-packages/aiohttp/client.py", line 779, in _ws_connect
    resp = await self.request(
           ^^^^^^^^^^^^^^^^^^^
  File "/usr/lib/python3/dist-packages/aiohttp/client.py", line 536, in _request
    conn = await self._connector.connect(
           ^^^^^^^^^^^^^^^^^^^^^^^^^^^^^^
  File "/usr/lib/python3/dist-packages/aiohttp/connector.py", line 540, in connect
    proto = await self._create_connection(req, traces, timeout)
            ^^^^^^^^^^^^^^^^^^^^^^^^^^^^^^^^^^^^^^^^^^^^^^^^^^^
  File "/usr/lib/python3/dist-packages/aiohttp/connector.py", line 901, in _create_connection
    _, proto = await self._create_direct_connection(req, traces, timeout)
               ^^^^^^^^^^^^^^^^^^^^^^^^^^^^^^^^^^^^^^^^^^^^^^^^^^^^^^^^^^
  File "/usr/lib/python3/dist-packages/aiohttp/connector.py", line 1166, in _create_direct_connection
    raise ClientConnectorError(req.connection_key, exc) from exc
aiohttp.client_exceptions.ClientConnectorError: Cannot connect to host gateway-us-east1-c.discord.gg:443 ssl:default [Temporary failure in name resolution]
2024-06-06 05:39:39,168 - discord_bot - ERROR - Failed to purge or send message in people-in-studio: Cannot connect to host discord.com:443 ssl:default [Temporary failure in name resolution]
2024-06-06 05:41:39,172 - discord_bot - ERROR - Failed to purge or send message in people-in-studio: Cannot connect to host discord.com:443 ssl:default [Temporary failure in name resolution]
2024-06-06 05:43:39,175 - discord_bot - ERROR - Failed to purge or send message in people-in-studio: Cannot connect to host discord.com:443 ssl:default [Temporary failure in name resolution]
2024-06-06 05:45:39,180 - discord_bot - ERROR - Failed to purge or send message in people-in-studio: Cannot connect to host discord.com:443 ssl:default [Temporary failure in name resolution]
2024-06-06 05:47:39,182 - discord_bot - ERROR - Failed to purge or send message in people-in-studio: Cannot connect to host discord.com:443 ssl:default [Temporary failure in name resolution]
2024-06-06 05:49:39,187 - discord_bot - ERROR - Failed to purge or send message in people-in-studio: Cannot connect to host discord.com:443 ssl:default [Temporary failure in name resolution]
2024-06-06 05:50:54,184 - discord.client - ERROR - Attempting a reconnect in 682.53s
Traceback (most recent call last):
  File "/usr/lib/python3/dist-packages/aiohttp/connector.py", line 1152, in _create_direct_connection
    hosts = await asyncio.shield(host_resolved)
            ^^^^^^^^^^^^^^^^^^^^^^^^^^^^^^^^^^^
  File "/usr/lib/python3/dist-packages/aiohttp/connector.py", line 874, in _resolve_host
    addrs = await self._resolver.resolve(host, port, family=self._family)
            ^^^^^^^^^^^^^^^^^^^^^^^^^^^^^^^^^^^^^^^^^^^^^^^^^^^^^^^^^^^^^
  File "/usr/lib/python3/dist-packages/aiohttp/resolver.py", line 33, in resolve
    infos = await self._loop.getaddrinfo(
            ^^^^^^^^^^^^^^^^^^^^^^^^^^^^^
  File "/usr/lib/python3.11/asyncio/base_events.py", line 867, in getaddrinfo
    return await self.run_in_executor(
           ^^^^^^^^^^^^^^^^^^^^^^^^^^^
  File "/usr/lib/python3.11/concurrent/futures/thread.py", line 58, in run
    result = self.fn(*self.args, **self.kwargs)
             ^^^^^^^^^^^^^^^^^^^^^^^^^^^^^^^^^^
  File "/usr/lib/python3.11/socket.py", line 962, in getaddrinfo
    for res in _socket.getaddrinfo(host, port, family, type, proto, flags):
               ^^^^^^^^^^^^^^^^^^^^^^^^^^^^^^^^^^^^^^^^^^^^^^^^^^^^^^^^^^^
socket.gaierror: [Errno -3] Temporary failure in name resolution

The above exception was the direct cause of the following exception:

Traceback (most recent call last):
  File "/usr/lib/python3/dist-packages/discord/client.py", line 656, in connect
    self.ws = await asyncio.wait_for(coro, timeout=60.0)
              ^^^^^^^^^^^^^^^^^^^^^^^^^^^^^^^^^^^^^^^^^^
  File "/usr/lib/python3.11/asyncio/tasks.py", line 479, in wait_for
    return fut.result()
           ^^^^^^^^^^^^
  File "/usr/lib/python3/dist-packages/discord/gateway.py", line 372, in from_client
    socket = await client.http.ws_connect(str(url))
             ^^^^^^^^^^^^^^^^^^^^^^^^^^^^^^^^^^^^^^
  File "/usr/lib/python3/dist-packages/discord/http.py", line 536, in ws_connect
    return await self.__session.ws_connect(url, **kwargs)
           ^^^^^^^^^^^^^^^^^^^^^^^^^^^^^^^^^^^^^^^^^^^^^^
  File "/usr/lib/python3/dist-packages/aiohttp/client.py", line 779, in _ws_connect
    resp = await self.request(
           ^^^^^^^^^^^^^^^^^^^
  File "/usr/lib/python3/dist-packages/aiohttp/client.py", line 536, in _request
    conn = await self._connector.connect(
           ^^^^^^^^^^^^^^^^^^^^^^^^^^^^^^
  File "/usr/lib/python3/dist-packages/aiohttp/connector.py", line 540, in connect
    proto = await self._create_connection(req, traces, timeout)
            ^^^^^^^^^^^^^^^^^^^^^^^^^^^^^^^^^^^^^^^^^^^^^^^^^^^
  File "/usr/lib/python3/dist-packages/aiohttp/connector.py", line 901, in _create_connection
    _, proto = await self._create_direct_connection(req, traces, timeout)
               ^^^^^^^^^^^^^^^^^^^^^^^^^^^^^^^^^^^^^^^^^^^^^^^^^^^^^^^^^^
  File "/usr/lib/python3/dist-packages/aiohttp/connector.py", line 1166, in _create_direct_connection
    raise ClientConnectorError(req.connection_key, exc) from exc
aiohttp.client_exceptions.ClientConnectorError: Cannot connect to host gateway-us-east1-c.discord.gg:443 ssl:default [Temporary failure in name resolution]
2024-06-06 05:51:39,192 - discord_bot - ERROR - Failed to purge or send message in people-in-studio: Cannot connect to host discord.com:443 ssl:default [Temporary failure in name resolution]
2024-06-06 05:53:39,195 - discord_bot - ERROR - Failed to purge or send message in people-in-studio: Cannot connect to host discord.com:443 ssl:default [Temporary failure in name resolution]
2024-06-06 05:55:39,199 - discord_bot - ERROR - Failed to purge or send message in people-in-studio: Cannot connect to host discord.com:443 ssl:default [Temporary failure in name resolution]
2024-06-06 05:57:39,197 - discord_bot - ERROR - Failed to purge or send message in people-in-studio: Cannot connect to host discord.com:443 ssl:default [Temporary failure in name resolution]
2024-06-06 05:59:39,204 - discord_bot - ERROR - Failed to purge or send message in people-in-studio: Cannot connect to host discord.com:443 ssl:default [Temporary failure in name resolution]
2024-06-06 06:01:39,209 - discord_bot - ERROR - Failed to purge or send message in people-in-studio: Cannot connect to host discord.com:443 ssl:default [Temporary failure in name resolution]
2024-06-06 06:02:16,736 - discord.client - ERROR - Attempting a reconnect in 505.71s
Traceback (most recent call last):
  File "/usr/lib/python3/dist-packages/aiohttp/connector.py", line 1152, in _create_direct_connection
    hosts = await asyncio.shield(host_resolved)
            ^^^^^^^^^^^^^^^^^^^^^^^^^^^^^^^^^^^
  File "/usr/lib/python3/dist-packages/aiohttp/connector.py", line 874, in _resolve_host
    addrs = await self._resolver.resolve(host, port, family=self._family)
            ^^^^^^^^^^^^^^^^^^^^^^^^^^^^^^^^^^^^^^^^^^^^^^^^^^^^^^^^^^^^^
  File "/usr/lib/python3/dist-packages/aiohttp/resolver.py", line 33, in resolve
    infos = await self._loop.getaddrinfo(
            ^^^^^^^^^^^^^^^^^^^^^^^^^^^^^
  File "/usr/lib/python3.11/asyncio/base_events.py", line 867, in getaddrinfo
    return await self.run_in_executor(
           ^^^^^^^^^^^^^^^^^^^^^^^^^^^
  File "/usr/lib/python3.11/concurrent/futures/thread.py", line 58, in run
    result = self.fn(*self.args, **self.kwargs)
             ^^^^^^^^^^^^^^^^^^^^^^^^^^^^^^^^^^
  File "/usr/lib/python3.11/socket.py", line 962, in getaddrinfo
    for res in _socket.getaddrinfo(host, port, family, type, proto, flags):
               ^^^^^^^^^^^^^^^^^^^^^^^^^^^^^^^^^^^^^^^^^^^^^^^^^^^^^^^^^^^
socket.gaierror: [Errno -3] Temporary failure in name resolution

The above exception was the direct cause of the following exception:

Traceback (most recent call last):
  File "/usr/lib/python3/dist-packages/discord/client.py", line 656, in connect
    self.ws = await asyncio.wait_for(coro, timeout=60.0)
              ^^^^^^^^^^^^^^^^^^^^^^^^^^^^^^^^^^^^^^^^^^
  File "/usr/lib/python3.11/asyncio/tasks.py", line 479, in wait_for
    return fut.result()
           ^^^^^^^^^^^^
  File "/usr/lib/python3/dist-packages/discord/gateway.py", line 372, in from_client
    socket = await client.http.ws_connect(str(url))
             ^^^^^^^^^^^^^^^^^^^^^^^^^^^^^^^^^^^^^^
  File "/usr/lib/python3/dist-packages/discord/http.py", line 536, in ws_connect
    return await self.__session.ws_connect(url, **kwargs)
           ^^^^^^^^^^^^^^^^^^^^^^^^^^^^^^^^^^^^^^^^^^^^^^
  File "/usr/lib/python3/dist-packages/aiohttp/client.py", line 779, in _ws_connect
    resp = await self.request(
           ^^^^^^^^^^^^^^^^^^^
  File "/usr/lib/python3/dist-packages/aiohttp/client.py", line 536, in _request
    conn = await self._connector.connect(
           ^^^^^^^^^^^^^^^^^^^^^^^^^^^^^^
  File "/usr/lib/python3/dist-packages/aiohttp/connector.py", line 540, in connect
    proto = await self._create_connection(req, traces, timeout)
            ^^^^^^^^^^^^^^^^^^^^^^^^^^^^^^^^^^^^^^^^^^^^^^^^^^^
  File "/usr/lib/python3/dist-packages/aiohttp/connector.py", line 901, in _create_connection
    _, proto = await self._create_direct_connection(req, traces, timeout)
               ^^^^^^^^^^^^^^^^^^^^^^^^^^^^^^^^^^^^^^^^^^^^^^^^^^^^^^^^^^
  File "/usr/lib/python3/dist-packages/aiohttp/connector.py", line 1166, in _create_direct_connection
    raise ClientConnectorError(req.connection_key, exc) from exc
aiohttp.client_exceptions.ClientConnectorError: Cannot connect to host gateway-us-east1-c.discord.gg:443 ssl:default [Temporary failure in name resolution]
2024-06-06 06:03:39,216 - discord_bot - ERROR - Failed to purge or send message in people-in-studio: Cannot connect to host discord.com:443 ssl:default [Temporary failure in name resolution]
2024-06-06 06:05:39,219 - discord_bot - ERROR - Failed to purge or send message in people-in-studio: Cannot connect to host discord.com:443 ssl:default [Temporary failure in name resolution]
2024-06-06 06:07:39,224 - discord_bot - ERROR - Failed to purge or send message in people-in-studio: Cannot connect to host discord.com:443 ssl:default [Temporary failure in name resolution]
2024-06-06 06:09:39,229 - discord_bot - ERROR - Failed to purge or send message in people-in-studio: Cannot connect to host discord.com:443 ssl:default [Temporary failure in name resolution]
2024-06-06 06:10:42,521 - discord.client - ERROR - Attempting a reconnect in 801.38s
Traceback (most recent call last):
  File "/usr/lib/python3/dist-packages/aiohttp/connector.py", line 1152, in _create_direct_connection
    hosts = await asyncio.shield(host_resolved)
            ^^^^^^^^^^^^^^^^^^^^^^^^^^^^^^^^^^^
  File "/usr/lib/python3/dist-packages/aiohttp/connector.py", line 874, in _resolve_host
    addrs = await self._resolver.resolve(host, port, family=self._family)
            ^^^^^^^^^^^^^^^^^^^^^^^^^^^^^^^^^^^^^^^^^^^^^^^^^^^^^^^^^^^^^
  File "/usr/lib/python3/dist-packages/aiohttp/resolver.py", line 33, in resolve
    infos = await self._loop.getaddrinfo(
            ^^^^^^^^^^^^^^^^^^^^^^^^^^^^^
  File "/usr/lib/python3.11/asyncio/base_events.py", line 867, in getaddrinfo
    return await self.run_in_executor(
           ^^^^^^^^^^^^^^^^^^^^^^^^^^^
  File "/usr/lib/python3.11/concurrent/futures/thread.py", line 58, in run
    result = self.fn(*self.args, **self.kwargs)
             ^^^^^^^^^^^^^^^^^^^^^^^^^^^^^^^^^^
  File "/usr/lib/python3.11/socket.py", line 962, in getaddrinfo
    for res in _socket.getaddrinfo(host, port, family, type, proto, flags):
               ^^^^^^^^^^^^^^^^^^^^^^^^^^^^^^^^^^^^^^^^^^^^^^^^^^^^^^^^^^^
socket.gaierror: [Errno -3] Temporary failure in name resolution

The above exception was the direct cause of the following exception:

Traceback (most recent call last):
  File "/usr/lib/python3/dist-packages/discord/client.py", line 656, in connect
    self.ws = await asyncio.wait_for(coro, timeout=60.0)
              ^^^^^^^^^^^^^^^^^^^^^^^^^^^^^^^^^^^^^^^^^^
  File "/usr/lib/python3.11/asyncio/tasks.py", line 479, in wait_for
    return fut.result()
           ^^^^^^^^^^^^
  File "/usr/lib/python3/dist-packages/discord/gateway.py", line 372, in from_client
    socket = await client.http.ws_connect(str(url))
             ^^^^^^^^^^^^^^^^^^^^^^^^^^^^^^^^^^^^^^
  File "/usr/lib/python3/dist-packages/discord/http.py", line 536, in ws_connect
    return await self.__session.ws_connect(url, **kwargs)
           ^^^^^^^^^^^^^^^^^^^^^^^^^^^^^^^^^^^^^^^^^^^^^^
  File "/usr/lib/python3/dist-packages/aiohttp/client.py", line 779, in _ws_connect
    resp = await self.request(
           ^^^^^^^^^^^^^^^^^^^
  File "/usr/lib/python3/dist-packages/aiohttp/client.py", line 536, in _request
    conn = await self._connector.connect(
           ^^^^^^^^^^^^^^^^^^^^^^^^^^^^^^
  File "/usr/lib/python3/dist-packages/aiohttp/connector.py", line 540, in connect
    proto = await self._create_connection(req, traces, timeout)
            ^^^^^^^^^^^^^^^^^^^^^^^^^^^^^^^^^^^^^^^^^^^^^^^^^^^
  File "/usr/lib/python3/dist-packages/aiohttp/connector.py", line 901, in _create_connection
    _, proto = await self._create_direct_connection(req, traces, timeout)
               ^^^^^^^^^^^^^^^^^^^^^^^^^^^^^^^^^^^^^^^^^^^^^^^^^^^^^^^^^^
  File "/usr/lib/python3/dist-packages/aiohttp/connector.py", line 1166, in _create_direct_connection
    raise ClientConnectorError(req.connection_key, exc) from exc
aiohttp.client_exceptions.ClientConnectorError: Cannot connect to host gateway-us-east1-c.discord.gg:443 ssl:default [Temporary failure in name resolution]
2024-06-06 06:11:39,235 - discord_bot - ERROR - Failed to purge or send message in people-in-studio: Cannot connect to host discord.com:443 ssl:default [Temporary failure in name resolution]
2024-06-06 06:13:39,239 - discord_bot - ERROR - Failed to purge or send message in people-in-studio: Cannot connect to host discord.com:443 ssl:default [Temporary failure in name resolution]
2024-06-06 06:15:39,243 - discord_bot - ERROR - Failed to purge or send message in people-in-studio: Cannot connect to host discord.com:443 ssl:default [Temporary failure in name resolution]
2024-06-06 06:17:39,238 - discord_bot - ERROR - Failed to purge or send message in people-in-studio: Cannot connect to host discord.com:443 ssl:default [Temporary failure in name resolution]
2024-06-06 06:19:39,248 - discord_bot - ERROR - Failed to purge or send message in people-in-studio: Cannot connect to host discord.com:443 ssl:default [Temporary failure in name resolution]
2024-06-06 06:21:39,246 - discord_bot - ERROR - Failed to purge or send message in people-in-studio: Cannot connect to host discord.com:443 ssl:default [Temporary failure in name resolution]
2024-06-06 06:23:39,259 - discord_bot - ERROR - Failed to purge or send message in people-in-studio: Cannot connect to host discord.com:443 ssl:default [Temporary failure in name resolution]
2024-06-06 06:24:03,935 - discord.client - ERROR - Attempting a reconnect in 722.38s
Traceback (most recent call last):
  File "/usr/lib/python3/dist-packages/aiohttp/connector.py", line 1152, in _create_direct_connection
    hosts = await asyncio.shield(host_resolved)
            ^^^^^^^^^^^^^^^^^^^^^^^^^^^^^^^^^^^
  File "/usr/lib/python3/dist-packages/aiohttp/connector.py", line 874, in _resolve_host
    addrs = await self._resolver.resolve(host, port, family=self._family)
            ^^^^^^^^^^^^^^^^^^^^^^^^^^^^^^^^^^^^^^^^^^^^^^^^^^^^^^^^^^^^^
  File "/usr/lib/python3/dist-packages/aiohttp/resolver.py", line 33, in resolve
    infos = await self._loop.getaddrinfo(
            ^^^^^^^^^^^^^^^^^^^^^^^^^^^^^
  File "/usr/lib/python3.11/asyncio/base_events.py", line 867, in getaddrinfo
    return await self.run_in_executor(
           ^^^^^^^^^^^^^^^^^^^^^^^^^^^
  File "/usr/lib/python3.11/concurrent/futures/thread.py", line 58, in run
    result = self.fn(*self.args, **self.kwargs)
             ^^^^^^^^^^^^^^^^^^^^^^^^^^^^^^^^^^
  File "/usr/lib/python3.11/socket.py", line 962, in getaddrinfo
    for res in _socket.getaddrinfo(host, port, family, type, proto, flags):
               ^^^^^^^^^^^^^^^^^^^^^^^^^^^^^^^^^^^^^^^^^^^^^^^^^^^^^^^^^^^
socket.gaierror: [Errno -3] Temporary failure in name resolution

The above exception was the direct cause of the following exception:

Traceback (most recent call last):
  File "/usr/lib/python3/dist-packages/discord/client.py", line 656, in connect
    self.ws = await asyncio.wait_for(coro, timeout=60.0)
              ^^^^^^^^^^^^^^^^^^^^^^^^^^^^^^^^^^^^^^^^^^
  File "/usr/lib/python3.11/asyncio/tasks.py", line 479, in wait_for
    return fut.result()
           ^^^^^^^^^^^^
  File "/usr/lib/python3/dist-packages/discord/gateway.py", line 372, in from_client
    socket = await client.http.ws_connect(str(url))
             ^^^^^^^^^^^^^^^^^^^^^^^^^^^^^^^^^^^^^^
  File "/usr/lib/python3/dist-packages/discord/http.py", line 536, in ws_connect
    return await self.__session.ws_connect(url, **kwargs)
           ^^^^^^^^^^^^^^^^^^^^^^^^^^^^^^^^^^^^^^^^^^^^^^
  File "/usr/lib/python3/dist-packages/aiohttp/client.py", line 779, in _ws_connect
    resp = await self.request(
           ^^^^^^^^^^^^^^^^^^^
  File "/usr/lib/python3/dist-packages/aiohttp/client.py", line 536, in _request
    conn = await self._connector.connect(
           ^^^^^^^^^^^^^^^^^^^^^^^^^^^^^^
  File "/usr/lib/python3/dist-packages/aiohttp/connector.py", line 540, in connect
    proto = await self._create_connection(req, traces, timeout)
            ^^^^^^^^^^^^^^^^^^^^^^^^^^^^^^^^^^^^^^^^^^^^^^^^^^^
  File "/usr/lib/python3/dist-packages/aiohttp/connector.py", line 901, in _create_connection
    _, proto = await self._create_direct_connection(req, traces, timeout)
               ^^^^^^^^^^^^^^^^^^^^^^^^^^^^^^^^^^^^^^^^^^^^^^^^^^^^^^^^^^
  File "/usr/lib/python3/dist-packages/aiohttp/connector.py", line 1166, in _create_direct_connection
    raise ClientConnectorError(req.connection_key, exc) from exc
aiohttp.client_exceptions.ClientConnectorError: Cannot connect to host gateway-us-east1-c.discord.gg:443 ssl:default [Temporary failure in name resolution]
2024-06-06 06:25:39,254 - discord_bot - ERROR - Failed to purge or send message in people-in-studio: Cannot connect to host discord.com:443 ssl:default [Temporary failure in name resolution]
2024-06-06 06:27:39,256 - discord_bot - ERROR - Failed to purge or send message in people-in-studio: Cannot connect to host discord.com:443 ssl:default [Temporary failure in name resolution]
2024-06-06 06:29:39,262 - discord_bot - ERROR - Failed to purge or send message in people-in-studio: Cannot connect to host discord.com:443 ssl:default [Temporary failure in name resolution]
2024-06-06 06:31:39,270 - discord_bot - ERROR - Failed to purge or send message in people-in-studio: Cannot connect to host discord.com:443 ssl:default [Temporary failure in name resolution]
2024-06-06 06:33:39,264 - discord_bot - ERROR - Failed to purge or send message in people-in-studio: Cannot connect to host discord.com:443 ssl:default [Temporary failure in name resolution]
2024-06-06 06:35:39,267 - discord_bot - ERROR - Failed to purge or send message in people-in-studio: Cannot connect to host discord.com:443 ssl:default [Temporary failure in name resolution]
2024-06-06 06:36:06,362 - discord.client - ERROR - Attempting a reconnect in 563.87s
Traceback (most recent call last):
  File "/usr/lib/python3/dist-packages/aiohttp/connector.py", line 1152, in _create_direct_connection
    hosts = await asyncio.shield(host_resolved)
            ^^^^^^^^^^^^^^^^^^^^^^^^^^^^^^^^^^^
  File "/usr/lib/python3/dist-packages/aiohttp/connector.py", line 874, in _resolve_host
    addrs = await self._resolver.resolve(host, port, family=self._family)
            ^^^^^^^^^^^^^^^^^^^^^^^^^^^^^^^^^^^^^^^^^^^^^^^^^^^^^^^^^^^^^
  File "/usr/lib/python3/dist-packages/aiohttp/resolver.py", line 33, in resolve
    infos = await self._loop.getaddrinfo(
            ^^^^^^^^^^^^^^^^^^^^^^^^^^^^^
  File "/usr/lib/python3.11/asyncio/base_events.py", line 867, in getaddrinfo
    return await self.run_in_executor(
           ^^^^^^^^^^^^^^^^^^^^^^^^^^^
  File "/usr/lib/python3.11/concurrent/futures/thread.py", line 58, in run
    result = self.fn(*self.args, **self.kwargs)
             ^^^^^^^^^^^^^^^^^^^^^^^^^^^^^^^^^^
  File "/usr/lib/python3.11/socket.py", line 962, in getaddrinfo
    for res in _socket.getaddrinfo(host, port, family, type, proto, flags):
               ^^^^^^^^^^^^^^^^^^^^^^^^^^^^^^^^^^^^^^^^^^^^^^^^^^^^^^^^^^^
socket.gaierror: [Errno -3] Temporary failure in name resolution

The above exception was the direct cause of the following exception:

Traceback (most recent call last):
  File "/usr/lib/python3/dist-packages/discord/client.py", line 656, in connect
    self.ws = await asyncio.wait_for(coro, timeout=60.0)
              ^^^^^^^^^^^^^^^^^^^^^^^^^^^^^^^^^^^^^^^^^^
  File "/usr/lib/python3.11/asyncio/tasks.py", line 479, in wait_for
    return fut.result()
           ^^^^^^^^^^^^
  File "/usr/lib/python3/dist-packages/discord/gateway.py", line 372, in from_client
    socket = await client.http.ws_connect(str(url))
             ^^^^^^^^^^^^^^^^^^^^^^^^^^^^^^^^^^^^^^
  File "/usr/lib/python3/dist-packages/discord/http.py", line 536, in ws_connect
    return await self.__session.ws_connect(url, **kwargs)
           ^^^^^^^^^^^^^^^^^^^^^^^^^^^^^^^^^^^^^^^^^^^^^^
  File "/usr/lib/python3/dist-packages/aiohttp/client.py", line 779, in _ws_connect
    resp = await self.request(
           ^^^^^^^^^^^^^^^^^^^
  File "/usr/lib/python3/dist-packages/aiohttp/client.py", line 536, in _request
    conn = await self._connector.connect(
           ^^^^^^^^^^^^^^^^^^^^^^^^^^^^^^
  File "/usr/lib/python3/dist-packages/aiohttp/connector.py", line 540, in connect
    proto = await self._create_connection(req, traces, timeout)
            ^^^^^^^^^^^^^^^^^^^^^^^^^^^^^^^^^^^^^^^^^^^^^^^^^^^
  File "/usr/lib/python3/dist-packages/aiohttp/connector.py", line 901, in _create_connection
    _, proto = await self._create_direct_connection(req, traces, timeout)
               ^^^^^^^^^^^^^^^^^^^^^^^^^^^^^^^^^^^^^^^^^^^^^^^^^^^^^^^^^^
  File "/usr/lib/python3/dist-packages/aiohttp/connector.py", line 1166, in _create_direct_connection
    raise ClientConnectorError(req.connection_key, exc) from exc
aiohttp.client_exceptions.ClientConnectorError: Cannot connect to host gateway-us-east1-c.discord.gg:443 ssl:default [Temporary failure in name resolution]
2024-06-06 06:37:39,268 - discord_bot - ERROR - Failed to purge or send message in people-in-studio: Cannot connect to host discord.com:443 ssl:default [Temporary failure in name resolution]
2024-06-06 06:39:39,282 - discord_bot - ERROR - Failed to purge or send message in people-in-studio: Cannot connect to host discord.com:443 ssl:default [Temporary failure in name resolution]
2024-06-06 06:41:39,280 - discord_bot - ERROR - Failed to purge or send message in people-in-studio: Cannot connect to host discord.com:443 ssl:default [Temporary failure in name resolution]
2024-06-06 06:43:39,290 - discord_bot - ERROR - Failed to purge or send message in people-in-studio: Cannot connect to host discord.com:443 ssl:default [Temporary failure in name resolution]
2024-06-06 06:45:30,335 - discord.client - ERROR - Attempting a reconnect in 576.70s
Traceback (most recent call last):
  File "/usr/lib/python3/dist-packages/aiohttp/connector.py", line 1152, in _create_direct_connection
    hosts = await asyncio.shield(host_resolved)
            ^^^^^^^^^^^^^^^^^^^^^^^^^^^^^^^^^^^
  File "/usr/lib/python3/dist-packages/aiohttp/connector.py", line 874, in _resolve_host
    addrs = await self._resolver.resolve(host, port, family=self._family)
            ^^^^^^^^^^^^^^^^^^^^^^^^^^^^^^^^^^^^^^^^^^^^^^^^^^^^^^^^^^^^^
  File "/usr/lib/python3/dist-packages/aiohttp/resolver.py", line 33, in resolve
    infos = await self._loop.getaddrinfo(
            ^^^^^^^^^^^^^^^^^^^^^^^^^^^^^
  File "/usr/lib/python3.11/asyncio/base_events.py", line 867, in getaddrinfo
    return await self.run_in_executor(
           ^^^^^^^^^^^^^^^^^^^^^^^^^^^
  File "/usr/lib/python3.11/concurrent/futures/thread.py", line 58, in run
    result = self.fn(*self.args, **self.kwargs)
             ^^^^^^^^^^^^^^^^^^^^^^^^^^^^^^^^^^
  File "/usr/lib/python3.11/socket.py", line 962, in getaddrinfo
    for res in _socket.getaddrinfo(host, port, family, type, proto, flags):
               ^^^^^^^^^^^^^^^^^^^^^^^^^^^^^^^^^^^^^^^^^^^^^^^^^^^^^^^^^^^
socket.gaierror: [Errno -3] Temporary failure in name resolution

The above exception was the direct cause of the following exception:

Traceback (most recent call last):
  File "/usr/lib/python3/dist-packages/discord/client.py", line 656, in connect
    self.ws = await asyncio.wait_for(coro, timeout=60.0)
              ^^^^^^^^^^^^^^^^^^^^^^^^^^^^^^^^^^^^^^^^^^
  File "/usr/lib/python3.11/asyncio/tasks.py", line 479, in wait_for
    return fut.result()
           ^^^^^^^^^^^^
  File "/usr/lib/python3/dist-packages/discord/gateway.py", line 372, in from_client
    socket = await client.http.ws_connect(str(url))
             ^^^^^^^^^^^^^^^^^^^^^^^^^^^^^^^^^^^^^^
  File "/usr/lib/python3/dist-packages/discord/http.py", line 536, in ws_connect
    return await self.__session.ws_connect(url, **kwargs)
           ^^^^^^^^^^^^^^^^^^^^^^^^^^^^^^^^^^^^^^^^^^^^^^
  File "/usr/lib/python3/dist-packages/aiohttp/client.py", line 779, in _ws_connect
    resp = await self.request(
           ^^^^^^^^^^^^^^^^^^^
  File "/usr/lib/python3/dist-packages/aiohttp/client.py", line 536, in _request
    conn = await self._connector.connect(
           ^^^^^^^^^^^^^^^^^^^^^^^^^^^^^^
  File "/usr/lib/python3/dist-packages/aiohttp/connector.py", line 540, in connect
    proto = await self._create_connection(req, traces, timeout)
            ^^^^^^^^^^^^^^^^^^^^^^^^^^^^^^^^^^^^^^^^^^^^^^^^^^^
  File "/usr/lib/python3/dist-packages/aiohttp/connector.py", line 901, in _create_connection
    _, proto = await self._create_direct_connection(req, traces, timeout)
               ^^^^^^^^^^^^^^^^^^^^^^^^^^^^^^^^^^^^^^^^^^^^^^^^^^^^^^^^^^
  File "/usr/lib/python3/dist-packages/aiohttp/connector.py", line 1166, in _create_direct_connection
    raise ClientConnectorError(req.connection_key, exc) from exc
aiohttp.client_exceptions.ClientConnectorError: Cannot connect to host gateway-us-east1-c.discord.gg:443 ssl:default [Temporary failure in name resolution]
2024-06-06 06:45:39,286 - discord_bot - ERROR - Failed to purge or send message in people-in-studio: Cannot connect to host discord.com:443 ssl:default [Temporary failure in name resolution]
2024-06-06 06:47:39,288 - discord_bot - ERROR - Failed to purge or send message in people-in-studio: Cannot connect to host discord.com:443 ssl:default [Temporary failure in name resolution]
2024-06-06 06:49:39,290 - discord_bot - ERROR - Failed to purge or send message in people-in-studio: Cannot connect to host discord.com:443 ssl:default [Temporary failure in name resolution]
2024-06-06 06:51:39,293 - discord_bot - ERROR - Failed to purge or send message in people-in-studio: Cannot connect to host discord.com:443 ssl:default [Temporary failure in name resolution]
2024-06-06 06:53:39,303 - discord_bot - ERROR - Failed to purge or send message in people-in-studio: Cannot connect to host discord.com:443 ssl:default [Temporary failure in name resolution]
2024-06-06 06:55:07,121 - discord.client - ERROR - Attempting a reconnect in 268.75s
Traceback (most recent call last):
  File "/usr/lib/python3/dist-packages/aiohttp/connector.py", line 1152, in _create_direct_connection
    hosts = await asyncio.shield(host_resolved)
            ^^^^^^^^^^^^^^^^^^^^^^^^^^^^^^^^^^^
  File "/usr/lib/python3/dist-packages/aiohttp/connector.py", line 874, in _resolve_host
    addrs = await self._resolver.resolve(host, port, family=self._family)
            ^^^^^^^^^^^^^^^^^^^^^^^^^^^^^^^^^^^^^^^^^^^^^^^^^^^^^^^^^^^^^
  File "/usr/lib/python3/dist-packages/aiohttp/resolver.py", line 33, in resolve
    infos = await self._loop.getaddrinfo(
            ^^^^^^^^^^^^^^^^^^^^^^^^^^^^^
  File "/usr/lib/python3.11/asyncio/base_events.py", line 867, in getaddrinfo
    return await self.run_in_executor(
           ^^^^^^^^^^^^^^^^^^^^^^^^^^^
  File "/usr/lib/python3.11/concurrent/futures/thread.py", line 58, in run
    result = self.fn(*self.args, **self.kwargs)
             ^^^^^^^^^^^^^^^^^^^^^^^^^^^^^^^^^^
  File "/usr/lib/python3.11/socket.py", line 962, in getaddrinfo
    for res in _socket.getaddrinfo(host, port, family, type, proto, flags):
               ^^^^^^^^^^^^^^^^^^^^^^^^^^^^^^^^^^^^^^^^^^^^^^^^^^^^^^^^^^^
socket.gaierror: [Errno -3] Temporary failure in name resolution

The above exception was the direct cause of the following exception:

Traceback (most recent call last):
  File "/usr/lib/python3/dist-packages/discord/client.py", line 656, in connect
    self.ws = await asyncio.wait_for(coro, timeout=60.0)
              ^^^^^^^^^^^^^^^^^^^^^^^^^^^^^^^^^^^^^^^^^^
  File "/usr/lib/python3.11/asyncio/tasks.py", line 479, in wait_for
    return fut.result()
           ^^^^^^^^^^^^
  File "/usr/lib/python3/dist-packages/discord/gateway.py", line 372, in from_client
    socket = await client.http.ws_connect(str(url))
             ^^^^^^^^^^^^^^^^^^^^^^^^^^^^^^^^^^^^^^
  File "/usr/lib/python3/dist-packages/discord/http.py", line 536, in ws_connect
    return await self.__session.ws_connect(url, **kwargs)
           ^^^^^^^^^^^^^^^^^^^^^^^^^^^^^^^^^^^^^^^^^^^^^^
  File "/usr/lib/python3/dist-packages/aiohttp/client.py", line 779, in _ws_connect
    resp = await self.request(
           ^^^^^^^^^^^^^^^^^^^
  File "/usr/lib/python3/dist-packages/aiohttp/client.py", line 536, in _request
    conn = await self._connector.connect(
           ^^^^^^^^^^^^^^^^^^^^^^^^^^^^^^
  File "/usr/lib/python3/dist-packages/aiohttp/connector.py", line 540, in connect
    proto = await self._create_connection(req, traces, timeout)
            ^^^^^^^^^^^^^^^^^^^^^^^^^^^^^^^^^^^^^^^^^^^^^^^^^^^
  File "/usr/lib/python3/dist-packages/aiohttp/connector.py", line 901, in _create_connection
    _, proto = await self._create_direct_connection(req, traces, timeout)
               ^^^^^^^^^^^^^^^^^^^^^^^^^^^^^^^^^^^^^^^^^^^^^^^^^^^^^^^^^^
  File "/usr/lib/python3/dist-packages/aiohttp/connector.py", line 1166, in _create_direct_connection
    raise ClientConnectorError(req.connection_key, exc) from exc
aiohttp.client_exceptions.ClientConnectorError: Cannot connect to host gateway-us-east1-c.discord.gg:443 ssl:default [Temporary failure in name resolution]
2024-06-06 06:55:39,299 - discord_bot - ERROR - Failed to purge or send message in people-in-studio: Cannot connect to host discord.com:443 ssl:default [Temporary failure in name resolution]
2024-06-06 06:57:39,300 - discord_bot - ERROR - Failed to purge or send message in people-in-studio: Cannot connect to host discord.com:443 ssl:default [Temporary failure in name resolution]
2024-06-06 06:59:35,908 - discord.client - ERROR - Attempting a reconnect in 450.58s
Traceback (most recent call last):
  File "/usr/lib/python3/dist-packages/aiohttp/connector.py", line 1152, in _create_direct_connection
    hosts = await asyncio.shield(host_resolved)
            ^^^^^^^^^^^^^^^^^^^^^^^^^^^^^^^^^^^
  File "/usr/lib/python3/dist-packages/aiohttp/connector.py", line 874, in _resolve_host
    addrs = await self._resolver.resolve(host, port, family=self._family)
            ^^^^^^^^^^^^^^^^^^^^^^^^^^^^^^^^^^^^^^^^^^^^^^^^^^^^^^^^^^^^^
  File "/usr/lib/python3/dist-packages/aiohttp/resolver.py", line 33, in resolve
    infos = await self._loop.getaddrinfo(
            ^^^^^^^^^^^^^^^^^^^^^^^^^^^^^
  File "/usr/lib/python3.11/asyncio/base_events.py", line 867, in getaddrinfo
    return await self.run_in_executor(
           ^^^^^^^^^^^^^^^^^^^^^^^^^^^
  File "/usr/lib/python3.11/concurrent/futures/thread.py", line 58, in run
    result = self.fn(*self.args, **self.kwargs)
             ^^^^^^^^^^^^^^^^^^^^^^^^^^^^^^^^^^
  File "/usr/lib/python3.11/socket.py", line 962, in getaddrinfo
    for res in _socket.getaddrinfo(host, port, family, type, proto, flags):
               ^^^^^^^^^^^^^^^^^^^^^^^^^^^^^^^^^^^^^^^^^^^^^^^^^^^^^^^^^^^
socket.gaierror: [Errno -3] Temporary failure in name resolution

The above exception was the direct cause of the following exception:

Traceback (most recent call last):
  File "/usr/lib/python3/dist-packages/discord/client.py", line 656, in connect
    self.ws = await asyncio.wait_for(coro, timeout=60.0)
              ^^^^^^^^^^^^^^^^^^^^^^^^^^^^^^^^^^^^^^^^^^
  File "/usr/lib/python3.11/asyncio/tasks.py", line 479, in wait_for
    return fut.result()
           ^^^^^^^^^^^^
  File "/usr/lib/python3/dist-packages/discord/gateway.py", line 372, in from_client
    socket = await client.http.ws_connect(str(url))
             ^^^^^^^^^^^^^^^^^^^^^^^^^^^^^^^^^^^^^^
  File "/usr/lib/python3/dist-packages/discord/http.py", line 536, in ws_connect
    return await self.__session.ws_connect(url, **kwargs)
           ^^^^^^^^^^^^^^^^^^^^^^^^^^^^^^^^^^^^^^^^^^^^^^
  File "/usr/lib/python3/dist-packages/aiohttp/client.py", line 779, in _ws_connect
    resp = await self.request(
           ^^^^^^^^^^^^^^^^^^^
  File "/usr/lib/python3/dist-packages/aiohttp/client.py", line 536, in _request
    conn = await self._connector.connect(
           ^^^^^^^^^^^^^^^^^^^^^^^^^^^^^^
  File "/usr/lib/python3/dist-packages/aiohttp/connector.py", line 540, in connect
    proto = await self._create_connection(req, traces, timeout)
            ^^^^^^^^^^^^^^^^^^^^^^^^^^^^^^^^^^^^^^^^^^^^^^^^^^^
  File "/usr/lib/python3/dist-packages/aiohttp/connector.py", line 901, in _create_connection
    _, proto = await self._create_direct_connection(req, traces, timeout)
               ^^^^^^^^^^^^^^^^^^^^^^^^^^^^^^^^^^^^^^^^^^^^^^^^^^^^^^^^^^
  File "/usr/lib/python3/dist-packages/aiohttp/connector.py", line 1166, in _create_direct_connection
    raise ClientConnectorError(req.connection_key, exc) from exc
aiohttp.client_exceptions.ClientConnectorError: Cannot connect to host gateway-us-east1-c.discord.gg:443 ssl:default [Temporary failure in name resolution]
2024-06-06 06:59:39,301 - discord_bot - ERROR - Failed to purge or send message in people-in-studio: Cannot connect to host discord.com:443 ssl:default [Temporary failure in name resolution]
2024-06-06 07:01:39,303 - discord_bot - ERROR - Failed to purge or send message in people-in-studio: Cannot connect to host discord.com:443 ssl:default [Temporary failure in name resolution]
2024-06-06 07:03:39,315 - discord_bot - ERROR - Failed to purge or send message in people-in-studio: Cannot connect to host discord.com:443 ssl:default [Temporary failure in name resolution]
2024-06-06 07:05:39,320 - discord_bot - ERROR - Failed to purge or send message in people-in-studio: Cannot connect to host discord.com:443 ssl:default [Temporary failure in name resolution]
2024-06-06 07:07:06,568 - discord.client - ERROR - Attempting a reconnect in 344.31s
Traceback (most recent call last):
  File "/usr/lib/python3/dist-packages/aiohttp/connector.py", line 1152, in _create_direct_connection
    hosts = await asyncio.shield(host_resolved)
            ^^^^^^^^^^^^^^^^^^^^^^^^^^^^^^^^^^^
  File "/usr/lib/python3/dist-packages/aiohttp/connector.py", line 874, in _resolve_host
    addrs = await self._resolver.resolve(host, port, family=self._family)
            ^^^^^^^^^^^^^^^^^^^^^^^^^^^^^^^^^^^^^^^^^^^^^^^^^^^^^^^^^^^^^
  File "/usr/lib/python3/dist-packages/aiohttp/resolver.py", line 33, in resolve
    infos = await self._loop.getaddrinfo(
            ^^^^^^^^^^^^^^^^^^^^^^^^^^^^^
  File "/usr/lib/python3.11/asyncio/base_events.py", line 867, in getaddrinfo
    return await self.run_in_executor(
           ^^^^^^^^^^^^^^^^^^^^^^^^^^^
  File "/usr/lib/python3.11/concurrent/futures/thread.py", line 58, in run
    result = self.fn(*self.args, **self.kwargs)
             ^^^^^^^^^^^^^^^^^^^^^^^^^^^^^^^^^^
  File "/usr/lib/python3.11/socket.py", line 962, in getaddrinfo
    for res in _socket.getaddrinfo(host, port, family, type, proto, flags):
               ^^^^^^^^^^^^^^^^^^^^^^^^^^^^^^^^^^^^^^^^^^^^^^^^^^^^^^^^^^^
socket.gaierror: [Errno -3] Temporary failure in name resolution

The above exception was the direct cause of the following exception:

Traceback (most recent call last):
  File "/usr/lib/python3/dist-packages/discord/client.py", line 656, in connect
    self.ws = await asyncio.wait_for(coro, timeout=60.0)
              ^^^^^^^^^^^^^^^^^^^^^^^^^^^^^^^^^^^^^^^^^^
  File "/usr/lib/python3.11/asyncio/tasks.py", line 479, in wait_for
    return fut.result()
           ^^^^^^^^^^^^
  File "/usr/lib/python3/dist-packages/discord/gateway.py", line 372, in from_client
    socket = await client.http.ws_connect(str(url))
             ^^^^^^^^^^^^^^^^^^^^^^^^^^^^^^^^^^^^^^
  File "/usr/lib/python3/dist-packages/discord/http.py", line 536, in ws_connect
    return await self.__session.ws_connect(url, **kwargs)
           ^^^^^^^^^^^^^^^^^^^^^^^^^^^^^^^^^^^^^^^^^^^^^^
  File "/usr/lib/python3/dist-packages/aiohttp/client.py", line 779, in _ws_connect
    resp = await self.request(
           ^^^^^^^^^^^^^^^^^^^
  File "/usr/lib/python3/dist-packages/aiohttp/client.py", line 536, in _request
    conn = await self._connector.connect(
           ^^^^^^^^^^^^^^^^^^^^^^^^^^^^^^
  File "/usr/lib/python3/dist-packages/aiohttp/connector.py", line 540, in connect
    proto = await self._create_connection(req, traces, timeout)
            ^^^^^^^^^^^^^^^^^^^^^^^^^^^^^^^^^^^^^^^^^^^^^^^^^^^
  File "/usr/lib/python3/dist-packages/aiohttp/connector.py", line 901, in _create_connection
    _, proto = await self._create_direct_connection(req, traces, timeout)
               ^^^^^^^^^^^^^^^^^^^^^^^^^^^^^^^^^^^^^^^^^^^^^^^^^^^^^^^^^^
  File "/usr/lib/python3/dist-packages/aiohttp/connector.py", line 1166, in _create_direct_connection
    raise ClientConnectorError(req.connection_key, exc) from exc
aiohttp.client_exceptions.ClientConnectorError: Cannot connect to host gateway-us-east1-c.discord.gg:443 ssl:default [Temporary failure in name resolution]
2024-06-06 07:07:39,325 - discord_bot - ERROR - Failed to purge or send message in people-in-studio: Cannot connect to host discord.com:443 ssl:default [Temporary failure in name resolution]
2024-06-06 07:09:39,328 - discord_bot - ERROR - Failed to purge or send message in people-in-studio: Cannot connect to host discord.com:443 ssl:default [Temporary failure in name resolution]
2024-06-06 07:11:39,331 - discord_bot - ERROR - Failed to purge or send message in people-in-studio: Cannot connect to host discord.com:443 ssl:default [Temporary failure in name resolution]
2024-06-06 07:12:50,945 - discord.client - ERROR - Attempting a reconnect in 304.32s
Traceback (most recent call last):
  File "/usr/lib/python3/dist-packages/aiohttp/connector.py", line 1152, in _create_direct_connection
    hosts = await asyncio.shield(host_resolved)
            ^^^^^^^^^^^^^^^^^^^^^^^^^^^^^^^^^^^
  File "/usr/lib/python3/dist-packages/aiohttp/connector.py", line 874, in _resolve_host
    addrs = await self._resolver.resolve(host, port, family=self._family)
            ^^^^^^^^^^^^^^^^^^^^^^^^^^^^^^^^^^^^^^^^^^^^^^^^^^^^^^^^^^^^^
  File "/usr/lib/python3/dist-packages/aiohttp/resolver.py", line 33, in resolve
    infos = await self._loop.getaddrinfo(
            ^^^^^^^^^^^^^^^^^^^^^^^^^^^^^
  File "/usr/lib/python3.11/asyncio/base_events.py", line 867, in getaddrinfo
    return await self.run_in_executor(
           ^^^^^^^^^^^^^^^^^^^^^^^^^^^
  File "/usr/lib/python3.11/concurrent/futures/thread.py", line 58, in run
    result = self.fn(*self.args, **self.kwargs)
             ^^^^^^^^^^^^^^^^^^^^^^^^^^^^^^^^^^
  File "/usr/lib/python3.11/socket.py", line 962, in getaddrinfo
    for res in _socket.getaddrinfo(host, port, family, type, proto, flags):
               ^^^^^^^^^^^^^^^^^^^^^^^^^^^^^^^^^^^^^^^^^^^^^^^^^^^^^^^^^^^
socket.gaierror: [Errno -3] Temporary failure in name resolution

The above exception was the direct cause of the following exception:

Traceback (most recent call last):
  File "/usr/lib/python3/dist-packages/discord/client.py", line 656, in connect
    self.ws = await asyncio.wait_for(coro, timeout=60.0)
              ^^^^^^^^^^^^^^^^^^^^^^^^^^^^^^^^^^^^^^^^^^
  File "/usr/lib/python3.11/asyncio/tasks.py", line 479, in wait_for
    return fut.result()
           ^^^^^^^^^^^^
  File "/usr/lib/python3/dist-packages/discord/gateway.py", line 372, in from_client
    socket = await client.http.ws_connect(str(url))
             ^^^^^^^^^^^^^^^^^^^^^^^^^^^^^^^^^^^^^^
  File "/usr/lib/python3/dist-packages/discord/http.py", line 536, in ws_connect
    return await self.__session.ws_connect(url, **kwargs)
           ^^^^^^^^^^^^^^^^^^^^^^^^^^^^^^^^^^^^^^^^^^^^^^
  File "/usr/lib/python3/dist-packages/aiohttp/client.py", line 779, in _ws_connect
    resp = await self.request(
           ^^^^^^^^^^^^^^^^^^^
  File "/usr/lib/python3/dist-packages/aiohttp/client.py", line 536, in _request
    conn = await self._connector.connect(
           ^^^^^^^^^^^^^^^^^^^^^^^^^^^^^^
  File "/usr/lib/python3/dist-packages/aiohttp/connector.py", line 540, in connect
    proto = await self._create_connection(req, traces, timeout)
            ^^^^^^^^^^^^^^^^^^^^^^^^^^^^^^^^^^^^^^^^^^^^^^^^^^^
  File "/usr/lib/python3/dist-packages/aiohttp/connector.py", line 901, in _create_connection
    _, proto = await self._create_direct_connection(req, traces, timeout)
               ^^^^^^^^^^^^^^^^^^^^^^^^^^^^^^^^^^^^^^^^^^^^^^^^^^^^^^^^^^
  File "/usr/lib/python3/dist-packages/aiohttp/connector.py", line 1166, in _create_direct_connection
    raise ClientConnectorError(req.connection_key, exc) from exc
aiohttp.client_exceptions.ClientConnectorError: Cannot connect to host gateway-us-east1-c.discord.gg:443 ssl:default [Temporary failure in name resolution]
2024-06-06 07:13:39,336 - discord_bot - ERROR - Failed to purge or send message in people-in-studio: Cannot connect to host discord.com:443 ssl:default [Temporary failure in name resolution]
2024-06-06 07:15:39,342 - discord_bot - ERROR - Failed to purge or send message in people-in-studio: Cannot connect to host discord.com:443 ssl:default [Temporary failure in name resolution]
2024-06-06 07:17:39,345 - discord_bot - ERROR - Failed to purge or send message in people-in-studio: Cannot connect to host discord.com:443 ssl:default [Temporary failure in name resolution]
2024-06-06 07:17:55,290 - discord.client - ERROR - Attempting a reconnect in 792.06s
Traceback (most recent call last):
  File "/usr/lib/python3/dist-packages/aiohttp/connector.py", line 1152, in _create_direct_connection
    hosts = await asyncio.shield(host_resolved)
            ^^^^^^^^^^^^^^^^^^^^^^^^^^^^^^^^^^^
  File "/usr/lib/python3/dist-packages/aiohttp/connector.py", line 874, in _resolve_host
    addrs = await self._resolver.resolve(host, port, family=self._family)
            ^^^^^^^^^^^^^^^^^^^^^^^^^^^^^^^^^^^^^^^^^^^^^^^^^^^^^^^^^^^^^
  File "/usr/lib/python3/dist-packages/aiohttp/resolver.py", line 33, in resolve
    infos = await self._loop.getaddrinfo(
            ^^^^^^^^^^^^^^^^^^^^^^^^^^^^^
  File "/usr/lib/python3.11/asyncio/base_events.py", line 867, in getaddrinfo
    return await self.run_in_executor(
           ^^^^^^^^^^^^^^^^^^^^^^^^^^^
  File "/usr/lib/python3.11/concurrent/futures/thread.py", line 58, in run
    result = self.fn(*self.args, **self.kwargs)
             ^^^^^^^^^^^^^^^^^^^^^^^^^^^^^^^^^^
  File "/usr/lib/python3.11/socket.py", line 962, in getaddrinfo
    for res in _socket.getaddrinfo(host, port, family, type, proto, flags):
               ^^^^^^^^^^^^^^^^^^^^^^^^^^^^^^^^^^^^^^^^^^^^^^^^^^^^^^^^^^^
socket.gaierror: [Errno -3] Temporary failure in name resolution

The above exception was the direct cause of the following exception:

Traceback (most recent call last):
  File "/usr/lib/python3/dist-packages/discord/client.py", line 656, in connect
    self.ws = await asyncio.wait_for(coro, timeout=60.0)
              ^^^^^^^^^^^^^^^^^^^^^^^^^^^^^^^^^^^^^^^^^^
  File "/usr/lib/python3.11/asyncio/tasks.py", line 479, in wait_for
    return fut.result()
           ^^^^^^^^^^^^
  File "/usr/lib/python3/dist-packages/discord/gateway.py", line 372, in from_client
    socket = await client.http.ws_connect(str(url))
             ^^^^^^^^^^^^^^^^^^^^^^^^^^^^^^^^^^^^^^
  File "/usr/lib/python3/dist-packages/discord/http.py", line 536, in ws_connect
    return await self.__session.ws_connect(url, **kwargs)
           ^^^^^^^^^^^^^^^^^^^^^^^^^^^^^^^^^^^^^^^^^^^^^^
  File "/usr/lib/python3/dist-packages/aiohttp/client.py", line 779, in _ws_connect
    resp = await self.request(
           ^^^^^^^^^^^^^^^^^^^
  File "/usr/lib/python3/dist-packages/aiohttp/client.py", line 536, in _request
    conn = await self._connector.connect(
           ^^^^^^^^^^^^^^^^^^^^^^^^^^^^^^
  File "/usr/lib/python3/dist-packages/aiohttp/connector.py", line 540, in connect
    proto = await self._create_connection(req, traces, timeout)
            ^^^^^^^^^^^^^^^^^^^^^^^^^^^^^^^^^^^^^^^^^^^^^^^^^^^
  File "/usr/lib/python3/dist-packages/aiohttp/connector.py", line 901, in _create_connection
    _, proto = await self._create_direct_connection(req, traces, timeout)
               ^^^^^^^^^^^^^^^^^^^^^^^^^^^^^^^^^^^^^^^^^^^^^^^^^^^^^^^^^^
  File "/usr/lib/python3/dist-packages/aiohttp/connector.py", line 1166, in _create_direct_connection
    raise ClientConnectorError(req.connection_key, exc) from exc
aiohttp.client_exceptions.ClientConnectorError: Cannot connect to host gateway-us-east1-c.discord.gg:443 ssl:default [Temporary failure in name resolution]
2024-06-06 07:19:39,352 - discord_bot - ERROR - Failed to purge or send message in people-in-studio: Cannot connect to host discord.com:443 ssl:default [Temporary failure in name resolution]
2024-06-06 07:21:39,356 - discord_bot - ERROR - Failed to purge or send message in people-in-studio: Cannot connect to host discord.com:443 ssl:default [Temporary failure in name resolution]
2024-06-06 07:23:39,359 - discord_bot - ERROR - Failed to purge or send message in people-in-studio: Cannot connect to host discord.com:443 ssl:default [Temporary failure in name resolution]
2024-06-06 07:25:39,363 - discord_bot - ERROR - Failed to purge or send message in people-in-studio: Cannot connect to host discord.com:443 ssl:default [Temporary failure in name resolution]
2024-06-06 07:27:39,366 - discord_bot - ERROR - Failed to purge or send message in people-in-studio: Cannot connect to host discord.com:443 ssl:default [Temporary failure in name resolution]
2024-06-06 07:29:39,371 - discord_bot - ERROR - Failed to purge or send message in people-in-studio: Cannot connect to host discord.com:443 ssl:default [Temporary failure in name resolution]
2024-06-06 07:31:07,382 - discord.client - ERROR - Attempting a reconnect in 653.82s
Traceback (most recent call last):
  File "/usr/lib/python3/dist-packages/aiohttp/connector.py", line 1152, in _create_direct_connection
    hosts = await asyncio.shield(host_resolved)
            ^^^^^^^^^^^^^^^^^^^^^^^^^^^^^^^^^^^
  File "/usr/lib/python3/dist-packages/aiohttp/connector.py", line 874, in _resolve_host
    addrs = await self._resolver.resolve(host, port, family=self._family)
            ^^^^^^^^^^^^^^^^^^^^^^^^^^^^^^^^^^^^^^^^^^^^^^^^^^^^^^^^^^^^^
  File "/usr/lib/python3/dist-packages/aiohttp/resolver.py", line 33, in resolve
    infos = await self._loop.getaddrinfo(
            ^^^^^^^^^^^^^^^^^^^^^^^^^^^^^
  File "/usr/lib/python3.11/asyncio/base_events.py", line 867, in getaddrinfo
    return await self.run_in_executor(
           ^^^^^^^^^^^^^^^^^^^^^^^^^^^
  File "/usr/lib/python3.11/concurrent/futures/thread.py", line 58, in run
    result = self.fn(*self.args, **self.kwargs)
             ^^^^^^^^^^^^^^^^^^^^^^^^^^^^^^^^^^
  File "/usr/lib/python3.11/socket.py", line 962, in getaddrinfo
    for res in _socket.getaddrinfo(host, port, family, type, proto, flags):
               ^^^^^^^^^^^^^^^^^^^^^^^^^^^^^^^^^^^^^^^^^^^^^^^^^^^^^^^^^^^
socket.gaierror: [Errno -3] Temporary failure in name resolution

The above exception was the direct cause of the following exception:

Traceback (most recent call last):
  File "/usr/lib/python3/dist-packages/discord/client.py", line 656, in connect
    self.ws = await asyncio.wait_for(coro, timeout=60.0)
              ^^^^^^^^^^^^^^^^^^^^^^^^^^^^^^^^^^^^^^^^^^
  File "/usr/lib/python3.11/asyncio/tasks.py", line 479, in wait_for
    return fut.result()
           ^^^^^^^^^^^^
  File "/usr/lib/python3/dist-packages/discord/gateway.py", line 372, in from_client
    socket = await client.http.ws_connect(str(url))
             ^^^^^^^^^^^^^^^^^^^^^^^^^^^^^^^^^^^^^^
  File "/usr/lib/python3/dist-packages/discord/http.py", line 536, in ws_connect
    return await self.__session.ws_connect(url, **kwargs)
           ^^^^^^^^^^^^^^^^^^^^^^^^^^^^^^^^^^^^^^^^^^^^^^
  File "/usr/lib/python3/dist-packages/aiohttp/client.py", line 779, in _ws_connect
    resp = await self.request(
           ^^^^^^^^^^^^^^^^^^^
  File "/usr/lib/python3/dist-packages/aiohttp/client.py", line 536, in _request
    conn = await self._connector.connect(
           ^^^^^^^^^^^^^^^^^^^^^^^^^^^^^^
  File "/usr/lib/python3/dist-packages/aiohttp/connector.py", line 540, in connect
    proto = await self._create_connection(req, traces, timeout)
            ^^^^^^^^^^^^^^^^^^^^^^^^^^^^^^^^^^^^^^^^^^^^^^^^^^^
  File "/usr/lib/python3/dist-packages/aiohttp/connector.py", line 901, in _create_connection
    _, proto = await self._create_direct_connection(req, traces, timeout)
               ^^^^^^^^^^^^^^^^^^^^^^^^^^^^^^^^^^^^^^^^^^^^^^^^^^^^^^^^^^
  File "/usr/lib/python3/dist-packages/aiohttp/connector.py", line 1166, in _create_direct_connection
    raise ClientConnectorError(req.connection_key, exc) from exc
aiohttp.client_exceptions.ClientConnectorError: Cannot connect to host gateway-us-east1-c.discord.gg:443 ssl:default [Temporary failure in name resolution]
2024-06-06 07:31:39,376 - discord_bot - ERROR - Failed to purge or send message in people-in-studio: Cannot connect to host discord.com:443 ssl:default [Temporary failure in name resolution]
2024-06-06 07:33:39,383 - discord_bot - ERROR - Failed to purge or send message in people-in-studio: Cannot connect to host discord.com:443 ssl:default [Temporary failure in name resolution]
2024-06-06 07:35:39,386 - discord_bot - ERROR - Failed to purge or send message in people-in-studio: Cannot connect to host discord.com:443 ssl:default [Temporary failure in name resolution]
2024-06-06 07:37:39,391 - discord_bot - ERROR - Failed to purge or send message in people-in-studio: Cannot connect to host discord.com:443 ssl:default [Temporary failure in name resolution]
2024-06-06 07:39:39,394 - discord_bot - ERROR - Failed to purge or send message in people-in-studio: Cannot connect to host discord.com:443 ssl:default [Temporary failure in name resolution]
2024-06-06 07:41:39,399 - discord_bot - ERROR - Failed to purge or send message in people-in-studio: Cannot connect to host discord.com:443 ssl:default [Temporary failure in name resolution]
2024-06-06 07:42:01,239 - discord.client - ERROR - Attempting a reconnect in 557.18s
Traceback (most recent call last):
  File "/usr/lib/python3/dist-packages/aiohttp/connector.py", line 1152, in _create_direct_connection
    hosts = await asyncio.shield(host_resolved)
            ^^^^^^^^^^^^^^^^^^^^^^^^^^^^^^^^^^^
  File "/usr/lib/python3/dist-packages/aiohttp/connector.py", line 874, in _resolve_host
    addrs = await self._resolver.resolve(host, port, family=self._family)
            ^^^^^^^^^^^^^^^^^^^^^^^^^^^^^^^^^^^^^^^^^^^^^^^^^^^^^^^^^^^^^
  File "/usr/lib/python3/dist-packages/aiohttp/resolver.py", line 33, in resolve
    infos = await self._loop.getaddrinfo(
            ^^^^^^^^^^^^^^^^^^^^^^^^^^^^^
  File "/usr/lib/python3.11/asyncio/base_events.py", line 867, in getaddrinfo
    return await self.run_in_executor(
           ^^^^^^^^^^^^^^^^^^^^^^^^^^^
  File "/usr/lib/python3.11/concurrent/futures/thread.py", line 58, in run
    result = self.fn(*self.args, **self.kwargs)
             ^^^^^^^^^^^^^^^^^^^^^^^^^^^^^^^^^^
  File "/usr/lib/python3.11/socket.py", line 962, in getaddrinfo
    for res in _socket.getaddrinfo(host, port, family, type, proto, flags):
               ^^^^^^^^^^^^^^^^^^^^^^^^^^^^^^^^^^^^^^^^^^^^^^^^^^^^^^^^^^^
socket.gaierror: [Errno -3] Temporary failure in name resolution

The above exception was the direct cause of the following exception:

Traceback (most recent call last):
  File "/usr/lib/python3/dist-packages/discord/client.py", line 656, in connect
    self.ws = await asyncio.wait_for(coro, timeout=60.0)
              ^^^^^^^^^^^^^^^^^^^^^^^^^^^^^^^^^^^^^^^^^^
  File "/usr/lib/python3.11/asyncio/tasks.py", line 479, in wait_for
    return fut.result()
           ^^^^^^^^^^^^
  File "/usr/lib/python3/dist-packages/discord/gateway.py", line 372, in from_client
    socket = await client.http.ws_connect(str(url))
             ^^^^^^^^^^^^^^^^^^^^^^^^^^^^^^^^^^^^^^
  File "/usr/lib/python3/dist-packages/discord/http.py", line 536, in ws_connect
    return await self.__session.ws_connect(url, **kwargs)
           ^^^^^^^^^^^^^^^^^^^^^^^^^^^^^^^^^^^^^^^^^^^^^^
  File "/usr/lib/python3/dist-packages/aiohttp/client.py", line 779, in _ws_connect
    resp = await self.request(
           ^^^^^^^^^^^^^^^^^^^
  File "/usr/lib/python3/dist-packages/aiohttp/client.py", line 536, in _request
    conn = await self._connector.connect(
           ^^^^^^^^^^^^^^^^^^^^^^^^^^^^^^
  File "/usr/lib/python3/dist-packages/aiohttp/connector.py", line 540, in connect
    proto = await self._create_connection(req, traces, timeout)
            ^^^^^^^^^^^^^^^^^^^^^^^^^^^^^^^^^^^^^^^^^^^^^^^^^^^
  File "/usr/lib/python3/dist-packages/aiohttp/connector.py", line 901, in _create_connection
    _, proto = await self._create_direct_connection(req, traces, timeout)
               ^^^^^^^^^^^^^^^^^^^^^^^^^^^^^^^^^^^^^^^^^^^^^^^^^^^^^^^^^^
  File "/usr/lib/python3/dist-packages/aiohttp/connector.py", line 1166, in _create_direct_connection
    raise ClientConnectorError(req.connection_key, exc) from exc
aiohttp.client_exceptions.ClientConnectorError: Cannot connect to host gateway-us-east1-c.discord.gg:443 ssl:default [Temporary failure in name resolution]
2024-06-06 07:43:39,403 - discord_bot - ERROR - Failed to purge or send message in people-in-studio: Cannot connect to host discord.com:443 ssl:default [Temporary failure in name resolution]
2024-06-06 07:45:39,406 - discord_bot - ERROR - Failed to purge or send message in people-in-studio: Cannot connect to host discord.com:443 ssl:default [Temporary failure in name resolution]
2024-06-06 07:47:39,410 - discord_bot - ERROR - Failed to purge or send message in people-in-studio: Cannot connect to host discord.com:443 ssl:default [Temporary failure in name resolution]
2024-06-06 07:49:39,411 - discord_bot - ERROR - Failed to purge or send message in people-in-studio: Cannot connect to host discord.com:443 ssl:default [Temporary failure in name resolution]
2024-06-06 07:51:18,474 - discord.client - ERROR - Attempting a reconnect in 304.33s
Traceback (most recent call last):
  File "/usr/lib/python3/dist-packages/aiohttp/connector.py", line 1152, in _create_direct_connection
    hosts = await asyncio.shield(host_resolved)
            ^^^^^^^^^^^^^^^^^^^^^^^^^^^^^^^^^^^
  File "/usr/lib/python3/dist-packages/aiohttp/connector.py", line 874, in _resolve_host
    addrs = await self._resolver.resolve(host, port, family=self._family)
            ^^^^^^^^^^^^^^^^^^^^^^^^^^^^^^^^^^^^^^^^^^^^^^^^^^^^^^^^^^^^^
  File "/usr/lib/python3/dist-packages/aiohttp/resolver.py", line 33, in resolve
    infos = await self._loop.getaddrinfo(
            ^^^^^^^^^^^^^^^^^^^^^^^^^^^^^
  File "/usr/lib/python3.11/asyncio/base_events.py", line 867, in getaddrinfo
    return await self.run_in_executor(
           ^^^^^^^^^^^^^^^^^^^^^^^^^^^
  File "/usr/lib/python3.11/concurrent/futures/thread.py", line 58, in run
    result = self.fn(*self.args, **self.kwargs)
             ^^^^^^^^^^^^^^^^^^^^^^^^^^^^^^^^^^
  File "/usr/lib/python3.11/socket.py", line 962, in getaddrinfo
    for res in _socket.getaddrinfo(host, port, family, type, proto, flags):
               ^^^^^^^^^^^^^^^^^^^^^^^^^^^^^^^^^^^^^^^^^^^^^^^^^^^^^^^^^^^
socket.gaierror: [Errno -3] Temporary failure in name resolution

The above exception was the direct cause of the following exception:

Traceback (most recent call last):
  File "/usr/lib/python3/dist-packages/discord/client.py", line 656, in connect
    self.ws = await asyncio.wait_for(coro, timeout=60.0)
              ^^^^^^^^^^^^^^^^^^^^^^^^^^^^^^^^^^^^^^^^^^
  File "/usr/lib/python3.11/asyncio/tasks.py", line 479, in wait_for
    return fut.result()
           ^^^^^^^^^^^^
  File "/usr/lib/python3/dist-packages/discord/gateway.py", line 372, in from_client
    socket = await client.http.ws_connect(str(url))
             ^^^^^^^^^^^^^^^^^^^^^^^^^^^^^^^^^^^^^^
  File "/usr/lib/python3/dist-packages/discord/http.py", line 536, in ws_connect
    return await self.__session.ws_connect(url, **kwargs)
           ^^^^^^^^^^^^^^^^^^^^^^^^^^^^^^^^^^^^^^^^^^^^^^
  File "/usr/lib/python3/dist-packages/aiohttp/client.py", line 779, in _ws_connect
    resp = await self.request(
           ^^^^^^^^^^^^^^^^^^^
  File "/usr/lib/python3/dist-packages/aiohttp/client.py", line 536, in _request
    conn = await self._connector.connect(
           ^^^^^^^^^^^^^^^^^^^^^^^^^^^^^^
  File "/usr/lib/python3/dist-packages/aiohttp/connector.py", line 540, in connect
    proto = await self._create_connection(req, traces, timeout)
            ^^^^^^^^^^^^^^^^^^^^^^^^^^^^^^^^^^^^^^^^^^^^^^^^^^^
  File "/usr/lib/python3/dist-packages/aiohttp/connector.py", line 901, in _create_connection
    _, proto = await self._create_direct_connection(req, traces, timeout)
               ^^^^^^^^^^^^^^^^^^^^^^^^^^^^^^^^^^^^^^^^^^^^^^^^^^^^^^^^^^
  File "/usr/lib/python3/dist-packages/aiohttp/connector.py", line 1166, in _create_direct_connection
    raise ClientConnectorError(req.connection_key, exc) from exc
aiohttp.client_exceptions.ClientConnectorError: Cannot connect to host gateway-us-east1-c.discord.gg:443 ssl:default [Temporary failure in name resolution]
2024-06-06 07:51:39,409 - discord_bot - ERROR - Failed to purge or send message in people-in-studio: Cannot connect to host discord.com:443 ssl:default [Temporary failure in name resolution]
2024-06-06 07:53:39,419 - discord_bot - ERROR - Failed to purge or send message in people-in-studio: Cannot connect to host discord.com:443 ssl:default [Temporary failure in name resolution]
2024-06-06 07:55:39,414 - discord_bot - ERROR - Failed to purge or send message in people-in-studio: Cannot connect to host discord.com:443 ssl:default [Temporary failure in name resolution]
2024-06-06 07:56:22,817 - discord.client - ERROR - Attempting a reconnect in 913.44s
Traceback (most recent call last):
  File "/usr/lib/python3/dist-packages/aiohttp/connector.py", line 1152, in _create_direct_connection
    hosts = await asyncio.shield(host_resolved)
            ^^^^^^^^^^^^^^^^^^^^^^^^^^^^^^^^^^^
  File "/usr/lib/python3/dist-packages/aiohttp/connector.py", line 874, in _resolve_host
    addrs = await self._resolver.resolve(host, port, family=self._family)
            ^^^^^^^^^^^^^^^^^^^^^^^^^^^^^^^^^^^^^^^^^^^^^^^^^^^^^^^^^^^^^
  File "/usr/lib/python3/dist-packages/aiohttp/resolver.py", line 33, in resolve
    infos = await self._loop.getaddrinfo(
            ^^^^^^^^^^^^^^^^^^^^^^^^^^^^^
  File "/usr/lib/python3.11/asyncio/base_events.py", line 867, in getaddrinfo
    return await self.run_in_executor(
           ^^^^^^^^^^^^^^^^^^^^^^^^^^^
  File "/usr/lib/python3.11/concurrent/futures/thread.py", line 58, in run
    result = self.fn(*self.args, **self.kwargs)
             ^^^^^^^^^^^^^^^^^^^^^^^^^^^^^^^^^^
  File "/usr/lib/python3.11/socket.py", line 962, in getaddrinfo
    for res in _socket.getaddrinfo(host, port, family, type, proto, flags):
               ^^^^^^^^^^^^^^^^^^^^^^^^^^^^^^^^^^^^^^^^^^^^^^^^^^^^^^^^^^^
socket.gaierror: [Errno -3] Temporary failure in name resolution

The above exception was the direct cause of the following exception:

Traceback (most recent call last):
  File "/usr/lib/python3/dist-packages/discord/client.py", line 656, in connect
    self.ws = await asyncio.wait_for(coro, timeout=60.0)
              ^^^^^^^^^^^^^^^^^^^^^^^^^^^^^^^^^^^^^^^^^^
  File "/usr/lib/python3.11/asyncio/tasks.py", line 479, in wait_for
    return fut.result()
           ^^^^^^^^^^^^
  File "/usr/lib/python3/dist-packages/discord/gateway.py", line 372, in from_client
    socket = await client.http.ws_connect(str(url))
             ^^^^^^^^^^^^^^^^^^^^^^^^^^^^^^^^^^^^^^
  File "/usr/lib/python3/dist-packages/discord/http.py", line 536, in ws_connect
    return await self.__session.ws_connect(url, **kwargs)
           ^^^^^^^^^^^^^^^^^^^^^^^^^^^^^^^^^^^^^^^^^^^^^^
  File "/usr/lib/python3/dist-packages/aiohttp/client.py", line 779, in _ws_connect
    resp = await self.request(
           ^^^^^^^^^^^^^^^^^^^
  File "/usr/lib/python3/dist-packages/aiohttp/client.py", line 536, in _request
    conn = await self._connector.connect(
           ^^^^^^^^^^^^^^^^^^^^^^^^^^^^^^
  File "/usr/lib/python3/dist-packages/aiohttp/connector.py", line 540, in connect
    proto = await self._create_connection(req, traces, timeout)
            ^^^^^^^^^^^^^^^^^^^^^^^^^^^^^^^^^^^^^^^^^^^^^^^^^^^
  File "/usr/lib/python3/dist-packages/aiohttp/connector.py", line 901, in _create_connection
    _, proto = await self._create_direct_connection(req, traces, timeout)
               ^^^^^^^^^^^^^^^^^^^^^^^^^^^^^^^^^^^^^^^^^^^^^^^^^^^^^^^^^^
  File "/usr/lib/python3/dist-packages/aiohttp/connector.py", line 1166, in _create_direct_connection
    raise ClientConnectorError(req.connection_key, exc) from exc
aiohttp.client_exceptions.ClientConnectorError: Cannot connect to host gateway-us-east1-c.discord.gg:443 ssl:default [Temporary failure in name resolution]
2024-06-06 07:57:39,416 - discord_bot - ERROR - Failed to purge or send message in people-in-studio: Cannot connect to host discord.com:443 ssl:default [Temporary failure in name resolution]
2024-06-06 07:59:39,418 - discord_bot - ERROR - Failed to purge or send message in people-in-studio: Cannot connect to host discord.com:443 ssl:default [Temporary failure in name resolution]
2024-06-06 08:01:39,419 - discord_bot - ERROR - Failed to purge or send message in people-in-studio: Cannot connect to host discord.com:443 ssl:default [Temporary failure in name resolution]
2024-06-06 08:03:39,423 - discord_bot - ERROR - Failed to purge or send message in people-in-studio: Cannot connect to host discord.com:443 ssl:default [Temporary failure in name resolution]
2024-06-06 08:05:39,425 - discord_bot - ERROR - Failed to purge or send message in people-in-studio: Cannot connect to host discord.com:443 ssl:default [Temporary failure in name resolution]
2024-06-06 08:07:39,426 - discord_bot - ERROR - Failed to purge or send message in people-in-studio: Cannot connect to host discord.com:443 ssl:default [Temporary failure in name resolution]
2024-06-06 08:09:39,428 - discord_bot - ERROR - Failed to purge or send message in people-in-studio: Cannot connect to host discord.com:443 ssl:default [Temporary failure in name resolution]
2024-06-06 08:11:36,287 - discord.client - ERROR - Attempting a reconnect in 608.04s
Traceback (most recent call last):
  File "/usr/lib/python3/dist-packages/aiohttp/connector.py", line 1152, in _create_direct_connection
    hosts = await asyncio.shield(host_resolved)
            ^^^^^^^^^^^^^^^^^^^^^^^^^^^^^^^^^^^
  File "/usr/lib/python3/dist-packages/aiohttp/connector.py", line 874, in _resolve_host
    addrs = await self._resolver.resolve(host, port, family=self._family)
            ^^^^^^^^^^^^^^^^^^^^^^^^^^^^^^^^^^^^^^^^^^^^^^^^^^^^^^^^^^^^^
  File "/usr/lib/python3/dist-packages/aiohttp/resolver.py", line 33, in resolve
    infos = await self._loop.getaddrinfo(
            ^^^^^^^^^^^^^^^^^^^^^^^^^^^^^
  File "/usr/lib/python3.11/asyncio/base_events.py", line 867, in getaddrinfo
    return await self.run_in_executor(
           ^^^^^^^^^^^^^^^^^^^^^^^^^^^
  File "/usr/lib/python3.11/concurrent/futures/thread.py", line 58, in run
    result = self.fn(*self.args, **self.kwargs)
             ^^^^^^^^^^^^^^^^^^^^^^^^^^^^^^^^^^
  File "/usr/lib/python3.11/socket.py", line 962, in getaddrinfo
    for res in _socket.getaddrinfo(host, port, family, type, proto, flags):
               ^^^^^^^^^^^^^^^^^^^^^^^^^^^^^^^^^^^^^^^^^^^^^^^^^^^^^^^^^^^
socket.gaierror: [Errno -3] Temporary failure in name resolution

The above exception was the direct cause of the following exception:

Traceback (most recent call last):
  File "/usr/lib/python3/dist-packages/discord/client.py", line 656, in connect
    self.ws = await asyncio.wait_for(coro, timeout=60.0)
              ^^^^^^^^^^^^^^^^^^^^^^^^^^^^^^^^^^^^^^^^^^
  File "/usr/lib/python3.11/asyncio/tasks.py", line 479, in wait_for
    return fut.result()
           ^^^^^^^^^^^^
  File "/usr/lib/python3/dist-packages/discord/gateway.py", line 372, in from_client
    socket = await client.http.ws_connect(str(url))
             ^^^^^^^^^^^^^^^^^^^^^^^^^^^^^^^^^^^^^^
  File "/usr/lib/python3/dist-packages/discord/http.py", line 536, in ws_connect
    return await self.__session.ws_connect(url, **kwargs)
           ^^^^^^^^^^^^^^^^^^^^^^^^^^^^^^^^^^^^^^^^^^^^^^
  File "/usr/lib/python3/dist-packages/aiohttp/client.py", line 779, in _ws_connect
    resp = await self.request(
           ^^^^^^^^^^^^^^^^^^^
  File "/usr/lib/python3/dist-packages/aiohttp/client.py", line 536, in _request
    conn = await self._connector.connect(
           ^^^^^^^^^^^^^^^^^^^^^^^^^^^^^^
  File "/usr/lib/python3/dist-packages/aiohttp/connector.py", line 540, in connect
    proto = await self._create_connection(req, traces, timeout)
            ^^^^^^^^^^^^^^^^^^^^^^^^^^^^^^^^^^^^^^^^^^^^^^^^^^^
  File "/usr/lib/python3/dist-packages/aiohttp/connector.py", line 901, in _create_connection
    _, proto = await self._create_direct_connection(req, traces, timeout)
               ^^^^^^^^^^^^^^^^^^^^^^^^^^^^^^^^^^^^^^^^^^^^^^^^^^^^^^^^^^
  File "/usr/lib/python3/dist-packages/aiohttp/connector.py", line 1166, in _create_direct_connection
    raise ClientConnectorError(req.connection_key, exc) from exc
aiohttp.client_exceptions.ClientConnectorError: Cannot connect to host gateway-us-east1-c.discord.gg:443 ssl:default [Temporary failure in name resolution]
2024-06-06 08:11:39,429 - discord_bot - ERROR - Failed to purge or send message in people-in-studio: Cannot connect to host discord.com:443 ssl:default [Temporary failure in name resolution]
2024-06-06 08:13:39,441 - discord_bot - ERROR - Failed to purge or send message in people-in-studio: Cannot connect to host discord.com:443 ssl:default [Temporary failure in name resolution]
2024-06-06 08:15:39,443 - discord_bot - ERROR - Failed to purge or send message in people-in-studio: Cannot connect to host discord.com:443 ssl:default [Temporary failure in name resolution]
2024-06-06 08:17:39,446 - discord_bot - ERROR - Failed to purge or send message in people-in-studio: Cannot connect to host discord.com:443 ssl:default [Temporary failure in name resolution]
2024-06-06 08:19:39,449 - discord_bot - ERROR - Failed to purge or send message in people-in-studio: Cannot connect to host discord.com:443 ssl:default [Temporary failure in name resolution]
2024-06-06 08:21:39,452 - discord_bot - ERROR - Failed to purge or send message in people-in-studio: Cannot connect to host discord.com:443 ssl:default [Temporary failure in name resolution]
2024-06-06 08:21:44,339 - discord.client - ERROR - Attempting a reconnect in 232.79s
Traceback (most recent call last):
  File "/usr/lib/python3/dist-packages/aiohttp/connector.py", line 1152, in _create_direct_connection
    hosts = await asyncio.shield(host_resolved)
            ^^^^^^^^^^^^^^^^^^^^^^^^^^^^^^^^^^^
  File "/usr/lib/python3/dist-packages/aiohttp/connector.py", line 874, in _resolve_host
    addrs = await self._resolver.resolve(host, port, family=self._family)
            ^^^^^^^^^^^^^^^^^^^^^^^^^^^^^^^^^^^^^^^^^^^^^^^^^^^^^^^^^^^^^
  File "/usr/lib/python3/dist-packages/aiohttp/resolver.py", line 33, in resolve
    infos = await self._loop.getaddrinfo(
            ^^^^^^^^^^^^^^^^^^^^^^^^^^^^^
  File "/usr/lib/python3.11/asyncio/base_events.py", line 867, in getaddrinfo
    return await self.run_in_executor(
           ^^^^^^^^^^^^^^^^^^^^^^^^^^^
  File "/usr/lib/python3.11/concurrent/futures/thread.py", line 58, in run
    result = self.fn(*self.args, **self.kwargs)
             ^^^^^^^^^^^^^^^^^^^^^^^^^^^^^^^^^^
  File "/usr/lib/python3.11/socket.py", line 962, in getaddrinfo
    for res in _socket.getaddrinfo(host, port, family, type, proto, flags):
               ^^^^^^^^^^^^^^^^^^^^^^^^^^^^^^^^^^^^^^^^^^^^^^^^^^^^^^^^^^^
socket.gaierror: [Errno -3] Temporary failure in name resolution

The above exception was the direct cause of the following exception:

Traceback (most recent call last):
  File "/usr/lib/python3/dist-packages/discord/client.py", line 656, in connect
    self.ws = await asyncio.wait_for(coro, timeout=60.0)
              ^^^^^^^^^^^^^^^^^^^^^^^^^^^^^^^^^^^^^^^^^^
  File "/usr/lib/python3.11/asyncio/tasks.py", line 479, in wait_for
    return fut.result()
           ^^^^^^^^^^^^
  File "/usr/lib/python3/dist-packages/discord/gateway.py", line 372, in from_client
    socket = await client.http.ws_connect(str(url))
             ^^^^^^^^^^^^^^^^^^^^^^^^^^^^^^^^^^^^^^
  File "/usr/lib/python3/dist-packages/discord/http.py", line 536, in ws_connect
    return await self.__session.ws_connect(url, **kwargs)
           ^^^^^^^^^^^^^^^^^^^^^^^^^^^^^^^^^^^^^^^^^^^^^^
  File "/usr/lib/python3/dist-packages/aiohttp/client.py", line 779, in _ws_connect
    resp = await self.request(
           ^^^^^^^^^^^^^^^^^^^
  File "/usr/lib/python3/dist-packages/aiohttp/client.py", line 536, in _request
    conn = await self._connector.connect(
           ^^^^^^^^^^^^^^^^^^^^^^^^^^^^^^
  File "/usr/lib/python3/dist-packages/aiohttp/connector.py", line 540, in connect
    proto = await self._create_connection(req, traces, timeout)
            ^^^^^^^^^^^^^^^^^^^^^^^^^^^^^^^^^^^^^^^^^^^^^^^^^^^
  File "/usr/lib/python3/dist-packages/aiohttp/connector.py", line 901, in _create_connection
    _, proto = await self._create_direct_connection(req, traces, timeout)
               ^^^^^^^^^^^^^^^^^^^^^^^^^^^^^^^^^^^^^^^^^^^^^^^^^^^^^^^^^^
  File "/usr/lib/python3/dist-packages/aiohttp/connector.py", line 1166, in _create_direct_connection
    raise ClientConnectorError(req.connection_key, exc) from exc
aiohttp.client_exceptions.ClientConnectorError: Cannot connect to host gateway-us-east1-c.discord.gg:443 ssl:default [Temporary failure in name resolution]
2024-06-06 08:23:39,455 - discord_bot - ERROR - Failed to purge or send message in people-in-studio: Cannot connect to host discord.com:443 ssl:default [Temporary failure in name resolution]
2024-06-06 08:25:37,241 - discord.client - ERROR - Attempting a reconnect in 98.48s
Traceback (most recent call last):
  File "/usr/lib/python3/dist-packages/aiohttp/connector.py", line 1152, in _create_direct_connection
    hosts = await asyncio.shield(host_resolved)
            ^^^^^^^^^^^^^^^^^^^^^^^^^^^^^^^^^^^
  File "/usr/lib/python3/dist-packages/aiohttp/connector.py", line 874, in _resolve_host
    addrs = await self._resolver.resolve(host, port, family=self._family)
            ^^^^^^^^^^^^^^^^^^^^^^^^^^^^^^^^^^^^^^^^^^^^^^^^^^^^^^^^^^^^^
  File "/usr/lib/python3/dist-packages/aiohttp/resolver.py", line 33, in resolve
    infos = await self._loop.getaddrinfo(
            ^^^^^^^^^^^^^^^^^^^^^^^^^^^^^
  File "/usr/lib/python3.11/asyncio/base_events.py", line 867, in getaddrinfo
    return await self.run_in_executor(
           ^^^^^^^^^^^^^^^^^^^^^^^^^^^
  File "/usr/lib/python3.11/concurrent/futures/thread.py", line 58, in run
    result = self.fn(*self.args, **self.kwargs)
             ^^^^^^^^^^^^^^^^^^^^^^^^^^^^^^^^^^
  File "/usr/lib/python3.11/socket.py", line 962, in getaddrinfo
    for res in _socket.getaddrinfo(host, port, family, type, proto, flags):
               ^^^^^^^^^^^^^^^^^^^^^^^^^^^^^^^^^^^^^^^^^^^^^^^^^^^^^^^^^^^
socket.gaierror: [Errno -3] Temporary failure in name resolution

The above exception was the direct cause of the following exception:

Traceback (most recent call last):
  File "/usr/lib/python3/dist-packages/discord/client.py", line 656, in connect
    self.ws = await asyncio.wait_for(coro, timeout=60.0)
              ^^^^^^^^^^^^^^^^^^^^^^^^^^^^^^^^^^^^^^^^^^
  File "/usr/lib/python3.11/asyncio/tasks.py", line 479, in wait_for
    return fut.result()
           ^^^^^^^^^^^^
  File "/usr/lib/python3/dist-packages/discord/gateway.py", line 372, in from_client
    socket = await client.http.ws_connect(str(url))
             ^^^^^^^^^^^^^^^^^^^^^^^^^^^^^^^^^^^^^^
  File "/usr/lib/python3/dist-packages/discord/http.py", line 536, in ws_connect
    return await self.__session.ws_connect(url, **kwargs)
           ^^^^^^^^^^^^^^^^^^^^^^^^^^^^^^^^^^^^^^^^^^^^^^
  File "/usr/lib/python3/dist-packages/aiohttp/client.py", line 779, in _ws_connect
    resp = await self.request(
           ^^^^^^^^^^^^^^^^^^^
  File "/usr/lib/python3/dist-packages/aiohttp/client.py", line 536, in _request
    conn = await self._connector.connect(
           ^^^^^^^^^^^^^^^^^^^^^^^^^^^^^^
  File "/usr/lib/python3/dist-packages/aiohttp/connector.py", line 540, in connect
    proto = await self._create_connection(req, traces, timeout)
            ^^^^^^^^^^^^^^^^^^^^^^^^^^^^^^^^^^^^^^^^^^^^^^^^^^^
  File "/usr/lib/python3/dist-packages/aiohttp/connector.py", line 901, in _create_connection
    _, proto = await self._create_direct_connection(req, traces, timeout)
               ^^^^^^^^^^^^^^^^^^^^^^^^^^^^^^^^^^^^^^^^^^^^^^^^^^^^^^^^^^
  File "/usr/lib/python3/dist-packages/aiohttp/connector.py", line 1166, in _create_direct_connection
    raise ClientConnectorError(req.connection_key, exc) from exc
aiohttp.client_exceptions.ClientConnectorError: Cannot connect to host gateway-us-east1-c.discord.gg:443 ssl:default [Temporary failure in name resolution]
2024-06-06 08:25:39,461 - discord_bot - ERROR - Failed to purge or send message in people-in-studio: Cannot connect to host discord.com:443 ssl:default [Temporary failure in name resolution]
2024-06-06 08:27:15,774 - discord.client - ERROR - Attempting a reconnect in 397.50s
Traceback (most recent call last):
  File "/usr/lib/python3/dist-packages/aiohttp/connector.py", line 1152, in _create_direct_connection
    hosts = await asyncio.shield(host_resolved)
            ^^^^^^^^^^^^^^^^^^^^^^^^^^^^^^^^^^^
  File "/usr/lib/python3/dist-packages/aiohttp/connector.py", line 874, in _resolve_host
    addrs = await self._resolver.resolve(host, port, family=self._family)
            ^^^^^^^^^^^^^^^^^^^^^^^^^^^^^^^^^^^^^^^^^^^^^^^^^^^^^^^^^^^^^
  File "/usr/lib/python3/dist-packages/aiohttp/resolver.py", line 33, in resolve
    infos = await self._loop.getaddrinfo(
            ^^^^^^^^^^^^^^^^^^^^^^^^^^^^^
  File "/usr/lib/python3.11/asyncio/base_events.py", line 867, in getaddrinfo
    return await self.run_in_executor(
           ^^^^^^^^^^^^^^^^^^^^^^^^^^^
  File "/usr/lib/python3.11/concurrent/futures/thread.py", line 58, in run
    result = self.fn(*self.args, **self.kwargs)
             ^^^^^^^^^^^^^^^^^^^^^^^^^^^^^^^^^^
  File "/usr/lib/python3.11/socket.py", line 962, in getaddrinfo
    for res in _socket.getaddrinfo(host, port, family, type, proto, flags):
               ^^^^^^^^^^^^^^^^^^^^^^^^^^^^^^^^^^^^^^^^^^^^^^^^^^^^^^^^^^^
socket.gaierror: [Errno -3] Temporary failure in name resolution

The above exception was the direct cause of the following exception:

Traceback (most recent call last):
  File "/usr/lib/python3/dist-packages/discord/client.py", line 656, in connect
    self.ws = await asyncio.wait_for(coro, timeout=60.0)
              ^^^^^^^^^^^^^^^^^^^^^^^^^^^^^^^^^^^^^^^^^^
  File "/usr/lib/python3.11/asyncio/tasks.py", line 479, in wait_for
    return fut.result()
           ^^^^^^^^^^^^
  File "/usr/lib/python3/dist-packages/discord/gateway.py", line 372, in from_client
    socket = await client.http.ws_connect(str(url))
             ^^^^^^^^^^^^^^^^^^^^^^^^^^^^^^^^^^^^^^
  File "/usr/lib/python3/dist-packages/discord/http.py", line 536, in ws_connect
    return await self.__session.ws_connect(url, **kwargs)
           ^^^^^^^^^^^^^^^^^^^^^^^^^^^^^^^^^^^^^^^^^^^^^^
  File "/usr/lib/python3/dist-packages/aiohttp/client.py", line 779, in _ws_connect
    resp = await self.request(
           ^^^^^^^^^^^^^^^^^^^
  File "/usr/lib/python3/dist-packages/aiohttp/client.py", line 536, in _request
    conn = await self._connector.connect(
           ^^^^^^^^^^^^^^^^^^^^^^^^^^^^^^
  File "/usr/lib/python3/dist-packages/aiohttp/connector.py", line 540, in connect
    proto = await self._create_connection(req, traces, timeout)
            ^^^^^^^^^^^^^^^^^^^^^^^^^^^^^^^^^^^^^^^^^^^^^^^^^^^
  File "/usr/lib/python3/dist-packages/aiohttp/connector.py", line 901, in _create_connection
    _, proto = await self._create_direct_connection(req, traces, timeout)
               ^^^^^^^^^^^^^^^^^^^^^^^^^^^^^^^^^^^^^^^^^^^^^^^^^^^^^^^^^^
  File "/usr/lib/python3/dist-packages/aiohttp/connector.py", line 1166, in _create_direct_connection
    raise ClientConnectorError(req.connection_key, exc) from exc
aiohttp.client_exceptions.ClientConnectorError: Cannot connect to host gateway-us-east1-c.discord.gg:443 ssl:default [Temporary failure in name resolution]
2024-06-06 08:27:39,456 - discord_bot - ERROR - Failed to purge or send message in people-in-studio: Cannot connect to host discord.com:443 ssl:default [Temporary failure in name resolution]
2024-06-06 08:29:39,467 - discord_bot - ERROR - Failed to purge or send message in people-in-studio: Cannot connect to host discord.com:443 ssl:default [Temporary failure in name resolution]
2024-06-06 08:31:39,469 - discord_bot - ERROR - Failed to purge or send message in people-in-studio: Cannot connect to host discord.com:443 ssl:default [Temporary failure in name resolution]
2024-06-06 08:33:39,473 - discord_bot - ERROR - Failed to purge or send message in people-in-studio: Cannot connect to host discord.com:443 ssl:default [Temporary failure in name resolution]
2024-06-06 08:33:53,286 - discord.client - ERROR - Attempting a reconnect in 127.74s
Traceback (most recent call last):
  File "/usr/lib/python3/dist-packages/aiohttp/connector.py", line 1152, in _create_direct_connection
    hosts = await asyncio.shield(host_resolved)
            ^^^^^^^^^^^^^^^^^^^^^^^^^^^^^^^^^^^
  File "/usr/lib/python3/dist-packages/aiohttp/connector.py", line 874, in _resolve_host
    addrs = await self._resolver.resolve(host, port, family=self._family)
            ^^^^^^^^^^^^^^^^^^^^^^^^^^^^^^^^^^^^^^^^^^^^^^^^^^^^^^^^^^^^^
  File "/usr/lib/python3/dist-packages/aiohttp/resolver.py", line 33, in resolve
    infos = await self._loop.getaddrinfo(
            ^^^^^^^^^^^^^^^^^^^^^^^^^^^^^
  File "/usr/lib/python3.11/asyncio/base_events.py", line 867, in getaddrinfo
    return await self.run_in_executor(
           ^^^^^^^^^^^^^^^^^^^^^^^^^^^
  File "/usr/lib/python3.11/concurrent/futures/thread.py", line 58, in run
    result = self.fn(*self.args, **self.kwargs)
             ^^^^^^^^^^^^^^^^^^^^^^^^^^^^^^^^^^
  File "/usr/lib/python3.11/socket.py", line 962, in getaddrinfo
    for res in _socket.getaddrinfo(host, port, family, type, proto, flags):
               ^^^^^^^^^^^^^^^^^^^^^^^^^^^^^^^^^^^^^^^^^^^^^^^^^^^^^^^^^^^
socket.gaierror: [Errno -3] Temporary failure in name resolution

The above exception was the direct cause of the following exception:

Traceback (most recent call last):
  File "/usr/lib/python3/dist-packages/discord/client.py", line 656, in connect
    self.ws = await asyncio.wait_for(coro, timeout=60.0)
              ^^^^^^^^^^^^^^^^^^^^^^^^^^^^^^^^^^^^^^^^^^
  File "/usr/lib/python3.11/asyncio/tasks.py", line 479, in wait_for
    return fut.result()
           ^^^^^^^^^^^^
  File "/usr/lib/python3/dist-packages/discord/gateway.py", line 372, in from_client
    socket = await client.http.ws_connect(str(url))
             ^^^^^^^^^^^^^^^^^^^^^^^^^^^^^^^^^^^^^^
  File "/usr/lib/python3/dist-packages/discord/http.py", line 536, in ws_connect
    return await self.__session.ws_connect(url, **kwargs)
           ^^^^^^^^^^^^^^^^^^^^^^^^^^^^^^^^^^^^^^^^^^^^^^
  File "/usr/lib/python3/dist-packages/aiohttp/client.py", line 779, in _ws_connect
    resp = await self.request(
           ^^^^^^^^^^^^^^^^^^^
  File "/usr/lib/python3/dist-packages/aiohttp/client.py", line 536, in _request
    conn = await self._connector.connect(
           ^^^^^^^^^^^^^^^^^^^^^^^^^^^^^^
  File "/usr/lib/python3/dist-packages/aiohttp/connector.py", line 540, in connect
    proto = await self._create_connection(req, traces, timeout)
            ^^^^^^^^^^^^^^^^^^^^^^^^^^^^^^^^^^^^^^^^^^^^^^^^^^^
  File "/usr/lib/python3/dist-packages/aiohttp/connector.py", line 901, in _create_connection
    _, proto = await self._create_direct_connection(req, traces, timeout)
               ^^^^^^^^^^^^^^^^^^^^^^^^^^^^^^^^^^^^^^^^^^^^^^^^^^^^^^^^^^
  File "/usr/lib/python3/dist-packages/aiohttp/connector.py", line 1166, in _create_direct_connection
    raise ClientConnectorError(req.connection_key, exc) from exc
aiohttp.client_exceptions.ClientConnectorError: Cannot connect to host gateway-us-east1-c.discord.gg:443 ssl:default [Temporary failure in name resolution]
2024-06-06 08:35:39,480 - discord_bot - ERROR - Failed to purge or send message in people-in-studio: Cannot connect to host discord.com:443 ssl:default [Temporary failure in name resolution]
2024-06-06 08:36:01,055 - discord.client - ERROR - Attempting a reconnect in 682.03s
Traceback (most recent call last):
  File "/usr/lib/python3/dist-packages/aiohttp/connector.py", line 1152, in _create_direct_connection
    hosts = await asyncio.shield(host_resolved)
            ^^^^^^^^^^^^^^^^^^^^^^^^^^^^^^^^^^^
  File "/usr/lib/python3/dist-packages/aiohttp/connector.py", line 874, in _resolve_host
    addrs = await self._resolver.resolve(host, port, family=self._family)
            ^^^^^^^^^^^^^^^^^^^^^^^^^^^^^^^^^^^^^^^^^^^^^^^^^^^^^^^^^^^^^
  File "/usr/lib/python3/dist-packages/aiohttp/resolver.py", line 33, in resolve
    infos = await self._loop.getaddrinfo(
            ^^^^^^^^^^^^^^^^^^^^^^^^^^^^^
  File "/usr/lib/python3.11/asyncio/base_events.py", line 867, in getaddrinfo
    return await self.run_in_executor(
           ^^^^^^^^^^^^^^^^^^^^^^^^^^^
  File "/usr/lib/python3.11/concurrent/futures/thread.py", line 58, in run
    result = self.fn(*self.args, **self.kwargs)
             ^^^^^^^^^^^^^^^^^^^^^^^^^^^^^^^^^^
  File "/usr/lib/python3.11/socket.py", line 962, in getaddrinfo
    for res in _socket.getaddrinfo(host, port, family, type, proto, flags):
               ^^^^^^^^^^^^^^^^^^^^^^^^^^^^^^^^^^^^^^^^^^^^^^^^^^^^^^^^^^^
socket.gaierror: [Errno -3] Temporary failure in name resolution

The above exception was the direct cause of the following exception:

Traceback (most recent call last):
  File "/usr/lib/python3/dist-packages/discord/client.py", line 656, in connect
    self.ws = await asyncio.wait_for(coro, timeout=60.0)
              ^^^^^^^^^^^^^^^^^^^^^^^^^^^^^^^^^^^^^^^^^^
  File "/usr/lib/python3.11/asyncio/tasks.py", line 479, in wait_for
    return fut.result()
           ^^^^^^^^^^^^
  File "/usr/lib/python3/dist-packages/discord/gateway.py", line 372, in from_client
    socket = await client.http.ws_connect(str(url))
             ^^^^^^^^^^^^^^^^^^^^^^^^^^^^^^^^^^^^^^
  File "/usr/lib/python3/dist-packages/discord/http.py", line 536, in ws_connect
    return await self.__session.ws_connect(url, **kwargs)
           ^^^^^^^^^^^^^^^^^^^^^^^^^^^^^^^^^^^^^^^^^^^^^^
  File "/usr/lib/python3/dist-packages/aiohttp/client.py", line 779, in _ws_connect
    resp = await self.request(
           ^^^^^^^^^^^^^^^^^^^
  File "/usr/lib/python3/dist-packages/aiohttp/client.py", line 536, in _request
    conn = await self._connector.connect(
           ^^^^^^^^^^^^^^^^^^^^^^^^^^^^^^
  File "/usr/lib/python3/dist-packages/aiohttp/connector.py", line 540, in connect
    proto = await self._create_connection(req, traces, timeout)
            ^^^^^^^^^^^^^^^^^^^^^^^^^^^^^^^^^^^^^^^^^^^^^^^^^^^
  File "/usr/lib/python3/dist-packages/aiohttp/connector.py", line 901, in _create_connection
    _, proto = await self._create_direct_connection(req, traces, timeout)
               ^^^^^^^^^^^^^^^^^^^^^^^^^^^^^^^^^^^^^^^^^^^^^^^^^^^^^^^^^^
  File "/usr/lib/python3/dist-packages/aiohttp/connector.py", line 1166, in _create_direct_connection
    raise ClientConnectorError(req.connection_key, exc) from exc
aiohttp.client_exceptions.ClientConnectorError: Cannot connect to host gateway-us-east1-c.discord.gg:443 ssl:default [Temporary failure in name resolution]
2024-06-06 08:37:39,482 - discord_bot - ERROR - Failed to purge or send message in people-in-studio: Cannot connect to host discord.com:443 ssl:default [Temporary failure in name resolution]
2024-06-06 08:39:39,487 - discord_bot - ERROR - Failed to purge or send message in people-in-studio: Cannot connect to host discord.com:443 ssl:default [Temporary failure in name resolution]
2024-06-06 08:41:39,491 - discord_bot - ERROR - Failed to purge or send message in people-in-studio: Cannot connect to host discord.com:443 ssl:default [Temporary failure in name resolution]
2024-06-06 08:43:39,496 - discord_bot - ERROR - Failed to purge or send message in people-in-studio: Cannot connect to host discord.com:443 ssl:default [Temporary failure in name resolution]
2024-06-06 08:45:39,501 - discord_bot - ERROR - Failed to purge or send message in people-in-studio: Cannot connect to host discord.com:443 ssl:default [Temporary failure in name resolution]
2024-06-06 08:47:23,168 - discord.client - ERROR - Attempting a reconnect in 437.51s
Traceback (most recent call last):
  File "/usr/lib/python3/dist-packages/aiohttp/connector.py", line 1152, in _create_direct_connection
    hosts = await asyncio.shield(host_resolved)
            ^^^^^^^^^^^^^^^^^^^^^^^^^^^^^^^^^^^
  File "/usr/lib/python3/dist-packages/aiohttp/connector.py", line 874, in _resolve_host
    addrs = await self._resolver.resolve(host, port, family=self._family)
            ^^^^^^^^^^^^^^^^^^^^^^^^^^^^^^^^^^^^^^^^^^^^^^^^^^^^^^^^^^^^^
  File "/usr/lib/python3/dist-packages/aiohttp/resolver.py", line 33, in resolve
    infos = await self._loop.getaddrinfo(
            ^^^^^^^^^^^^^^^^^^^^^^^^^^^^^
  File "/usr/lib/python3.11/asyncio/base_events.py", line 867, in getaddrinfo
    return await self.run_in_executor(
           ^^^^^^^^^^^^^^^^^^^^^^^^^^^
  File "/usr/lib/python3.11/concurrent/futures/thread.py", line 58, in run
    result = self.fn(*self.args, **self.kwargs)
             ^^^^^^^^^^^^^^^^^^^^^^^^^^^^^^^^^^
  File "/usr/lib/python3.11/socket.py", line 962, in getaddrinfo
    for res in _socket.getaddrinfo(host, port, family, type, proto, flags):
               ^^^^^^^^^^^^^^^^^^^^^^^^^^^^^^^^^^^^^^^^^^^^^^^^^^^^^^^^^^^
socket.gaierror: [Errno -3] Temporary failure in name resolution

The above exception was the direct cause of the following exception:

Traceback (most recent call last):
  File "/usr/lib/python3/dist-packages/discord/client.py", line 656, in connect
    self.ws = await asyncio.wait_for(coro, timeout=60.0)
              ^^^^^^^^^^^^^^^^^^^^^^^^^^^^^^^^^^^^^^^^^^
  File "/usr/lib/python3.11/asyncio/tasks.py", line 479, in wait_for
    return fut.result()
           ^^^^^^^^^^^^
  File "/usr/lib/python3/dist-packages/discord/gateway.py", line 372, in from_client
    socket = await client.http.ws_connect(str(url))
             ^^^^^^^^^^^^^^^^^^^^^^^^^^^^^^^^^^^^^^
  File "/usr/lib/python3/dist-packages/discord/http.py", line 536, in ws_connect
    return await self.__session.ws_connect(url, **kwargs)
           ^^^^^^^^^^^^^^^^^^^^^^^^^^^^^^^^^^^^^^^^^^^^^^
  File "/usr/lib/python3/dist-packages/aiohttp/client.py", line 779, in _ws_connect
    resp = await self.request(
           ^^^^^^^^^^^^^^^^^^^
  File "/usr/lib/python3/dist-packages/aiohttp/client.py", line 536, in _request
    conn = await self._connector.connect(
           ^^^^^^^^^^^^^^^^^^^^^^^^^^^^^^
  File "/usr/lib/python3/dist-packages/aiohttp/connector.py", line 540, in connect
    proto = await self._create_connection(req, traces, timeout)
            ^^^^^^^^^^^^^^^^^^^^^^^^^^^^^^^^^^^^^^^^^^^^^^^^^^^
  File "/usr/lib/python3/dist-packages/aiohttp/connector.py", line 901, in _create_connection
    _, proto = await self._create_direct_connection(req, traces, timeout)
               ^^^^^^^^^^^^^^^^^^^^^^^^^^^^^^^^^^^^^^^^^^^^^^^^^^^^^^^^^^
  File "/usr/lib/python3/dist-packages/aiohttp/connector.py", line 1166, in _create_direct_connection
    raise ClientConnectorError(req.connection_key, exc) from exc
aiohttp.client_exceptions.ClientConnectorError: Cannot connect to host gateway-us-east1-c.discord.gg:443 ssl:default [Temporary failure in name resolution]
2024-06-06 08:47:39,505 - discord_bot - ERROR - Failed to purge or send message in people-in-studio: Cannot connect to host discord.com:443 ssl:default [Temporary failure in name resolution]
2024-06-06 08:49:39,508 - discord_bot - ERROR - Failed to purge or send message in people-in-studio: Cannot connect to host discord.com:443 ssl:default [Temporary failure in name resolution]
2024-06-06 08:51:39,511 - discord_bot - ERROR - Failed to purge or send message in people-in-studio: Cannot connect to host discord.com:443 ssl:default [Temporary failure in name resolution]
2024-06-06 08:53:39,515 - discord_bot - ERROR - Failed to purge or send message in people-in-studio: Cannot connect to host discord.com:443 ssl:default [Temporary failure in name resolution]
