2024-06-05 22:45:25,964 - discord.client - ERROR - Attempting a reconnect in 326.59s
Traceback (most recent call last):
  File "/usr/lib/python3/dist-packages/aiohttp/connector.py", line 1152, in _create_direct_connection
    hosts = await asyncio.shield(host_resolved)
            ^^^^^^^^^^^^^^^^^^^^^^^^^^^^^^^^^^^
  File "/usr/lib/python3/dist-packages/aiohttp/connector.py", line 874, in _resolve_host
    addrs = await self._resolver.resolve(host, port, family=self._family)
            ^^^^^^^^^^^^^^^^^^^^^^^^^^^^^^^^^^^^^^^^^^^^^^^^^^^^^^^^^^^^^
  File "/usr/lib/python3/dist-packages/aiohttp/resolver.py", line 33, in resolve
    infos = await self._loop.getaddrinfo(
            ^^^^^^^^^^^^^^^^^^^^^^^^^^^^^
  File "/usr/lib/python3.11/asyncio/base_events.py", line 867, in getaddrinfo
    return await self.run_in_executor(
           ^^^^^^^^^^^^^^^^^^^^^^^^^^^
  File "/usr/lib/python3.11/concurrent/futures/thread.py", line 58, in run
    result = self.fn(*self.args, **self.kwargs)
             ^^^^^^^^^^^^^^^^^^^^^^^^^^^^^^^^^^
  File "/usr/lib/python3.11/socket.py", line 962, in getaddrinfo
    for res in _socket.getaddrinfo(host, port, family, type, proto, flags):
               ^^^^^^^^^^^^^^^^^^^^^^^^^^^^^^^^^^^^^^^^^^^^^^^^^^^^^^^^^^^
socket.gaierror: [Errno -3] Temporary failure in name resolution

The above exception was the direct cause of the following exception:

Traceback (most recent call last):
  File "/usr/lib/python3/dist-packages/discord/client.py", line 656, in connect
    self.ws = await asyncio.wait_for(coro, timeout=60.0)
              ^^^^^^^^^^^^^^^^^^^^^^^^^^^^^^^^^^^^^^^^^^
  File "/usr/lib/python3.11/asyncio/tasks.py", line 479, in wait_for
    return fut.result()
           ^^^^^^^^^^^^
  File "/usr/lib/python3/dist-packages/discord/gateway.py", line 372, in from_client
    socket = await client.http.ws_connect(str(url))
             ^^^^^^^^^^^^^^^^^^^^^^^^^^^^^^^^^^^^^^
  File "/usr/lib/python3/dist-packages/discord/http.py", line 536, in ws_connect
    return await self.__session.ws_connect(url, **kwargs)
           ^^^^^^^^^^^^^^^^^^^^^^^^^^^^^^^^^^^^^^^^^^^^^^
  File "/usr/lib/python3/dist-packages/aiohttp/client.py", line 779, in _ws_connect
    resp = await self.request(
           ^^^^^^^^^^^^^^^^^^^
  File "/usr/lib/python3/dist-packages/aiohttp/client.py", line 536, in _request
    conn = await self._connector.connect(
           ^^^^^^^^^^^^^^^^^^^^^^^^^^^^^^
  File "/usr/lib/python3/dist-packages/aiohttp/connector.py", line 540, in connect
    proto = await self._create_connection(req, traces, timeout)
            ^^^^^^^^^^^^^^^^^^^^^^^^^^^^^^^^^^^^^^^^^^^^^^^^^^^
  File "/usr/lib/python3/dist-packages/aiohttp/connector.py", line 901, in _create_connection
    _, proto = await self._create_direct_connection(req, traces, timeout)
               ^^^^^^^^^^^^^^^^^^^^^^^^^^^^^^^^^^^^^^^^^^^^^^^^^^^^^^^^^^
  File "/usr/lib/python3/dist-packages/aiohttp/connector.py", line 1166, in _create_direct_connection
    raise ClientConnectorError(req.connection_key, exc) from exc
aiohttp.client_exceptions.ClientConnectorError: Cannot connect to host gateway-us-east1-c.discord.gg:443 ssl:default [Temporary failure in name resolution]
2024-06-05 22:45:38,456 - discord_bot - ERROR - Failed to purge or send message in people-in-studio: Cannot connect to host discord.com:443 ssl:default [Temporary failure in name resolution]
2024-06-05 22:47:38,460 - discord_bot - ERROR - Failed to purge or send message in people-in-studio: Cannot connect to host discord.com:443 ssl:default [Temporary failure in name resolution]
2024-06-05 22:49:38,463 - discord_bot - ERROR - Failed to purge or send message in people-in-studio: Cannot connect to host discord.com:443 ssl:default [Temporary failure in name resolution]
2024-06-05 22:50:52,637 - discord.client - ERROR - Attempting a reconnect in 868.86s
Traceback (most recent call last):
  File "/usr/lib/python3/dist-packages/aiohttp/connector.py", line 1152, in _create_direct_connection
    hosts = await asyncio.shield(host_resolved)
            ^^^^^^^^^^^^^^^^^^^^^^^^^^^^^^^^^^^
  File "/usr/lib/python3/dist-packages/aiohttp/connector.py", line 874, in _resolve_host
    addrs = await self._resolver.resolve(host, port, family=self._family)
            ^^^^^^^^^^^^^^^^^^^^^^^^^^^^^^^^^^^^^^^^^^^^^^^^^^^^^^^^^^^^^
  File "/usr/lib/python3/dist-packages/aiohttp/resolver.py", line 33, in resolve
    infos = await self._loop.getaddrinfo(
            ^^^^^^^^^^^^^^^^^^^^^^^^^^^^^
  File "/usr/lib/python3.11/asyncio/base_events.py", line 867, in getaddrinfo
    return await self.run_in_executor(
           ^^^^^^^^^^^^^^^^^^^^^^^^^^^
  File "/usr/lib/python3.11/concurrent/futures/thread.py", line 58, in run
    result = self.fn(*self.args, **self.kwargs)
             ^^^^^^^^^^^^^^^^^^^^^^^^^^^^^^^^^^
  File "/usr/lib/python3.11/socket.py", line 962, in getaddrinfo
    for res in _socket.getaddrinfo(host, port, family, type, proto, flags):
               ^^^^^^^^^^^^^^^^^^^^^^^^^^^^^^^^^^^^^^^^^^^^^^^^^^^^^^^^^^^
socket.gaierror: [Errno -3] Temporary failure in name resolution

The above exception was the direct cause of the following exception:

Traceback (most recent call last):
  File "/usr/lib/python3/dist-packages/discord/client.py", line 656, in connect
    self.ws = await asyncio.wait_for(coro, timeout=60.0)
              ^^^^^^^^^^^^^^^^^^^^^^^^^^^^^^^^^^^^^^^^^^
  File "/usr/lib/python3.11/asyncio/tasks.py", line 479, in wait_for
    return fut.result()
           ^^^^^^^^^^^^
  File "/usr/lib/python3/dist-packages/discord/gateway.py", line 372, in from_client
    socket = await client.http.ws_connect(str(url))
             ^^^^^^^^^^^^^^^^^^^^^^^^^^^^^^^^^^^^^^
  File "/usr/lib/python3/dist-packages/discord/http.py", line 536, in ws_connect
    return await self.__session.ws_connect(url, **kwargs)
           ^^^^^^^^^^^^^^^^^^^^^^^^^^^^^^^^^^^^^^^^^^^^^^
  File "/usr/lib/python3/dist-packages/aiohttp/client.py", line 779, in _ws_connect
    resp = await self.request(
           ^^^^^^^^^^^^^^^^^^^
  File "/usr/lib/python3/dist-packages/aiohttp/client.py", line 536, in _request
    conn = await self._connector.connect(
           ^^^^^^^^^^^^^^^^^^^^^^^^^^^^^^
  File "/usr/lib/python3/dist-packages/aiohttp/connector.py", line 540, in connect
    proto = await self._create_connection(req, traces, timeout)
            ^^^^^^^^^^^^^^^^^^^^^^^^^^^^^^^^^^^^^^^^^^^^^^^^^^^
  File "/usr/lib/python3/dist-packages/aiohttp/connector.py", line 901, in _create_connection
    _, proto = await self._create_direct_connection(req, traces, timeout)
               ^^^^^^^^^^^^^^^^^^^^^^^^^^^^^^^^^^^^^^^^^^^^^^^^^^^^^^^^^^
  File "/usr/lib/python3/dist-packages/aiohttp/connector.py", line 1166, in _create_direct_connection
    raise ClientConnectorError(req.connection_key, exc) from exc
aiohttp.client_exceptions.ClientConnectorError: Cannot connect to host gateway-us-east1-c.discord.gg:443 ssl:default [Temporary failure in name resolution]
2024-06-05 22:51:38,466 - discord_bot - ERROR - Failed to purge or send message in people-in-studio: Cannot connect to host discord.com:443 ssl:default [Temporary failure in name resolution]
2024-06-05 22:53:38,473 - discord_bot - ERROR - Failed to purge or send message in people-in-studio: Cannot connect to host discord.com:443 ssl:default [Temporary failure in name resolution]
2024-06-05 22:55:38,474 - discord_bot - ERROR - Failed to purge or send message in people-in-studio: Cannot connect to host discord.com:443 ssl:default [Temporary failure in name resolution]
2024-06-05 22:57:38,476 - discord_bot - ERROR - Failed to purge or send message in people-in-studio: Cannot connect to host discord.com:443 ssl:default [Temporary failure in name resolution]
2024-06-05 22:59:38,480 - discord_bot - ERROR - Failed to purge or send message in people-in-studio: Cannot connect to host discord.com:443 ssl:default [Temporary failure in name resolution]
2024-06-05 23:01:38,484 - discord_bot - ERROR - Failed to purge or send message in people-in-studio: Cannot connect to host discord.com:443 ssl:default [Temporary failure in name resolution]
2024-06-05 23:03:38,479 - discord_bot - ERROR - Failed to purge or send message in people-in-studio: Cannot connect to host discord.com:443 ssl:default [Temporary failure in name resolution]
2024-06-05 23:05:21,568 - discord.client - ERROR - Attempting a reconnect in 77.10s
Traceback (most recent call last):
  File "/usr/lib/python3/dist-packages/aiohttp/connector.py", line 1152, in _create_direct_connection
    hosts = await asyncio.shield(host_resolved)
            ^^^^^^^^^^^^^^^^^^^^^^^^^^^^^^^^^^^
  File "/usr/lib/python3/dist-packages/aiohttp/connector.py", line 874, in _resolve_host
    addrs = await self._resolver.resolve(host, port, family=self._family)
            ^^^^^^^^^^^^^^^^^^^^^^^^^^^^^^^^^^^^^^^^^^^^^^^^^^^^^^^^^^^^^
  File "/usr/lib/python3/dist-packages/aiohttp/resolver.py", line 33, in resolve
    infos = await self._loop.getaddrinfo(
            ^^^^^^^^^^^^^^^^^^^^^^^^^^^^^
  File "/usr/lib/python3.11/asyncio/base_events.py", line 867, in getaddrinfo
    return await self.run_in_executor(
           ^^^^^^^^^^^^^^^^^^^^^^^^^^^
  File "/usr/lib/python3.11/concurrent/futures/thread.py", line 58, in run
    result = self.fn(*self.args, **self.kwargs)
             ^^^^^^^^^^^^^^^^^^^^^^^^^^^^^^^^^^
  File "/usr/lib/python3.11/socket.py", line 962, in getaddrinfo
    for res in _socket.getaddrinfo(host, port, family, type, proto, flags):
               ^^^^^^^^^^^^^^^^^^^^^^^^^^^^^^^^^^^^^^^^^^^^^^^^^^^^^^^^^^^
socket.gaierror: [Errno -3] Temporary failure in name resolution

The above exception was the direct cause of the following exception:

Traceback (most recent call last):
  File "/usr/lib/python3/dist-packages/discord/client.py", line 656, in connect
    self.ws = await asyncio.wait_for(coro, timeout=60.0)
              ^^^^^^^^^^^^^^^^^^^^^^^^^^^^^^^^^^^^^^^^^^
  File "/usr/lib/python3.11/asyncio/tasks.py", line 479, in wait_for
    return fut.result()
           ^^^^^^^^^^^^
  File "/usr/lib/python3/dist-packages/discord/gateway.py", line 372, in from_client
    socket = await client.http.ws_connect(str(url))
             ^^^^^^^^^^^^^^^^^^^^^^^^^^^^^^^^^^^^^^
  File "/usr/lib/python3/dist-packages/discord/http.py", line 536, in ws_connect
    return await self.__session.ws_connect(url, **kwargs)
           ^^^^^^^^^^^^^^^^^^^^^^^^^^^^^^^^^^^^^^^^^^^^^^
  File "/usr/lib/python3/dist-packages/aiohttp/client.py", line 779, in _ws_connect
    resp = await self.request(
           ^^^^^^^^^^^^^^^^^^^
  File "/usr/lib/python3/dist-packages/aiohttp/client.py", line 536, in _request
    conn = await self._connector.connect(
           ^^^^^^^^^^^^^^^^^^^^^^^^^^^^^^
  File "/usr/lib/python3/dist-packages/aiohttp/connector.py", line 540, in connect
    proto = await self._create_connection(req, traces, timeout)
            ^^^^^^^^^^^^^^^^^^^^^^^^^^^^^^^^^^^^^^^^^^^^^^^^^^^
  File "/usr/lib/python3/dist-packages/aiohttp/connector.py", line 901, in _create_connection
    _, proto = await self._create_direct_connection(req, traces, timeout)
               ^^^^^^^^^^^^^^^^^^^^^^^^^^^^^^^^^^^^^^^^^^^^^^^^^^^^^^^^^^
  File "/usr/lib/python3/dist-packages/aiohttp/connector.py", line 1166, in _create_direct_connection
    raise ClientConnectorError(req.connection_key, exc) from exc
aiohttp.client_exceptions.ClientConnectorError: Cannot connect to host gateway-us-east1-c.discord.gg:443 ssl:default [Temporary failure in name resolution]
2024-06-05 23:05:38,482 - discord_bot - ERROR - Failed to purge or send message in people-in-studio: Cannot connect to host discord.com:443 ssl:default [Temporary failure in name resolution]
2024-06-05 23:06:38,746 - discord.client - ERROR - Attempting a reconnect in 268.62s
Traceback (most recent call last):
  File "/usr/lib/python3/dist-packages/aiohttp/connector.py", line 1152, in _create_direct_connection
    hosts = await asyncio.shield(host_resolved)
            ^^^^^^^^^^^^^^^^^^^^^^^^^^^^^^^^^^^
  File "/usr/lib/python3/dist-packages/aiohttp/connector.py", line 874, in _resolve_host
    addrs = await self._resolver.resolve(host, port, family=self._family)
            ^^^^^^^^^^^^^^^^^^^^^^^^^^^^^^^^^^^^^^^^^^^^^^^^^^^^^^^^^^^^^
  File "/usr/lib/python3/dist-packages/aiohttp/resolver.py", line 33, in resolve
    infos = await self._loop.getaddrinfo(
            ^^^^^^^^^^^^^^^^^^^^^^^^^^^^^
  File "/usr/lib/python3.11/asyncio/base_events.py", line 867, in getaddrinfo
    return await self.run_in_executor(
           ^^^^^^^^^^^^^^^^^^^^^^^^^^^
  File "/usr/lib/python3.11/concurrent/futures/thread.py", line 58, in run
    result = self.fn(*self.args, **self.kwargs)
             ^^^^^^^^^^^^^^^^^^^^^^^^^^^^^^^^^^
  File "/usr/lib/python3.11/socket.py", line 962, in getaddrinfo
    for res in _socket.getaddrinfo(host, port, family, type, proto, flags):
               ^^^^^^^^^^^^^^^^^^^^^^^^^^^^^^^^^^^^^^^^^^^^^^^^^^^^^^^^^^^
socket.gaierror: [Errno -3] Temporary failure in name resolution

The above exception was the direct cause of the following exception:

Traceback (most recent call last):
  File "/usr/lib/python3/dist-packages/discord/client.py", line 656, in connect
    self.ws = await asyncio.wait_for(coro, timeout=60.0)
              ^^^^^^^^^^^^^^^^^^^^^^^^^^^^^^^^^^^^^^^^^^
  File "/usr/lib/python3.11/asyncio/tasks.py", line 479, in wait_for
    return fut.result()
           ^^^^^^^^^^^^
  File "/usr/lib/python3/dist-packages/discord/gateway.py", line 372, in from_client
    socket = await client.http.ws_connect(str(url))
             ^^^^^^^^^^^^^^^^^^^^^^^^^^^^^^^^^^^^^^
  File "/usr/lib/python3/dist-packages/discord/http.py", line 536, in ws_connect
    return await self.__session.ws_connect(url, **kwargs)
           ^^^^^^^^^^^^^^^^^^^^^^^^^^^^^^^^^^^^^^^^^^^^^^
  File "/usr/lib/python3/dist-packages/aiohttp/client.py", line 779, in _ws_connect
    resp = await self.request(
           ^^^^^^^^^^^^^^^^^^^
  File "/usr/lib/python3/dist-packages/aiohttp/client.py", line 536, in _request
    conn = await self._connector.connect(
           ^^^^^^^^^^^^^^^^^^^^^^^^^^^^^^
  File "/usr/lib/python3/dist-packages/aiohttp/connector.py", line 540, in connect
    proto = await self._create_connection(req, traces, timeout)
            ^^^^^^^^^^^^^^^^^^^^^^^^^^^^^^^^^^^^^^^^^^^^^^^^^^^
  File "/usr/lib/python3/dist-packages/aiohttp/connector.py", line 901, in _create_connection
    _, proto = await self._create_direct_connection(req, traces, timeout)
               ^^^^^^^^^^^^^^^^^^^^^^^^^^^^^^^^^^^^^^^^^^^^^^^^^^^^^^^^^^
  File "/usr/lib/python3/dist-packages/aiohttp/connector.py", line 1166, in _create_direct_connection
    raise ClientConnectorError(req.connection_key, exc) from exc
aiohttp.client_exceptions.ClientConnectorError: Cannot connect to host gateway-us-east1-c.discord.gg:443 ssl:default [Temporary failure in name resolution]
2024-06-05 23:07:38,490 - discord_bot - ERROR - Failed to purge or send message in people-in-studio: Cannot connect to host discord.com:443 ssl:default [Temporary failure in name resolution]
2024-06-05 23:09:38,487 - discord_bot - ERROR - Failed to purge or send message in people-in-studio: Cannot connect to host discord.com:443 ssl:default [Temporary failure in name resolution]
2024-06-05 23:11:07,459 - discord.client - ERROR - Attempting a reconnect in 364.29s
Traceback (most recent call last):
  File "/usr/lib/python3/dist-packages/aiohttp/connector.py", line 1152, in _create_direct_connection
    hosts = await asyncio.shield(host_resolved)
            ^^^^^^^^^^^^^^^^^^^^^^^^^^^^^^^^^^^
  File "/usr/lib/python3/dist-packages/aiohttp/connector.py", line 874, in _resolve_host
    addrs = await self._resolver.resolve(host, port, family=self._family)
            ^^^^^^^^^^^^^^^^^^^^^^^^^^^^^^^^^^^^^^^^^^^^^^^^^^^^^^^^^^^^^
  File "/usr/lib/python3/dist-packages/aiohttp/resolver.py", line 33, in resolve
    infos = await self._loop.getaddrinfo(
            ^^^^^^^^^^^^^^^^^^^^^^^^^^^^^
  File "/usr/lib/python3.11/asyncio/base_events.py", line 867, in getaddrinfo
    return await self.run_in_executor(
           ^^^^^^^^^^^^^^^^^^^^^^^^^^^
  File "/usr/lib/python3.11/concurrent/futures/thread.py", line 58, in run
    result = self.fn(*self.args, **self.kwargs)
             ^^^^^^^^^^^^^^^^^^^^^^^^^^^^^^^^^^
  File "/usr/lib/python3.11/socket.py", line 962, in getaddrinfo
    for res in _socket.getaddrinfo(host, port, family, type, proto, flags):
               ^^^^^^^^^^^^^^^^^^^^^^^^^^^^^^^^^^^^^^^^^^^^^^^^^^^^^^^^^^^
socket.gaierror: [Errno -3] Temporary failure in name resolution

The above exception was the direct cause of the following exception:

Traceback (most recent call last):
  File "/usr/lib/python3/dist-packages/discord/client.py", line 656, in connect
    self.ws = await asyncio.wait_for(coro, timeout=60.0)
              ^^^^^^^^^^^^^^^^^^^^^^^^^^^^^^^^^^^^^^^^^^
  File "/usr/lib/python3.11/asyncio/tasks.py", line 479, in wait_for
    return fut.result()
           ^^^^^^^^^^^^
  File "/usr/lib/python3/dist-packages/discord/gateway.py", line 372, in from_client
    socket = await client.http.ws_connect(str(url))
             ^^^^^^^^^^^^^^^^^^^^^^^^^^^^^^^^^^^^^^
  File "/usr/lib/python3/dist-packages/discord/http.py", line 536, in ws_connect
    return await self.__session.ws_connect(url, **kwargs)
           ^^^^^^^^^^^^^^^^^^^^^^^^^^^^^^^^^^^^^^^^^^^^^^
  File "/usr/lib/python3/dist-packages/aiohttp/client.py", line 779, in _ws_connect
    resp = await self.request(
           ^^^^^^^^^^^^^^^^^^^
  File "/usr/lib/python3/dist-packages/aiohttp/client.py", line 536, in _request
    conn = await self._connector.connect(
           ^^^^^^^^^^^^^^^^^^^^^^^^^^^^^^
  File "/usr/lib/python3/dist-packages/aiohttp/connector.py", line 540, in connect
    proto = await self._create_connection(req, traces, timeout)
            ^^^^^^^^^^^^^^^^^^^^^^^^^^^^^^^^^^^^^^^^^^^^^^^^^^^
  File "/usr/lib/python3/dist-packages/aiohttp/connector.py", line 901, in _create_connection
    _, proto = await self._create_direct_connection(req, traces, timeout)
               ^^^^^^^^^^^^^^^^^^^^^^^^^^^^^^^^^^^^^^^^^^^^^^^^^^^^^^^^^^
  File "/usr/lib/python3/dist-packages/aiohttp/connector.py", line 1166, in _create_direct_connection
    raise ClientConnectorError(req.connection_key, exc) from exc
aiohttp.client_exceptions.ClientConnectorError: Cannot connect to host gateway-us-east1-c.discord.gg:443 ssl:default [Temporary failure in name resolution]
2024-06-05 23:11:38,489 - discord_bot - ERROR - Failed to purge or send message in people-in-studio: Cannot connect to host discord.com:443 ssl:default [Temporary failure in name resolution]
2024-06-05 23:13:38,490 - discord_bot - ERROR - Failed to purge or send message in people-in-studio: Cannot connect to host discord.com:443 ssl:default [Temporary failure in name resolution]
2024-06-05 23:15:38,492 - discord_bot - ERROR - Failed to purge or send message in people-in-studio: Cannot connect to host discord.com:443 ssl:default [Temporary failure in name resolution]
2024-06-05 23:17:11,834 - discord.client - ERROR - Attempting a reconnect in 436.73s
Traceback (most recent call last):
  File "/usr/lib/python3/dist-packages/aiohttp/connector.py", line 1152, in _create_direct_connection
    hosts = await asyncio.shield(host_resolved)
            ^^^^^^^^^^^^^^^^^^^^^^^^^^^^^^^^^^^
  File "/usr/lib/python3/dist-packages/aiohttp/connector.py", line 874, in _resolve_host
    addrs = await self._resolver.resolve(host, port, family=self._family)
            ^^^^^^^^^^^^^^^^^^^^^^^^^^^^^^^^^^^^^^^^^^^^^^^^^^^^^^^^^^^^^
  File "/usr/lib/python3/dist-packages/aiohttp/resolver.py", line 33, in resolve
    infos = await self._loop.getaddrinfo(
            ^^^^^^^^^^^^^^^^^^^^^^^^^^^^^
  File "/usr/lib/python3.11/asyncio/base_events.py", line 867, in getaddrinfo
    return await self.run_in_executor(
           ^^^^^^^^^^^^^^^^^^^^^^^^^^^
  File "/usr/lib/python3.11/concurrent/futures/thread.py", line 58, in run
    result = self.fn(*self.args, **self.kwargs)
             ^^^^^^^^^^^^^^^^^^^^^^^^^^^^^^^^^^
  File "/usr/lib/python3.11/socket.py", line 962, in getaddrinfo
    for res in _socket.getaddrinfo(host, port, family, type, proto, flags):
               ^^^^^^^^^^^^^^^^^^^^^^^^^^^^^^^^^^^^^^^^^^^^^^^^^^^^^^^^^^^
socket.gaierror: [Errno -3] Temporary failure in name resolution

The above exception was the direct cause of the following exception:

Traceback (most recent call last):
  File "/usr/lib/python3/dist-packages/discord/client.py", line 656, in connect
    self.ws = await asyncio.wait_for(coro, timeout=60.0)
              ^^^^^^^^^^^^^^^^^^^^^^^^^^^^^^^^^^^^^^^^^^
  File "/usr/lib/python3.11/asyncio/tasks.py", line 479, in wait_for
    return fut.result()
           ^^^^^^^^^^^^
  File "/usr/lib/python3/dist-packages/discord/gateway.py", line 372, in from_client
    socket = await client.http.ws_connect(str(url))
             ^^^^^^^^^^^^^^^^^^^^^^^^^^^^^^^^^^^^^^
  File "/usr/lib/python3/dist-packages/discord/http.py", line 536, in ws_connect
    return await self.__session.ws_connect(url, **kwargs)
           ^^^^^^^^^^^^^^^^^^^^^^^^^^^^^^^^^^^^^^^^^^^^^^
  File "/usr/lib/python3/dist-packages/aiohttp/client.py", line 779, in _ws_connect
    resp = await self.request(
           ^^^^^^^^^^^^^^^^^^^
  File "/usr/lib/python3/dist-packages/aiohttp/client.py", line 536, in _request
    conn = await self._connector.connect(
           ^^^^^^^^^^^^^^^^^^^^^^^^^^^^^^
  File "/usr/lib/python3/dist-packages/aiohttp/connector.py", line 540, in connect
    proto = await self._create_connection(req, traces, timeout)
            ^^^^^^^^^^^^^^^^^^^^^^^^^^^^^^^^^^^^^^^^^^^^^^^^^^^
  File "/usr/lib/python3/dist-packages/aiohttp/connector.py", line 901, in _create_connection
    _, proto = await self._create_direct_connection(req, traces, timeout)
               ^^^^^^^^^^^^^^^^^^^^^^^^^^^^^^^^^^^^^^^^^^^^^^^^^^^^^^^^^^
  File "/usr/lib/python3/dist-packages/aiohttp/connector.py", line 1166, in _create_direct_connection
    raise ClientConnectorError(req.connection_key, exc) from exc
aiohttp.client_exceptions.ClientConnectorError: Cannot connect to host gateway-us-east1-c.discord.gg:443 ssl:default [Temporary failure in name resolution]
2024-06-05 23:17:38,495 - discord_bot - ERROR - Failed to purge or send message in people-in-studio: Cannot connect to host discord.com:443 ssl:default [Temporary failure in name resolution]
2024-06-05 23:19:38,498 - discord_bot - ERROR - Failed to purge or send message in people-in-studio: Cannot connect to host discord.com:443 ssl:default [Temporary failure in name resolution]
2024-06-05 23:21:38,507 - discord_bot - ERROR - Failed to purge or send message in people-in-studio: Cannot connect to host discord.com:443 ssl:default [Temporary failure in name resolution]
2024-06-05 23:23:38,505 - discord_bot - ERROR - Failed to purge or send message in people-in-studio: Cannot connect to host discord.com:443 ssl:default [Temporary failure in name resolution]
2024-06-05 23:24:28,586 - discord.client - ERROR - Attempting a reconnect in 147.95s
Traceback (most recent call last):
  File "/usr/lib/python3/dist-packages/aiohttp/connector.py", line 1152, in _create_direct_connection
    hosts = await asyncio.shield(host_resolved)
            ^^^^^^^^^^^^^^^^^^^^^^^^^^^^^^^^^^^
  File "/usr/lib/python3/dist-packages/aiohttp/connector.py", line 874, in _resolve_host
    addrs = await self._resolver.resolve(host, port, family=self._family)
            ^^^^^^^^^^^^^^^^^^^^^^^^^^^^^^^^^^^^^^^^^^^^^^^^^^^^^^^^^^^^^
  File "/usr/lib/python3/dist-packages/aiohttp/resolver.py", line 33, in resolve
    infos = await self._loop.getaddrinfo(
            ^^^^^^^^^^^^^^^^^^^^^^^^^^^^^
  File "/usr/lib/python3.11/asyncio/base_events.py", line 867, in getaddrinfo
    return await self.run_in_executor(
           ^^^^^^^^^^^^^^^^^^^^^^^^^^^
  File "/usr/lib/python3.11/concurrent/futures/thread.py", line 58, in run
    result = self.fn(*self.args, **self.kwargs)
             ^^^^^^^^^^^^^^^^^^^^^^^^^^^^^^^^^^
  File "/usr/lib/python3.11/socket.py", line 962, in getaddrinfo
    for res in _socket.getaddrinfo(host, port, family, type, proto, flags):
               ^^^^^^^^^^^^^^^^^^^^^^^^^^^^^^^^^^^^^^^^^^^^^^^^^^^^^^^^^^^
socket.gaierror: [Errno -3] Temporary failure in name resolution

The above exception was the direct cause of the following exception:

Traceback (most recent call last):
  File "/usr/lib/python3/dist-packages/discord/client.py", line 656, in connect
    self.ws = await asyncio.wait_for(coro, timeout=60.0)
              ^^^^^^^^^^^^^^^^^^^^^^^^^^^^^^^^^^^^^^^^^^
  File "/usr/lib/python3.11/asyncio/tasks.py", line 479, in wait_for
    return fut.result()
           ^^^^^^^^^^^^
  File "/usr/lib/python3/dist-packages/discord/gateway.py", line 372, in from_client
    socket = await client.http.ws_connect(str(url))
             ^^^^^^^^^^^^^^^^^^^^^^^^^^^^^^^^^^^^^^
  File "/usr/lib/python3/dist-packages/discord/http.py", line 536, in ws_connect
    return await self.__session.ws_connect(url, **kwargs)
           ^^^^^^^^^^^^^^^^^^^^^^^^^^^^^^^^^^^^^^^^^^^^^^
  File "/usr/lib/python3/dist-packages/aiohttp/client.py", line 779, in _ws_connect
    resp = await self.request(
           ^^^^^^^^^^^^^^^^^^^
  File "/usr/lib/python3/dist-packages/aiohttp/client.py", line 536, in _request
    conn = await self._connector.connect(
           ^^^^^^^^^^^^^^^^^^^^^^^^^^^^^^
  File "/usr/lib/python3/dist-packages/aiohttp/connector.py", line 540, in connect
    proto = await self._create_connection(req, traces, timeout)
            ^^^^^^^^^^^^^^^^^^^^^^^^^^^^^^^^^^^^^^^^^^^^^^^^^^^
  File "/usr/lib/python3/dist-packages/aiohttp/connector.py", line 901, in _create_connection
    _, proto = await self._create_direct_connection(req, traces, timeout)
               ^^^^^^^^^^^^^^^^^^^^^^^^^^^^^^^^^^^^^^^^^^^^^^^^^^^^^^^^^^
  File "/usr/lib/python3/dist-packages/aiohttp/connector.py", line 1166, in _create_direct_connection
    raise ClientConnectorError(req.connection_key, exc) from exc
aiohttp.client_exceptions.ClientConnectorError: Cannot connect to host gateway-us-east1-c.discord.gg:443 ssl:default [Temporary failure in name resolution]
2024-06-05 23:25:38,506 - discord_bot - ERROR - Failed to purge or send message in people-in-studio: Cannot connect to host discord.com:443 ssl:default [Temporary failure in name resolution]
2024-06-05 23:26:56,607 - discord.client - ERROR - Attempting a reconnect in 657.98s
Traceback (most recent call last):
  File "/usr/lib/python3/dist-packages/aiohttp/connector.py", line 1152, in _create_direct_connection
    hosts = await asyncio.shield(host_resolved)
            ^^^^^^^^^^^^^^^^^^^^^^^^^^^^^^^^^^^
  File "/usr/lib/python3/dist-packages/aiohttp/connector.py", line 874, in _resolve_host
    addrs = await self._resolver.resolve(host, port, family=self._family)
            ^^^^^^^^^^^^^^^^^^^^^^^^^^^^^^^^^^^^^^^^^^^^^^^^^^^^^^^^^^^^^
  File "/usr/lib/python3/dist-packages/aiohttp/resolver.py", line 33, in resolve
    infos = await self._loop.getaddrinfo(
            ^^^^^^^^^^^^^^^^^^^^^^^^^^^^^
  File "/usr/lib/python3.11/asyncio/base_events.py", line 867, in getaddrinfo
    return await self.run_in_executor(
           ^^^^^^^^^^^^^^^^^^^^^^^^^^^
  File "/usr/lib/python3.11/concurrent/futures/thread.py", line 58, in run
    result = self.fn(*self.args, **self.kwargs)
             ^^^^^^^^^^^^^^^^^^^^^^^^^^^^^^^^^^
  File "/usr/lib/python3.11/socket.py", line 962, in getaddrinfo
    for res in _socket.getaddrinfo(host, port, family, type, proto, flags):
               ^^^^^^^^^^^^^^^^^^^^^^^^^^^^^^^^^^^^^^^^^^^^^^^^^^^^^^^^^^^
socket.gaierror: [Errno -3] Temporary failure in name resolution

The above exception was the direct cause of the following exception:

Traceback (most recent call last):
  File "/usr/lib/python3/dist-packages/discord/client.py", line 656, in connect
    self.ws = await asyncio.wait_for(coro, timeout=60.0)
              ^^^^^^^^^^^^^^^^^^^^^^^^^^^^^^^^^^^^^^^^^^
  File "/usr/lib/python3.11/asyncio/tasks.py", line 479, in wait_for
    return fut.result()
           ^^^^^^^^^^^^
  File "/usr/lib/python3/dist-packages/discord/gateway.py", line 372, in from_client
    socket = await client.http.ws_connect(str(url))
             ^^^^^^^^^^^^^^^^^^^^^^^^^^^^^^^^^^^^^^
  File "/usr/lib/python3/dist-packages/discord/http.py", line 536, in ws_connect
    return await self.__session.ws_connect(url, **kwargs)
           ^^^^^^^^^^^^^^^^^^^^^^^^^^^^^^^^^^^^^^^^^^^^^^
  File "/usr/lib/python3/dist-packages/aiohttp/client.py", line 779, in _ws_connect
    resp = await self.request(
           ^^^^^^^^^^^^^^^^^^^
  File "/usr/lib/python3/dist-packages/aiohttp/client.py", line 536, in _request
    conn = await self._connector.connect(
           ^^^^^^^^^^^^^^^^^^^^^^^^^^^^^^
  File "/usr/lib/python3/dist-packages/aiohttp/connector.py", line 540, in connect
    proto = await self._create_connection(req, traces, timeout)
            ^^^^^^^^^^^^^^^^^^^^^^^^^^^^^^^^^^^^^^^^^^^^^^^^^^^
  File "/usr/lib/python3/dist-packages/aiohttp/connector.py", line 901, in _create_connection
    _, proto = await self._create_direct_connection(req, traces, timeout)
               ^^^^^^^^^^^^^^^^^^^^^^^^^^^^^^^^^^^^^^^^^^^^^^^^^^^^^^^^^^
  File "/usr/lib/python3/dist-packages/aiohttp/connector.py", line 1166, in _create_direct_connection
    raise ClientConnectorError(req.connection_key, exc) from exc
aiohttp.client_exceptions.ClientConnectorError: Cannot connect to host gateway-us-east1-c.discord.gg:443 ssl:default [Temporary failure in name resolution]
2024-06-05 23:27:38,508 - discord_bot - ERROR - Failed to purge or send message in people-in-studio: Cannot connect to host discord.com:443 ssl:default [Temporary failure in name resolution]
2024-06-05 23:29:38,509 - discord_bot - ERROR - Failed to purge or send message in people-in-studio: Cannot connect to host discord.com:443 ssl:default [Temporary failure in name resolution]
2024-06-05 23:31:38,519 - discord_bot - ERROR - Failed to purge or send message in people-in-studio: Cannot connect to host discord.com:443 ssl:default [Temporary failure in name resolution]
2024-06-05 23:33:38,514 - discord_bot - ERROR - Failed to purge or send message in people-in-studio: Cannot connect to host discord.com:443 ssl:default [Temporary failure in name resolution]
2024-06-05 23:35:38,516 - discord_bot - ERROR - Failed to purge or send message in people-in-studio: Cannot connect to host discord.com:443 ssl:default [Temporary failure in name resolution]
2024-06-05 23:37:38,526 - discord_bot - ERROR - Failed to purge or send message in people-in-studio: Cannot connect to host discord.com:443 ssl:default [Temporary failure in name resolution]
2024-06-05 23:37:54,609 - discord.client - ERROR - Attempting a reconnect in 1018.17s
Traceback (most recent call last):
  File "/usr/lib/python3/dist-packages/aiohttp/connector.py", line 1152, in _create_direct_connection
    hosts = await asyncio.shield(host_resolved)
            ^^^^^^^^^^^^^^^^^^^^^^^^^^^^^^^^^^^
  File "/usr/lib/python3/dist-packages/aiohttp/connector.py", line 874, in _resolve_host
    addrs = await self._resolver.resolve(host, port, family=self._family)
            ^^^^^^^^^^^^^^^^^^^^^^^^^^^^^^^^^^^^^^^^^^^^^^^^^^^^^^^^^^^^^
  File "/usr/lib/python3/dist-packages/aiohttp/resolver.py", line 33, in resolve
    infos = await self._loop.getaddrinfo(
            ^^^^^^^^^^^^^^^^^^^^^^^^^^^^^
  File "/usr/lib/python3.11/asyncio/base_events.py", line 867, in getaddrinfo
    return await self.run_in_executor(
           ^^^^^^^^^^^^^^^^^^^^^^^^^^^
  File "/usr/lib/python3.11/concurrent/futures/thread.py", line 58, in run
    result = self.fn(*self.args, **self.kwargs)
             ^^^^^^^^^^^^^^^^^^^^^^^^^^^^^^^^^^
  File "/usr/lib/python3.11/socket.py", line 962, in getaddrinfo
    for res in _socket.getaddrinfo(host, port, family, type, proto, flags):
               ^^^^^^^^^^^^^^^^^^^^^^^^^^^^^^^^^^^^^^^^^^^^^^^^^^^^^^^^^^^
socket.gaierror: [Errno -3] Temporary failure in name resolution

The above exception was the direct cause of the following exception:

Traceback (most recent call last):
  File "/usr/lib/python3/dist-packages/discord/client.py", line 656, in connect
    self.ws = await asyncio.wait_for(coro, timeout=60.0)
              ^^^^^^^^^^^^^^^^^^^^^^^^^^^^^^^^^^^^^^^^^^
  File "/usr/lib/python3.11/asyncio/tasks.py", line 479, in wait_for
    return fut.result()
           ^^^^^^^^^^^^
  File "/usr/lib/python3/dist-packages/discord/gateway.py", line 372, in from_client
    socket = await client.http.ws_connect(str(url))
             ^^^^^^^^^^^^^^^^^^^^^^^^^^^^^^^^^^^^^^
  File "/usr/lib/python3/dist-packages/discord/http.py", line 536, in ws_connect
    return await self.__session.ws_connect(url, **kwargs)
           ^^^^^^^^^^^^^^^^^^^^^^^^^^^^^^^^^^^^^^^^^^^^^^
  File "/usr/lib/python3/dist-packages/aiohttp/client.py", line 779, in _ws_connect
    resp = await self.request(
           ^^^^^^^^^^^^^^^^^^^
  File "/usr/lib/python3/dist-packages/aiohttp/client.py", line 536, in _request
    conn = await self._connector.connect(
           ^^^^^^^^^^^^^^^^^^^^^^^^^^^^^^
  File "/usr/lib/python3/dist-packages/aiohttp/connector.py", line 540, in connect
    proto = await self._create_connection(req, traces, timeout)
            ^^^^^^^^^^^^^^^^^^^^^^^^^^^^^^^^^^^^^^^^^^^^^^^^^^^
  File "/usr/lib/python3/dist-packages/aiohttp/connector.py", line 901, in _create_connection
    _, proto = await self._create_direct_connection(req, traces, timeout)
               ^^^^^^^^^^^^^^^^^^^^^^^^^^^^^^^^^^^^^^^^^^^^^^^^^^^^^^^^^^
  File "/usr/lib/python3/dist-packages/aiohttp/connector.py", line 1166, in _create_direct_connection
    raise ClientConnectorError(req.connection_key, exc) from exc
aiohttp.client_exceptions.ClientConnectorError: Cannot connect to host gateway-us-east1-c.discord.gg:443 ssl:default [Temporary failure in name resolution]
2024-06-05 23:39:38,521 - discord_bot - ERROR - Failed to purge or send message in people-in-studio: Cannot connect to host discord.com:443 ssl:default [Temporary failure in name resolution]
2024-06-05 23:41:38,523 - discord_bot - ERROR - Failed to purge or send message in people-in-studio: Cannot connect to host discord.com:443 ssl:default [Temporary failure in name resolution]
2024-06-05 23:43:38,532 - discord_bot - ERROR - Failed to purge or send message in people-in-studio: Cannot connect to host discord.com:443 ssl:default [Temporary failure in name resolution]
2024-06-05 23:45:38,536 - discord_bot - ERROR - Failed to purge or send message in people-in-studio: Cannot connect to host discord.com:443 ssl:default [Temporary failure in name resolution]
2024-06-05 23:47:38,541 - discord_bot - ERROR - Failed to purge or send message in people-in-studio: Cannot connect to host discord.com:443 ssl:default [Temporary failure in name resolution]
2024-06-05 23:49:38,545 - discord_bot - ERROR - Failed to purge or send message in people-in-studio: Cannot connect to host discord.com:443 ssl:default [Temporary failure in name resolution]
2024-06-05 23:51:38,551 - discord_bot - ERROR - Failed to purge or send message in people-in-studio: Cannot connect to host discord.com:443 ssl:default [Temporary failure in name resolution]
2024-06-05 23:53:38,554 - discord_bot - ERROR - Failed to purge or send message in people-in-studio: Cannot connect to host discord.com:443 ssl:default [Temporary failure in name resolution]
2024-06-05 23:54:52,841 - discord.client - ERROR - Attempting a reconnect in 34.04s
Traceback (most recent call last):
  File "/usr/lib/python3/dist-packages/aiohttp/connector.py", line 1152, in _create_direct_connection
    hosts = await asyncio.shield(host_resolved)
            ^^^^^^^^^^^^^^^^^^^^^^^^^^^^^^^^^^^
  File "/usr/lib/python3/dist-packages/aiohttp/connector.py", line 874, in _resolve_host
    addrs = await self._resolver.resolve(host, port, family=self._family)
            ^^^^^^^^^^^^^^^^^^^^^^^^^^^^^^^^^^^^^^^^^^^^^^^^^^^^^^^^^^^^^
  File "/usr/lib/python3/dist-packages/aiohttp/resolver.py", line 33, in resolve
    infos = await self._loop.getaddrinfo(
            ^^^^^^^^^^^^^^^^^^^^^^^^^^^^^
  File "/usr/lib/python3.11/asyncio/base_events.py", line 867, in getaddrinfo
    return await self.run_in_executor(
           ^^^^^^^^^^^^^^^^^^^^^^^^^^^
  File "/usr/lib/python3.11/concurrent/futures/thread.py", line 58, in run
    result = self.fn(*self.args, **self.kwargs)
             ^^^^^^^^^^^^^^^^^^^^^^^^^^^^^^^^^^
  File "/usr/lib/python3.11/socket.py", line 962, in getaddrinfo
    for res in _socket.getaddrinfo(host, port, family, type, proto, flags):
               ^^^^^^^^^^^^^^^^^^^^^^^^^^^^^^^^^^^^^^^^^^^^^^^^^^^^^^^^^^^
socket.gaierror: [Errno -3] Temporary failure in name resolution

The above exception was the direct cause of the following exception:

Traceback (most recent call last):
  File "/usr/lib/python3/dist-packages/discord/client.py", line 656, in connect
    self.ws = await asyncio.wait_for(coro, timeout=60.0)
              ^^^^^^^^^^^^^^^^^^^^^^^^^^^^^^^^^^^^^^^^^^
  File "/usr/lib/python3.11/asyncio/tasks.py", line 479, in wait_for
    return fut.result()
           ^^^^^^^^^^^^
  File "/usr/lib/python3/dist-packages/discord/gateway.py", line 372, in from_client
    socket = await client.http.ws_connect(str(url))
             ^^^^^^^^^^^^^^^^^^^^^^^^^^^^^^^^^^^^^^
  File "/usr/lib/python3/dist-packages/discord/http.py", line 536, in ws_connect
    return await self.__session.ws_connect(url, **kwargs)
           ^^^^^^^^^^^^^^^^^^^^^^^^^^^^^^^^^^^^^^^^^^^^^^
  File "/usr/lib/python3/dist-packages/aiohttp/client.py", line 779, in _ws_connect
    resp = await self.request(
           ^^^^^^^^^^^^^^^^^^^
  File "/usr/lib/python3/dist-packages/aiohttp/client.py", line 536, in _request
    conn = await self._connector.connect(
           ^^^^^^^^^^^^^^^^^^^^^^^^^^^^^^
  File "/usr/lib/python3/dist-packages/aiohttp/connector.py", line 540, in connect
    proto = await self._create_connection(req, traces, timeout)
            ^^^^^^^^^^^^^^^^^^^^^^^^^^^^^^^^^^^^^^^^^^^^^^^^^^^
  File "/usr/lib/python3/dist-packages/aiohttp/connector.py", line 901, in _create_connection
    _, proto = await self._create_direct_connection(req, traces, timeout)
               ^^^^^^^^^^^^^^^^^^^^^^^^^^^^^^^^^^^^^^^^^^^^^^^^^^^^^^^^^^
  File "/usr/lib/python3/dist-packages/aiohttp/connector.py", line 1166, in _create_direct_connection
    raise ClientConnectorError(req.connection_key, exc) from exc
aiohttp.client_exceptions.ClientConnectorError: Cannot connect to host gateway-us-east1-c.discord.gg:443 ssl:default [Temporary failure in name resolution]
2024-06-05 23:55:26,909 - discord.client - ERROR - Attempting a reconnect in 517.16s
Traceback (most recent call last):
  File "/usr/lib/python3/dist-packages/aiohttp/connector.py", line 1152, in _create_direct_connection
    hosts = await asyncio.shield(host_resolved)
            ^^^^^^^^^^^^^^^^^^^^^^^^^^^^^^^^^^^
  File "/usr/lib/python3/dist-packages/aiohttp/connector.py", line 874, in _resolve_host
    addrs = await self._resolver.resolve(host, port, family=self._family)
            ^^^^^^^^^^^^^^^^^^^^^^^^^^^^^^^^^^^^^^^^^^^^^^^^^^^^^^^^^^^^^
  File "/usr/lib/python3/dist-packages/aiohttp/resolver.py", line 33, in resolve
    infos = await self._loop.getaddrinfo(
            ^^^^^^^^^^^^^^^^^^^^^^^^^^^^^
  File "/usr/lib/python3.11/asyncio/base_events.py", line 867, in getaddrinfo
    return await self.run_in_executor(
           ^^^^^^^^^^^^^^^^^^^^^^^^^^^
  File "/usr/lib/python3.11/concurrent/futures/thread.py", line 58, in run
    result = self.fn(*self.args, **self.kwargs)
             ^^^^^^^^^^^^^^^^^^^^^^^^^^^^^^^^^^
  File "/usr/lib/python3.11/socket.py", line 962, in getaddrinfo
    for res in _socket.getaddrinfo(host, port, family, type, proto, flags):
               ^^^^^^^^^^^^^^^^^^^^^^^^^^^^^^^^^^^^^^^^^^^^^^^^^^^^^^^^^^^
socket.gaierror: [Errno -3] Temporary failure in name resolution

The above exception was the direct cause of the following exception:

Traceback (most recent call last):
  File "/usr/lib/python3/dist-packages/discord/client.py", line 656, in connect
    self.ws = await asyncio.wait_for(coro, timeout=60.0)
              ^^^^^^^^^^^^^^^^^^^^^^^^^^^^^^^^^^^^^^^^^^
  File "/usr/lib/python3.11/asyncio/tasks.py", line 479, in wait_for
    return fut.result()
           ^^^^^^^^^^^^
  File "/usr/lib/python3/dist-packages/discord/gateway.py", line 372, in from_client
    socket = await client.http.ws_connect(str(url))
             ^^^^^^^^^^^^^^^^^^^^^^^^^^^^^^^^^^^^^^
  File "/usr/lib/python3/dist-packages/discord/http.py", line 536, in ws_connect
    return await self.__session.ws_connect(url, **kwargs)
           ^^^^^^^^^^^^^^^^^^^^^^^^^^^^^^^^^^^^^^^^^^^^^^
  File "/usr/lib/python3/dist-packages/aiohttp/client.py", line 779, in _ws_connect
    resp = await self.request(
           ^^^^^^^^^^^^^^^^^^^
  File "/usr/lib/python3/dist-packages/aiohttp/client.py", line 536, in _request
    conn = await self._connector.connect(
           ^^^^^^^^^^^^^^^^^^^^^^^^^^^^^^
  File "/usr/lib/python3/dist-packages/aiohttp/connector.py", line 540, in connect
    proto = await self._create_connection(req, traces, timeout)
            ^^^^^^^^^^^^^^^^^^^^^^^^^^^^^^^^^^^^^^^^^^^^^^^^^^^
  File "/usr/lib/python3/dist-packages/aiohttp/connector.py", line 901, in _create_connection
    _, proto = await self._create_direct_connection(req, traces, timeout)
               ^^^^^^^^^^^^^^^^^^^^^^^^^^^^^^^^^^^^^^^^^^^^^^^^^^^^^^^^^^
  File "/usr/lib/python3/dist-packages/aiohttp/connector.py", line 1166, in _create_direct_connection
    raise ClientConnectorError(req.connection_key, exc) from exc
aiohttp.client_exceptions.ClientConnectorError: Cannot connect to host gateway-us-east1-c.discord.gg:443 ssl:default [Temporary failure in name resolution]
2024-06-05 23:55:38,557 - discord_bot - ERROR - Failed to purge or send message in people-in-studio: Cannot connect to host discord.com:443 ssl:default [Temporary failure in name resolution]
2024-06-05 23:57:38,563 - discord_bot - ERROR - Failed to purge or send message in people-in-studio: Cannot connect to host discord.com:443 ssl:default [Temporary failure in name resolution]
2024-06-05 23:59:38,566 - discord_bot - ERROR - Failed to purge or send message in people-in-studio: Cannot connect to host discord.com:443 ssl:default [Temporary failure in name resolution]
2024-06-06 00:01:38,571 - discord_bot - ERROR - Failed to purge or send message in people-in-studio: Cannot connect to host discord.com:443 ssl:default [Temporary failure in name resolution]
2024-06-06 00:03:38,574 - discord_bot - ERROR - Failed to purge or send message in people-in-studio: Cannot connect to host discord.com:443 ssl:default [Temporary failure in name resolution]
2024-06-06 00:04:04,106 - discord.client - ERROR - Attempting a reconnect in 618.67s
Traceback (most recent call last):
  File "/usr/lib/python3/dist-packages/aiohttp/connector.py", line 1152, in _create_direct_connection
    hosts = await asyncio.shield(host_resolved)
            ^^^^^^^^^^^^^^^^^^^^^^^^^^^^^^^^^^^
  File "/usr/lib/python3/dist-packages/aiohttp/connector.py", line 874, in _resolve_host
    addrs = await self._resolver.resolve(host, port, family=self._family)
            ^^^^^^^^^^^^^^^^^^^^^^^^^^^^^^^^^^^^^^^^^^^^^^^^^^^^^^^^^^^^^
  File "/usr/lib/python3/dist-packages/aiohttp/resolver.py", line 33, in resolve
    infos = await self._loop.getaddrinfo(
            ^^^^^^^^^^^^^^^^^^^^^^^^^^^^^
  File "/usr/lib/python3.11/asyncio/base_events.py", line 867, in getaddrinfo
    return await self.run_in_executor(
           ^^^^^^^^^^^^^^^^^^^^^^^^^^^
  File "/usr/lib/python3.11/concurrent/futures/thread.py", line 58, in run
    result = self.fn(*self.args, **self.kwargs)
             ^^^^^^^^^^^^^^^^^^^^^^^^^^^^^^^^^^
  File "/usr/lib/python3.11/socket.py", line 962, in getaddrinfo
    for res in _socket.getaddrinfo(host, port, family, type, proto, flags):
               ^^^^^^^^^^^^^^^^^^^^^^^^^^^^^^^^^^^^^^^^^^^^^^^^^^^^^^^^^^^
socket.gaierror: [Errno -3] Temporary failure in name resolution

The above exception was the direct cause of the following exception:

Traceback (most recent call last):
  File "/usr/lib/python3/dist-packages/discord/client.py", line 656, in connect
    self.ws = await asyncio.wait_for(coro, timeout=60.0)
              ^^^^^^^^^^^^^^^^^^^^^^^^^^^^^^^^^^^^^^^^^^
  File "/usr/lib/python3.11/asyncio/tasks.py", line 479, in wait_for
    return fut.result()
           ^^^^^^^^^^^^
  File "/usr/lib/python3/dist-packages/discord/gateway.py", line 372, in from_client
    socket = await client.http.ws_connect(str(url))
             ^^^^^^^^^^^^^^^^^^^^^^^^^^^^^^^^^^^^^^
  File "/usr/lib/python3/dist-packages/discord/http.py", line 536, in ws_connect
    return await self.__session.ws_connect(url, **kwargs)
           ^^^^^^^^^^^^^^^^^^^^^^^^^^^^^^^^^^^^^^^^^^^^^^
  File "/usr/lib/python3/dist-packages/aiohttp/client.py", line 779, in _ws_connect
    resp = await self.request(
           ^^^^^^^^^^^^^^^^^^^
  File "/usr/lib/python3/dist-packages/aiohttp/client.py", line 536, in _request
    conn = await self._connector.connect(
           ^^^^^^^^^^^^^^^^^^^^^^^^^^^^^^
  File "/usr/lib/python3/dist-packages/aiohttp/connector.py", line 540, in connect
    proto = await self._create_connection(req, traces, timeout)
            ^^^^^^^^^^^^^^^^^^^^^^^^^^^^^^^^^^^^^^^^^^^^^^^^^^^
  File "/usr/lib/python3/dist-packages/aiohttp/connector.py", line 901, in _create_connection
    _, proto = await self._create_direct_connection(req, traces, timeout)
               ^^^^^^^^^^^^^^^^^^^^^^^^^^^^^^^^^^^^^^^^^^^^^^^^^^^^^^^^^^
  File "/usr/lib/python3/dist-packages/aiohttp/connector.py", line 1166, in _create_direct_connection
    raise ClientConnectorError(req.connection_key, exc) from exc
aiohttp.client_exceptions.ClientConnectorError: Cannot connect to host gateway-us-east1-c.discord.gg:443 ssl:default [Temporary failure in name resolution]
2024-06-06 00:05:38,582 - discord_bot - ERROR - Failed to purge or send message in people-in-studio: Cannot connect to host discord.com:443 ssl:default [Temporary failure in name resolution]
2024-06-06 00:07:38,580 - discord_bot - ERROR - Failed to purge or send message in people-in-studio: Cannot connect to host discord.com:443 ssl:default [Temporary failure in name resolution]
2024-06-06 00:09:38,584 - discord_bot - ERROR - Failed to purge or send message in people-in-studio: Cannot connect to host discord.com:443 ssl:default [Temporary failure in name resolution]
2024-06-06 00:11:38,588 - discord_bot - ERROR - Failed to purge or send message in people-in-studio: Cannot connect to host discord.com:443 ssl:default [Temporary failure in name resolution]
2024-06-06 00:13:38,591 - discord_bot - ERROR - Failed to purge or send message in people-in-studio: Cannot connect to host discord.com:443 ssl:default [Temporary failure in name resolution]
2024-06-06 00:14:22,816 - discord.client - ERROR - Attempting a reconnect in 414.91s
Traceback (most recent call last):
  File "/usr/lib/python3/dist-packages/aiohttp/connector.py", line 1152, in _create_direct_connection
    hosts = await asyncio.shield(host_resolved)
            ^^^^^^^^^^^^^^^^^^^^^^^^^^^^^^^^^^^
  File "/usr/lib/python3/dist-packages/aiohttp/connector.py", line 874, in _resolve_host
    addrs = await self._resolver.resolve(host, port, family=self._family)
            ^^^^^^^^^^^^^^^^^^^^^^^^^^^^^^^^^^^^^^^^^^^^^^^^^^^^^^^^^^^^^
  File "/usr/lib/python3/dist-packages/aiohttp/resolver.py", line 33, in resolve
    infos = await self._loop.getaddrinfo(
            ^^^^^^^^^^^^^^^^^^^^^^^^^^^^^
  File "/usr/lib/python3.11/asyncio/base_events.py", line 867, in getaddrinfo
    return await self.run_in_executor(
           ^^^^^^^^^^^^^^^^^^^^^^^^^^^
  File "/usr/lib/python3.11/concurrent/futures/thread.py", line 58, in run
    result = self.fn(*self.args, **self.kwargs)
             ^^^^^^^^^^^^^^^^^^^^^^^^^^^^^^^^^^
  File "/usr/lib/python3.11/socket.py", line 962, in getaddrinfo
    for res in _socket.getaddrinfo(host, port, family, type, proto, flags):
               ^^^^^^^^^^^^^^^^^^^^^^^^^^^^^^^^^^^^^^^^^^^^^^^^^^^^^^^^^^^
socket.gaierror: [Errno -3] Temporary failure in name resolution

The above exception was the direct cause of the following exception:

Traceback (most recent call last):
  File "/usr/lib/python3/dist-packages/discord/client.py", line 656, in connect
    self.ws = await asyncio.wait_for(coro, timeout=60.0)
              ^^^^^^^^^^^^^^^^^^^^^^^^^^^^^^^^^^^^^^^^^^
  File "/usr/lib/python3.11/asyncio/tasks.py", line 479, in wait_for
    return fut.result()
           ^^^^^^^^^^^^
  File "/usr/lib/python3/dist-packages/discord/gateway.py", line 372, in from_client
    socket = await client.http.ws_connect(str(url))
             ^^^^^^^^^^^^^^^^^^^^^^^^^^^^^^^^^^^^^^
  File "/usr/lib/python3/dist-packages/discord/http.py", line 536, in ws_connect
    return await self.__session.ws_connect(url, **kwargs)
           ^^^^^^^^^^^^^^^^^^^^^^^^^^^^^^^^^^^^^^^^^^^^^^
  File "/usr/lib/python3/dist-packages/aiohttp/client.py", line 779, in _ws_connect
    resp = await self.request(
           ^^^^^^^^^^^^^^^^^^^
  File "/usr/lib/python3/dist-packages/aiohttp/client.py", line 536, in _request
    conn = await self._connector.connect(
           ^^^^^^^^^^^^^^^^^^^^^^^^^^^^^^
  File "/usr/lib/python3/dist-packages/aiohttp/connector.py", line 540, in connect
    proto = await self._create_connection(req, traces, timeout)
            ^^^^^^^^^^^^^^^^^^^^^^^^^^^^^^^^^^^^^^^^^^^^^^^^^^^
  File "/usr/lib/python3/dist-packages/aiohttp/connector.py", line 901, in _create_connection
    _, proto = await self._create_direct_connection(req, traces, timeout)
               ^^^^^^^^^^^^^^^^^^^^^^^^^^^^^^^^^^^^^^^^^^^^^^^^^^^^^^^^^^
  File "/usr/lib/python3/dist-packages/aiohttp/connector.py", line 1166, in _create_direct_connection
    raise ClientConnectorError(req.connection_key, exc) from exc
aiohttp.client_exceptions.ClientConnectorError: Cannot connect to host gateway-us-east1-c.discord.gg:443 ssl:default [Temporary failure in name resolution]
2024-06-06 00:15:38,594 - discord_bot - ERROR - Failed to purge or send message in people-in-studio: Cannot connect to host discord.com:443 ssl:default [Temporary failure in name resolution]
2024-06-06 00:17:38,599 - discord_bot - ERROR - Failed to purge or send message in people-in-studio: Cannot connect to host discord.com:443 ssl:default [Temporary failure in name resolution]
2024-06-06 00:19:38,601 - discord_bot - ERROR - Failed to purge or send message in people-in-studio: Cannot connect to host discord.com:443 ssl:default [Temporary failure in name resolution]
2024-06-06 00:21:17,845 - discord.client - ERROR - Attempting a reconnect in 454.58s
Traceback (most recent call last):
  File "/usr/lib/python3/dist-packages/aiohttp/connector.py", line 1152, in _create_direct_connection
    hosts = await asyncio.shield(host_resolved)
            ^^^^^^^^^^^^^^^^^^^^^^^^^^^^^^^^^^^
  File "/usr/lib/python3/dist-packages/aiohttp/connector.py", line 874, in _resolve_host
    addrs = await self._resolver.resolve(host, port, family=self._family)
            ^^^^^^^^^^^^^^^^^^^^^^^^^^^^^^^^^^^^^^^^^^^^^^^^^^^^^^^^^^^^^
  File "/usr/lib/python3/dist-packages/aiohttp/resolver.py", line 33, in resolve
    infos = await self._loop.getaddrinfo(
            ^^^^^^^^^^^^^^^^^^^^^^^^^^^^^
  File "/usr/lib/python3.11/asyncio/base_events.py", line 867, in getaddrinfo
    return await self.run_in_executor(
           ^^^^^^^^^^^^^^^^^^^^^^^^^^^
  File "/usr/lib/python3.11/concurrent/futures/thread.py", line 58, in run
    result = self.fn(*self.args, **self.kwargs)
             ^^^^^^^^^^^^^^^^^^^^^^^^^^^^^^^^^^
  File "/usr/lib/python3.11/socket.py", line 962, in getaddrinfo
    for res in _socket.getaddrinfo(host, port, family, type, proto, flags):
               ^^^^^^^^^^^^^^^^^^^^^^^^^^^^^^^^^^^^^^^^^^^^^^^^^^^^^^^^^^^
socket.gaierror: [Errno -3] Temporary failure in name resolution

The above exception was the direct cause of the following exception:

Traceback (most recent call last):
  File "/usr/lib/python3/dist-packages/discord/client.py", line 656, in connect
    self.ws = await asyncio.wait_for(coro, timeout=60.0)
              ^^^^^^^^^^^^^^^^^^^^^^^^^^^^^^^^^^^^^^^^^^
  File "/usr/lib/python3.11/asyncio/tasks.py", line 479, in wait_for
    return fut.result()
           ^^^^^^^^^^^^
  File "/usr/lib/python3/dist-packages/discord/gateway.py", line 372, in from_client
    socket = await client.http.ws_connect(str(url))
             ^^^^^^^^^^^^^^^^^^^^^^^^^^^^^^^^^^^^^^
  File "/usr/lib/python3/dist-packages/discord/http.py", line 536, in ws_connect
    return await self.__session.ws_connect(url, **kwargs)
           ^^^^^^^^^^^^^^^^^^^^^^^^^^^^^^^^^^^^^^^^^^^^^^
  File "/usr/lib/python3/dist-packages/aiohttp/client.py", line 779, in _ws_connect
    resp = await self.request(
           ^^^^^^^^^^^^^^^^^^^
  File "/usr/lib/python3/dist-packages/aiohttp/client.py", line 536, in _request
    conn = await self._connector.connect(
           ^^^^^^^^^^^^^^^^^^^^^^^^^^^^^^
  File "/usr/lib/python3/dist-packages/aiohttp/connector.py", line 540, in connect
    proto = await self._create_connection(req, traces, timeout)
            ^^^^^^^^^^^^^^^^^^^^^^^^^^^^^^^^^^^^^^^^^^^^^^^^^^^
  File "/usr/lib/python3/dist-packages/aiohttp/connector.py", line 901, in _create_connection
    _, proto = await self._create_direct_connection(req, traces, timeout)
               ^^^^^^^^^^^^^^^^^^^^^^^^^^^^^^^^^^^^^^^^^^^^^^^^^^^^^^^^^^
  File "/usr/lib/python3/dist-packages/aiohttp/connector.py", line 1166, in _create_direct_connection
    raise ClientConnectorError(req.connection_key, exc) from exc
aiohttp.client_exceptions.ClientConnectorError: Cannot connect to host gateway-us-east1-c.discord.gg:443 ssl:default [Temporary failure in name resolution]
2024-06-06 00:21:38,604 - discord_bot - ERROR - Failed to purge or send message in people-in-studio: Cannot connect to host discord.com:443 ssl:default [Temporary failure in name resolution]
2024-06-06 00:23:38,606 - discord_bot - ERROR - Failed to purge or send message in people-in-studio: Cannot connect to host discord.com:443 ssl:default [Temporary failure in name resolution]
2024-06-06 00:25:38,611 - discord_bot - ERROR - Failed to purge or send message in people-in-studio: Cannot connect to host discord.com:443 ssl:default [Temporary failure in name resolution]
2024-06-06 00:27:38,616 - discord_bot - ERROR - Failed to purge or send message in people-in-studio: Cannot connect to host discord.com:443 ssl:default [Temporary failure in name resolution]
2024-06-06 00:28:52,446 - discord.client - ERROR - Attempting a reconnect in 1013.83s
Traceback (most recent call last):
  File "/usr/lib/python3/dist-packages/aiohttp/connector.py", line 1152, in _create_direct_connection
    hosts = await asyncio.shield(host_resolved)
            ^^^^^^^^^^^^^^^^^^^^^^^^^^^^^^^^^^^
  File "/usr/lib/python3/dist-packages/aiohttp/connector.py", line 874, in _resolve_host
    addrs = await self._resolver.resolve(host, port, family=self._family)
            ^^^^^^^^^^^^^^^^^^^^^^^^^^^^^^^^^^^^^^^^^^^^^^^^^^^^^^^^^^^^^
  File "/usr/lib/python3/dist-packages/aiohttp/resolver.py", line 33, in resolve
    infos = await self._loop.getaddrinfo(
            ^^^^^^^^^^^^^^^^^^^^^^^^^^^^^
  File "/usr/lib/python3.11/asyncio/base_events.py", line 867, in getaddrinfo
    return await self.run_in_executor(
           ^^^^^^^^^^^^^^^^^^^^^^^^^^^
  File "/usr/lib/python3.11/concurrent/futures/thread.py", line 58, in run
    result = self.fn(*self.args, **self.kwargs)
             ^^^^^^^^^^^^^^^^^^^^^^^^^^^^^^^^^^
  File "/usr/lib/python3.11/socket.py", line 962, in getaddrinfo
    for res in _socket.getaddrinfo(host, port, family, type, proto, flags):
               ^^^^^^^^^^^^^^^^^^^^^^^^^^^^^^^^^^^^^^^^^^^^^^^^^^^^^^^^^^^
socket.gaierror: [Errno -3] Temporary failure in name resolution

The above exception was the direct cause of the following exception:

Traceback (most recent call last):
  File "/usr/lib/python3/dist-packages/discord/client.py", line 656, in connect
    self.ws = await asyncio.wait_for(coro, timeout=60.0)
              ^^^^^^^^^^^^^^^^^^^^^^^^^^^^^^^^^^^^^^^^^^
  File "/usr/lib/python3.11/asyncio/tasks.py", line 479, in wait_for
    return fut.result()
           ^^^^^^^^^^^^
  File "/usr/lib/python3/dist-packages/discord/gateway.py", line 372, in from_client
    socket = await client.http.ws_connect(str(url))
             ^^^^^^^^^^^^^^^^^^^^^^^^^^^^^^^^^^^^^^
  File "/usr/lib/python3/dist-packages/discord/http.py", line 536, in ws_connect
    return await self.__session.ws_connect(url, **kwargs)
           ^^^^^^^^^^^^^^^^^^^^^^^^^^^^^^^^^^^^^^^^^^^^^^
  File "/usr/lib/python3/dist-packages/aiohttp/client.py", line 779, in _ws_connect
    resp = await self.request(
           ^^^^^^^^^^^^^^^^^^^
  File "/usr/lib/python3/dist-packages/aiohttp/client.py", line 536, in _request
    conn = await self._connector.connect(
           ^^^^^^^^^^^^^^^^^^^^^^^^^^^^^^
  File "/usr/lib/python3/dist-packages/aiohttp/connector.py", line 540, in connect
    proto = await self._create_connection(req, traces, timeout)
            ^^^^^^^^^^^^^^^^^^^^^^^^^^^^^^^^^^^^^^^^^^^^^^^^^^^
  File "/usr/lib/python3/dist-packages/aiohttp/connector.py", line 901, in _create_connection
    _, proto = await self._create_direct_connection(req, traces, timeout)
               ^^^^^^^^^^^^^^^^^^^^^^^^^^^^^^^^^^^^^^^^^^^^^^^^^^^^^^^^^^
  File "/usr/lib/python3/dist-packages/aiohttp/connector.py", line 1166, in _create_direct_connection
    raise ClientConnectorError(req.connection_key, exc) from exc
aiohttp.client_exceptions.ClientConnectorError: Cannot connect to host gateway-us-east1-c.discord.gg:443 ssl:default [Temporary failure in name resolution]
2024-06-06 00:29:38,619 - discord_bot - ERROR - Failed to purge or send message in people-in-studio: Cannot connect to host discord.com:443 ssl:default [Temporary failure in name resolution]
2024-06-06 00:31:38,626 - discord_bot - ERROR - Failed to purge or send message in people-in-studio: Cannot connect to host discord.com:443 ssl:default [Temporary failure in name resolution]
2024-06-06 00:33:38,630 - discord_bot - ERROR - Failed to purge or send message in people-in-studio: Cannot connect to host discord.com:443 ssl:default [Temporary failure in name resolution]
2024-06-06 00:35:38,634 - discord_bot - ERROR - Failed to purge or send message in people-in-studio: Cannot connect to host discord.com:443 ssl:default [Temporary failure in name resolution]
2024-06-06 00:37:38,639 - discord_bot - ERROR - Failed to purge or send message in people-in-studio: Cannot connect to host discord.com:443 ssl:default [Temporary failure in name resolution]
2024-06-06 00:39:38,642 - discord_bot - ERROR - Failed to purge or send message in people-in-studio: Cannot connect to host discord.com:443 ssl:default [Temporary failure in name resolution]
2024-06-06 00:41:38,645 - discord_bot - ERROR - Failed to purge or send message in people-in-studio: Cannot connect to host discord.com:443 ssl:default [Temporary failure in name resolution]
2024-06-06 00:43:38,648 - discord_bot - ERROR - Failed to purge or send message in people-in-studio: Cannot connect to host discord.com:443 ssl:default [Temporary failure in name resolution]
2024-06-06 00:45:38,652 - discord_bot - ERROR - Failed to purge or send message in people-in-studio: Cannot connect to host discord.com:443 ssl:default [Temporary failure in name resolution]
2024-06-06 00:45:46,297 - discord.client - ERROR - Attempting a reconnect in 621.50s
Traceback (most recent call last):
  File "/usr/lib/python3/dist-packages/aiohttp/connector.py", line 1152, in _create_direct_connection
    hosts = await asyncio.shield(host_resolved)
            ^^^^^^^^^^^^^^^^^^^^^^^^^^^^^^^^^^^
  File "/usr/lib/python3/dist-packages/aiohttp/connector.py", line 874, in _resolve_host
    addrs = await self._resolver.resolve(host, port, family=self._family)
            ^^^^^^^^^^^^^^^^^^^^^^^^^^^^^^^^^^^^^^^^^^^^^^^^^^^^^^^^^^^^^
  File "/usr/lib/python3/dist-packages/aiohttp/resolver.py", line 33, in resolve
    infos = await self._loop.getaddrinfo(
            ^^^^^^^^^^^^^^^^^^^^^^^^^^^^^
  File "/usr/lib/python3.11/asyncio/base_events.py", line 867, in getaddrinfo
    return await self.run_in_executor(
           ^^^^^^^^^^^^^^^^^^^^^^^^^^^
  File "/usr/lib/python3.11/concurrent/futures/thread.py", line 58, in run
    result = self.fn(*self.args, **self.kwargs)
             ^^^^^^^^^^^^^^^^^^^^^^^^^^^^^^^^^^
  File "/usr/lib/python3.11/socket.py", line 962, in getaddrinfo
    for res in _socket.getaddrinfo(host, port, family, type, proto, flags):
               ^^^^^^^^^^^^^^^^^^^^^^^^^^^^^^^^^^^^^^^^^^^^^^^^^^^^^^^^^^^
socket.gaierror: [Errno -3] Temporary failure in name resolution

The above exception was the direct cause of the following exception:

Traceback (most recent call last):
  File "/usr/lib/python3/dist-packages/discord/client.py", line 656, in connect
    self.ws = await asyncio.wait_for(coro, timeout=60.0)
              ^^^^^^^^^^^^^^^^^^^^^^^^^^^^^^^^^^^^^^^^^^
  File "/usr/lib/python3.11/asyncio/tasks.py", line 479, in wait_for
    return fut.result()
           ^^^^^^^^^^^^
  File "/usr/lib/python3/dist-packages/discord/gateway.py", line 372, in from_client
    socket = await client.http.ws_connect(str(url))
             ^^^^^^^^^^^^^^^^^^^^^^^^^^^^^^^^^^^^^^
  File "/usr/lib/python3/dist-packages/discord/http.py", line 536, in ws_connect
    return await self.__session.ws_connect(url, **kwargs)
           ^^^^^^^^^^^^^^^^^^^^^^^^^^^^^^^^^^^^^^^^^^^^^^
  File "/usr/lib/python3/dist-packages/aiohttp/client.py", line 779, in _ws_connect
    resp = await self.request(
           ^^^^^^^^^^^^^^^^^^^
  File "/usr/lib/python3/dist-packages/aiohttp/client.py", line 536, in _request
    conn = await self._connector.connect(
           ^^^^^^^^^^^^^^^^^^^^^^^^^^^^^^
  File "/usr/lib/python3/dist-packages/aiohttp/connector.py", line 540, in connect
    proto = await self._create_connection(req, traces, timeout)
            ^^^^^^^^^^^^^^^^^^^^^^^^^^^^^^^^^^^^^^^^^^^^^^^^^^^
  File "/usr/lib/python3/dist-packages/aiohttp/connector.py", line 901, in _create_connection
    _, proto = await self._create_direct_connection(req, traces, timeout)
               ^^^^^^^^^^^^^^^^^^^^^^^^^^^^^^^^^^^^^^^^^^^^^^^^^^^^^^^^^^
  File "/usr/lib/python3/dist-packages/aiohttp/connector.py", line 1166, in _create_direct_connection
    raise ClientConnectorError(req.connection_key, exc) from exc
aiohttp.client_exceptions.ClientConnectorError: Cannot connect to host gateway-us-east1-c.discord.gg:443 ssl:default [Temporary failure in name resolution]
2024-06-06 00:47:38,653 - discord_bot - ERROR - Failed to purge or send message in people-in-studio: Cannot connect to host discord.com:443 ssl:default [Temporary failure in name resolution]
2024-06-06 00:49:38,658 - discord_bot - ERROR - Failed to purge or send message in people-in-studio: Cannot connect to host discord.com:443 ssl:default [Temporary failure in name resolution]
2024-06-06 00:51:38,661 - discord_bot - ERROR - Failed to purge or send message in people-in-studio: Cannot connect to host discord.com:443 ssl:default [Temporary failure in name resolution]
2024-06-06 00:53:38,665 - discord_bot - ERROR - Failed to purge or send message in people-in-studio: Cannot connect to host discord.com:443 ssl:default [Temporary failure in name resolution]
2024-06-06 00:55:38,670 - discord_bot - ERROR - Failed to purge or send message in people-in-studio: Cannot connect to host discord.com:443 ssl:default [Temporary failure in name resolution]
2024-06-06 00:56:07,838 - discord.client - ERROR - Attempting a reconnect in 897.68s
Traceback (most recent call last):
  File "/usr/lib/python3/dist-packages/aiohttp/connector.py", line 1152, in _create_direct_connection
    hosts = await asyncio.shield(host_resolved)
            ^^^^^^^^^^^^^^^^^^^^^^^^^^^^^^^^^^^
  File "/usr/lib/python3/dist-packages/aiohttp/connector.py", line 874, in _resolve_host
    addrs = await self._resolver.resolve(host, port, family=self._family)
            ^^^^^^^^^^^^^^^^^^^^^^^^^^^^^^^^^^^^^^^^^^^^^^^^^^^^^^^^^^^^^
  File "/usr/lib/python3/dist-packages/aiohttp/resolver.py", line 33, in resolve
    infos = await self._loop.getaddrinfo(
            ^^^^^^^^^^^^^^^^^^^^^^^^^^^^^
  File "/usr/lib/python3.11/asyncio/base_events.py", line 867, in getaddrinfo
    return await self.run_in_executor(
           ^^^^^^^^^^^^^^^^^^^^^^^^^^^
  File "/usr/lib/python3.11/concurrent/futures/thread.py", line 58, in run
    result = self.fn(*self.args, **self.kwargs)
             ^^^^^^^^^^^^^^^^^^^^^^^^^^^^^^^^^^
  File "/usr/lib/python3.11/socket.py", line 962, in getaddrinfo
    for res in _socket.getaddrinfo(host, port, family, type, proto, flags):
               ^^^^^^^^^^^^^^^^^^^^^^^^^^^^^^^^^^^^^^^^^^^^^^^^^^^^^^^^^^^
socket.gaierror: [Errno -3] Temporary failure in name resolution

The above exception was the direct cause of the following exception:

Traceback (most recent call last):
  File "/usr/lib/python3/dist-packages/discord/client.py", line 656, in connect
    self.ws = await asyncio.wait_for(coro, timeout=60.0)
              ^^^^^^^^^^^^^^^^^^^^^^^^^^^^^^^^^^^^^^^^^^
  File "/usr/lib/python3.11/asyncio/tasks.py", line 479, in wait_for
    return fut.result()
           ^^^^^^^^^^^^
  File "/usr/lib/python3/dist-packages/discord/gateway.py", line 372, in from_client
    socket = await client.http.ws_connect(str(url))
             ^^^^^^^^^^^^^^^^^^^^^^^^^^^^^^^^^^^^^^
  File "/usr/lib/python3/dist-packages/discord/http.py", line 536, in ws_connect
    return await self.__session.ws_connect(url, **kwargs)
           ^^^^^^^^^^^^^^^^^^^^^^^^^^^^^^^^^^^^^^^^^^^^^^
  File "/usr/lib/python3/dist-packages/aiohttp/client.py", line 779, in _ws_connect
    resp = await self.request(
           ^^^^^^^^^^^^^^^^^^^
  File "/usr/lib/python3/dist-packages/aiohttp/client.py", line 536, in _request
    conn = await self._connector.connect(
           ^^^^^^^^^^^^^^^^^^^^^^^^^^^^^^
  File "/usr/lib/python3/dist-packages/aiohttp/connector.py", line 540, in connect
    proto = await self._create_connection(req, traces, timeout)
            ^^^^^^^^^^^^^^^^^^^^^^^^^^^^^^^^^^^^^^^^^^^^^^^^^^^
  File "/usr/lib/python3/dist-packages/aiohttp/connector.py", line 901, in _create_connection
    _, proto = await self._create_direct_connection(req, traces, timeout)
               ^^^^^^^^^^^^^^^^^^^^^^^^^^^^^^^^^^^^^^^^^^^^^^^^^^^^^^^^^^
  File "/usr/lib/python3/dist-packages/aiohttp/connector.py", line 1166, in _create_direct_connection
    raise ClientConnectorError(req.connection_key, exc) from exc
aiohttp.client_exceptions.ClientConnectorError: Cannot connect to host gateway-us-east1-c.discord.gg:443 ssl:default [Temporary failure in name resolution]
2024-06-06 00:57:38,676 - discord_bot - ERROR - Failed to purge or send message in people-in-studio: Cannot connect to host discord.com:443 ssl:default [Temporary failure in name resolution]
2024-06-06 00:59:38,680 - discord_bot - ERROR - Failed to purge or send message in people-in-studio: Cannot connect to host discord.com:443 ssl:default [Temporary failure in name resolution]
2024-06-06 01:01:38,682 - discord_bot - ERROR - Failed to purge or send message in people-in-studio: Cannot connect to host discord.com:443 ssl:default [Temporary failure in name resolution]
2024-06-06 01:03:38,686 - discord_bot - ERROR - Failed to purge or send message in people-in-studio: Cannot connect to host discord.com:443 ssl:default [Temporary failure in name resolution]
2024-06-06 01:05:38,688 - discord_bot - ERROR - Failed to purge or send message in people-in-studio: Cannot connect to host discord.com:443 ssl:default [Temporary failure in name resolution]
2024-06-06 01:07:38,690 - discord_bot - ERROR - Failed to purge or send message in people-in-studio: Cannot connect to host discord.com:443 ssl:default [Temporary failure in name resolution]
2024-06-06 01:09:38,695 - discord_bot - ERROR - Failed to purge or send message in people-in-studio: Cannot connect to host discord.com:443 ssl:default [Temporary failure in name resolution]
2024-06-06 01:11:05,584 - discord.client - ERROR - Attempting a reconnect in 227.18s
Traceback (most recent call last):
  File "/usr/lib/python3/dist-packages/aiohttp/connector.py", line 1152, in _create_direct_connection
    hosts = await asyncio.shield(host_resolved)
            ^^^^^^^^^^^^^^^^^^^^^^^^^^^^^^^^^^^
  File "/usr/lib/python3/dist-packages/aiohttp/connector.py", line 874, in _resolve_host
    addrs = await self._resolver.resolve(host, port, family=self._family)
            ^^^^^^^^^^^^^^^^^^^^^^^^^^^^^^^^^^^^^^^^^^^^^^^^^^^^^^^^^^^^^
  File "/usr/lib/python3/dist-packages/aiohttp/resolver.py", line 33, in resolve
    infos = await self._loop.getaddrinfo(
            ^^^^^^^^^^^^^^^^^^^^^^^^^^^^^
  File "/usr/lib/python3.11/asyncio/base_events.py", line 867, in getaddrinfo
    return await self.run_in_executor(
           ^^^^^^^^^^^^^^^^^^^^^^^^^^^
  File "/usr/lib/python3.11/concurrent/futures/thread.py", line 58, in run
    result = self.fn(*self.args, **self.kwargs)
             ^^^^^^^^^^^^^^^^^^^^^^^^^^^^^^^^^^
  File "/usr/lib/python3.11/socket.py", line 962, in getaddrinfo
    for res in _socket.getaddrinfo(host, port, family, type, proto, flags):
               ^^^^^^^^^^^^^^^^^^^^^^^^^^^^^^^^^^^^^^^^^^^^^^^^^^^^^^^^^^^
socket.gaierror: [Errno -3] Temporary failure in name resolution

The above exception was the direct cause of the following exception:

Traceback (most recent call last):
  File "/usr/lib/python3/dist-packages/discord/client.py", line 656, in connect
    self.ws = await asyncio.wait_for(coro, timeout=60.0)
              ^^^^^^^^^^^^^^^^^^^^^^^^^^^^^^^^^^^^^^^^^^
  File "/usr/lib/python3.11/asyncio/tasks.py", line 479, in wait_for
    return fut.result()
           ^^^^^^^^^^^^
  File "/usr/lib/python3/dist-packages/discord/gateway.py", line 372, in from_client
    socket = await client.http.ws_connect(str(url))
             ^^^^^^^^^^^^^^^^^^^^^^^^^^^^^^^^^^^^^^
  File "/usr/lib/python3/dist-packages/discord/http.py", line 536, in ws_connect
    return await self.__session.ws_connect(url, **kwargs)
           ^^^^^^^^^^^^^^^^^^^^^^^^^^^^^^^^^^^^^^^^^^^^^^
  File "/usr/lib/python3/dist-packages/aiohttp/client.py", line 779, in _ws_connect
    resp = await self.request(
           ^^^^^^^^^^^^^^^^^^^
  File "/usr/lib/python3/dist-packages/aiohttp/client.py", line 536, in _request
    conn = await self._connector.connect(
           ^^^^^^^^^^^^^^^^^^^^^^^^^^^^^^
  File "/usr/lib/python3/dist-packages/aiohttp/connector.py", line 540, in connect
    proto = await self._create_connection(req, traces, timeout)
            ^^^^^^^^^^^^^^^^^^^^^^^^^^^^^^^^^^^^^^^^^^^^^^^^^^^
  File "/usr/lib/python3/dist-packages/aiohttp/connector.py", line 901, in _create_connection
    _, proto = await self._create_direct_connection(req, traces, timeout)
               ^^^^^^^^^^^^^^^^^^^^^^^^^^^^^^^^^^^^^^^^^^^^^^^^^^^^^^^^^^
  File "/usr/lib/python3/dist-packages/aiohttp/connector.py", line 1166, in _create_direct_connection
    raise ClientConnectorError(req.connection_key, exc) from exc
aiohttp.client_exceptions.ClientConnectorError: Cannot connect to host gateway-us-east1-c.discord.gg:443 ssl:default [Temporary failure in name resolution]
2024-06-06 01:11:38,696 - discord_bot - ERROR - Failed to purge or send message in people-in-studio: Cannot connect to host discord.com:443 ssl:default [Temporary failure in name resolution]
2024-06-06 01:13:38,692 - discord_bot - ERROR - Failed to purge or send message in people-in-studio: Cannot connect to host discord.com:443 ssl:default [Temporary failure in name resolution]
2024-06-06 01:14:52,780 - discord.client - ERROR - Attempting a reconnect in 408.37s
Traceback (most recent call last):
  File "/usr/lib/python3/dist-packages/aiohttp/connector.py", line 1152, in _create_direct_connection
    hosts = await asyncio.shield(host_resolved)
            ^^^^^^^^^^^^^^^^^^^^^^^^^^^^^^^^^^^
  File "/usr/lib/python3/dist-packages/aiohttp/connector.py", line 874, in _resolve_host
    addrs = await self._resolver.resolve(host, port, family=self._family)
            ^^^^^^^^^^^^^^^^^^^^^^^^^^^^^^^^^^^^^^^^^^^^^^^^^^^^^^^^^^^^^
  File "/usr/lib/python3/dist-packages/aiohttp/resolver.py", line 33, in resolve
    infos = await self._loop.getaddrinfo(
            ^^^^^^^^^^^^^^^^^^^^^^^^^^^^^
  File "/usr/lib/python3.11/asyncio/base_events.py", line 867, in getaddrinfo
    return await self.run_in_executor(
           ^^^^^^^^^^^^^^^^^^^^^^^^^^^
  File "/usr/lib/python3.11/concurrent/futures/thread.py", line 58, in run
    result = self.fn(*self.args, **self.kwargs)
             ^^^^^^^^^^^^^^^^^^^^^^^^^^^^^^^^^^
  File "/usr/lib/python3.11/socket.py", line 962, in getaddrinfo
    for res in _socket.getaddrinfo(host, port, family, type, proto, flags):
               ^^^^^^^^^^^^^^^^^^^^^^^^^^^^^^^^^^^^^^^^^^^^^^^^^^^^^^^^^^^
socket.gaierror: [Errno -3] Temporary failure in name resolution

The above exception was the direct cause of the following exception:

Traceback (most recent call last):
  File "/usr/lib/python3/dist-packages/discord/client.py", line 656, in connect
    self.ws = await asyncio.wait_for(coro, timeout=60.0)
              ^^^^^^^^^^^^^^^^^^^^^^^^^^^^^^^^^^^^^^^^^^
  File "/usr/lib/python3.11/asyncio/tasks.py", line 479, in wait_for
    return fut.result()
           ^^^^^^^^^^^^
  File "/usr/lib/python3/dist-packages/discord/gateway.py", line 372, in from_client
    socket = await client.http.ws_connect(str(url))
             ^^^^^^^^^^^^^^^^^^^^^^^^^^^^^^^^^^^^^^
  File "/usr/lib/python3/dist-packages/discord/http.py", line 536, in ws_connect
    return await self.__session.ws_connect(url, **kwargs)
           ^^^^^^^^^^^^^^^^^^^^^^^^^^^^^^^^^^^^^^^^^^^^^^
  File "/usr/lib/python3/dist-packages/aiohttp/client.py", line 779, in _ws_connect
    resp = await self.request(
           ^^^^^^^^^^^^^^^^^^^
  File "/usr/lib/python3/dist-packages/aiohttp/client.py", line 536, in _request
    conn = await self._connector.connect(
           ^^^^^^^^^^^^^^^^^^^^^^^^^^^^^^
  File "/usr/lib/python3/dist-packages/aiohttp/connector.py", line 540, in connect
    proto = await self._create_connection(req, traces, timeout)
            ^^^^^^^^^^^^^^^^^^^^^^^^^^^^^^^^^^^^^^^^^^^^^^^^^^^
  File "/usr/lib/python3/dist-packages/aiohttp/connector.py", line 901, in _create_connection
    _, proto = await self._create_direct_connection(req, traces, timeout)
               ^^^^^^^^^^^^^^^^^^^^^^^^^^^^^^^^^^^^^^^^^^^^^^^^^^^^^^^^^^
  File "/usr/lib/python3/dist-packages/aiohttp/connector.py", line 1166, in _create_direct_connection
    raise ClientConnectorError(req.connection_key, exc) from exc
aiohttp.client_exceptions.ClientConnectorError: Cannot connect to host gateway-us-east1-c.discord.gg:443 ssl:default [Temporary failure in name resolution]
2024-06-06 01:15:38,694 - discord_bot - ERROR - Failed to purge or send message in people-in-studio: Cannot connect to host discord.com:443 ssl:default [Temporary failure in name resolution]
2024-06-06 01:17:38,697 - discord_bot - ERROR - Failed to purge or send message in people-in-studio: Cannot connect to host discord.com:443 ssl:default [Temporary failure in name resolution]
2024-06-06 01:19:38,699 - discord_bot - ERROR - Failed to purge or send message in people-in-studio: Cannot connect to host discord.com:443 ssl:default [Temporary failure in name resolution]
2024-06-06 01:21:38,701 - discord_bot - ERROR - Failed to purge or send message in people-in-studio: Cannot connect to host discord.com:443 ssl:default [Temporary failure in name resolution]
2024-06-06 01:21:41,160 - discord.client - ERROR - Attempting a reconnect in 104.64s
Traceback (most recent call last):
  File "/usr/lib/python3/dist-packages/aiohttp/connector.py", line 1152, in _create_direct_connection
    hosts = await asyncio.shield(host_resolved)
            ^^^^^^^^^^^^^^^^^^^^^^^^^^^^^^^^^^^
  File "/usr/lib/python3/dist-packages/aiohttp/connector.py", line 874, in _resolve_host
    addrs = await self._resolver.resolve(host, port, family=self._family)
            ^^^^^^^^^^^^^^^^^^^^^^^^^^^^^^^^^^^^^^^^^^^^^^^^^^^^^^^^^^^^^
  File "/usr/lib/python3/dist-packages/aiohttp/resolver.py", line 33, in resolve
    infos = await self._loop.getaddrinfo(
            ^^^^^^^^^^^^^^^^^^^^^^^^^^^^^
  File "/usr/lib/python3.11/asyncio/base_events.py", line 867, in getaddrinfo
    return await self.run_in_executor(
           ^^^^^^^^^^^^^^^^^^^^^^^^^^^
  File "/usr/lib/python3.11/concurrent/futures/thread.py", line 58, in run
    result = self.fn(*self.args, **self.kwargs)
             ^^^^^^^^^^^^^^^^^^^^^^^^^^^^^^^^^^
  File "/usr/lib/python3.11/socket.py", line 962, in getaddrinfo
    for res in _socket.getaddrinfo(host, port, family, type, proto, flags):
               ^^^^^^^^^^^^^^^^^^^^^^^^^^^^^^^^^^^^^^^^^^^^^^^^^^^^^^^^^^^
socket.gaierror: [Errno -3] Temporary failure in name resolution

The above exception was the direct cause of the following exception:

Traceback (most recent call last):
  File "/usr/lib/python3/dist-packages/discord/client.py", line 656, in connect
    self.ws = await asyncio.wait_for(coro, timeout=60.0)
              ^^^^^^^^^^^^^^^^^^^^^^^^^^^^^^^^^^^^^^^^^^
  File "/usr/lib/python3.11/asyncio/tasks.py", line 479, in wait_for
    return fut.result()
           ^^^^^^^^^^^^
  File "/usr/lib/python3/dist-packages/discord/gateway.py", line 372, in from_client
    socket = await client.http.ws_connect(str(url))
             ^^^^^^^^^^^^^^^^^^^^^^^^^^^^^^^^^^^^^^
  File "/usr/lib/python3/dist-packages/discord/http.py", line 536, in ws_connect
    return await self.__session.ws_connect(url, **kwargs)
           ^^^^^^^^^^^^^^^^^^^^^^^^^^^^^^^^^^^^^^^^^^^^^^
  File "/usr/lib/python3/dist-packages/aiohttp/client.py", line 779, in _ws_connect
    resp = await self.request(
           ^^^^^^^^^^^^^^^^^^^
  File "/usr/lib/python3/dist-packages/aiohttp/client.py", line 536, in _request
    conn = await self._connector.connect(
           ^^^^^^^^^^^^^^^^^^^^^^^^^^^^^^
  File "/usr/lib/python3/dist-packages/aiohttp/connector.py", line 540, in connect
    proto = await self._create_connection(req, traces, timeout)
            ^^^^^^^^^^^^^^^^^^^^^^^^^^^^^^^^^^^^^^^^^^^^^^^^^^^
  File "/usr/lib/python3/dist-packages/aiohttp/connector.py", line 901, in _create_connection
    _, proto = await self._create_direct_connection(req, traces, timeout)
               ^^^^^^^^^^^^^^^^^^^^^^^^^^^^^^^^^^^^^^^^^^^^^^^^^^^^^^^^^^
  File "/usr/lib/python3/dist-packages/aiohttp/connector.py", line 1166, in _create_direct_connection
    raise ClientConnectorError(req.connection_key, exc) from exc
aiohttp.client_exceptions.ClientConnectorError: Cannot connect to host gateway-us-east1-c.discord.gg:443 ssl:default [Temporary failure in name resolution]
2024-06-06 01:23:25,895 - discord.client - ERROR - Attempting a reconnect in 964.87s
Traceback (most recent call last):
  File "/usr/lib/python3/dist-packages/aiohttp/connector.py", line 1152, in _create_direct_connection
    hosts = await asyncio.shield(host_resolved)
            ^^^^^^^^^^^^^^^^^^^^^^^^^^^^^^^^^^^
  File "/usr/lib/python3/dist-packages/aiohttp/connector.py", line 874, in _resolve_host
    addrs = await self._resolver.resolve(host, port, family=self._family)
            ^^^^^^^^^^^^^^^^^^^^^^^^^^^^^^^^^^^^^^^^^^^^^^^^^^^^^^^^^^^^^
  File "/usr/lib/python3/dist-packages/aiohttp/resolver.py", line 33, in resolve
    infos = await self._loop.getaddrinfo(
            ^^^^^^^^^^^^^^^^^^^^^^^^^^^^^
  File "/usr/lib/python3.11/asyncio/base_events.py", line 867, in getaddrinfo
    return await self.run_in_executor(
           ^^^^^^^^^^^^^^^^^^^^^^^^^^^
  File "/usr/lib/python3.11/concurrent/futures/thread.py", line 58, in run
    result = self.fn(*self.args, **self.kwargs)
             ^^^^^^^^^^^^^^^^^^^^^^^^^^^^^^^^^^
  File "/usr/lib/python3.11/socket.py", line 962, in getaddrinfo
    for res in _socket.getaddrinfo(host, port, family, type, proto, flags):
               ^^^^^^^^^^^^^^^^^^^^^^^^^^^^^^^^^^^^^^^^^^^^^^^^^^^^^^^^^^^
socket.gaierror: [Errno -3] Temporary failure in name resolution

The above exception was the direct cause of the following exception:

Traceback (most recent call last):
  File "/usr/lib/python3/dist-packages/discord/client.py", line 656, in connect
    self.ws = await asyncio.wait_for(coro, timeout=60.0)
              ^^^^^^^^^^^^^^^^^^^^^^^^^^^^^^^^^^^^^^^^^^
  File "/usr/lib/python3.11/asyncio/tasks.py", line 479, in wait_for
    return fut.result()
           ^^^^^^^^^^^^
  File "/usr/lib/python3/dist-packages/discord/gateway.py", line 372, in from_client
    socket = await client.http.ws_connect(str(url))
             ^^^^^^^^^^^^^^^^^^^^^^^^^^^^^^^^^^^^^^
  File "/usr/lib/python3/dist-packages/discord/http.py", line 536, in ws_connect
    return await self.__session.ws_connect(url, **kwargs)
           ^^^^^^^^^^^^^^^^^^^^^^^^^^^^^^^^^^^^^^^^^^^^^^
  File "/usr/lib/python3/dist-packages/aiohttp/client.py", line 779, in _ws_connect
    resp = await self.request(
           ^^^^^^^^^^^^^^^^^^^
  File "/usr/lib/python3/dist-packages/aiohttp/client.py", line 536, in _request
    conn = await self._connector.connect(
           ^^^^^^^^^^^^^^^^^^^^^^^^^^^^^^
  File "/usr/lib/python3/dist-packages/aiohttp/connector.py", line 540, in connect
    proto = await self._create_connection(req, traces, timeout)
            ^^^^^^^^^^^^^^^^^^^^^^^^^^^^^^^^^^^^^^^^^^^^^^^^^^^
  File "/usr/lib/python3/dist-packages/aiohttp/connector.py", line 901, in _create_connection
    _, proto = await self._create_direct_connection(req, traces, timeout)
               ^^^^^^^^^^^^^^^^^^^^^^^^^^^^^^^^^^^^^^^^^^^^^^^^^^^^^^^^^^
  File "/usr/lib/python3/dist-packages/aiohttp/connector.py", line 1166, in _create_direct_connection
    raise ClientConnectorError(req.connection_key, exc) from exc
aiohttp.client_exceptions.ClientConnectorError: Cannot connect to host gateway-us-east1-c.discord.gg:443 ssl:default [Temporary failure in name resolution]
2024-06-06 01:23:38,703 - discord_bot - ERROR - Failed to purge or send message in people-in-studio: Cannot connect to host discord.com:443 ssl:default [Temporary failure in name resolution]
2024-06-06 01:25:38,704 - discord_bot - ERROR - Failed to purge or send message in people-in-studio: Cannot connect to host discord.com:443 ssl:default [Temporary failure in name resolution]
2024-06-06 01:27:38,707 - discord_bot - ERROR - Failed to purge or send message in people-in-studio: Cannot connect to host discord.com:443 ssl:default [Temporary failure in name resolution]
2024-06-06 01:29:38,716 - discord_bot - ERROR - Failed to purge or send message in people-in-studio: Cannot connect to host discord.com:443 ssl:default [Temporary failure in name resolution]
2024-06-06 01:31:38,720 - discord_bot - ERROR - Failed to purge or send message in people-in-studio: Cannot connect to host discord.com:443 ssl:default [Temporary failure in name resolution]
2024-06-06 01:33:38,725 - discord_bot - ERROR - Failed to purge or send message in people-in-studio: Cannot connect to host discord.com:443 ssl:default [Temporary failure in name resolution]
2024-06-06 01:35:38,729 - discord_bot - ERROR - Failed to purge or send message in people-in-studio: Cannot connect to host discord.com:443 ssl:default [Temporary failure in name resolution]
2024-06-06 01:37:38,734 - discord_bot - ERROR - Failed to purge or send message in people-in-studio: Cannot connect to host discord.com:443 ssl:default [Temporary failure in name resolution]
2024-06-06 01:39:30,864 - discord.client - ERROR - Attempting a reconnect in 566.63s
Traceback (most recent call last):
  File "/usr/lib/python3/dist-packages/aiohttp/connector.py", line 1152, in _create_direct_connection
    hosts = await asyncio.shield(host_resolved)
            ^^^^^^^^^^^^^^^^^^^^^^^^^^^^^^^^^^^
  File "/usr/lib/python3/dist-packages/aiohttp/connector.py", line 874, in _resolve_host
    addrs = await self._resolver.resolve(host, port, family=self._family)
            ^^^^^^^^^^^^^^^^^^^^^^^^^^^^^^^^^^^^^^^^^^^^^^^^^^^^^^^^^^^^^
  File "/usr/lib/python3/dist-packages/aiohttp/resolver.py", line 33, in resolve
    infos = await self._loop.getaddrinfo(
            ^^^^^^^^^^^^^^^^^^^^^^^^^^^^^
  File "/usr/lib/python3.11/asyncio/base_events.py", line 867, in getaddrinfo
    return await self.run_in_executor(
           ^^^^^^^^^^^^^^^^^^^^^^^^^^^
  File "/usr/lib/python3.11/concurrent/futures/thread.py", line 58, in run
    result = self.fn(*self.args, **self.kwargs)
             ^^^^^^^^^^^^^^^^^^^^^^^^^^^^^^^^^^
  File "/usr/lib/python3.11/socket.py", line 962, in getaddrinfo
    for res in _socket.getaddrinfo(host, port, family, type, proto, flags):
               ^^^^^^^^^^^^^^^^^^^^^^^^^^^^^^^^^^^^^^^^^^^^^^^^^^^^^^^^^^^
socket.gaierror: [Errno -3] Temporary failure in name resolution

The above exception was the direct cause of the following exception:

Traceback (most recent call last):
  File "/usr/lib/python3/dist-packages/discord/client.py", line 656, in connect
    self.ws = await asyncio.wait_for(coro, timeout=60.0)
              ^^^^^^^^^^^^^^^^^^^^^^^^^^^^^^^^^^^^^^^^^^
  File "/usr/lib/python3.11/asyncio/tasks.py", line 479, in wait_for
    return fut.result()
           ^^^^^^^^^^^^
  File "/usr/lib/python3/dist-packages/discord/gateway.py", line 372, in from_client
    socket = await client.http.ws_connect(str(url))
             ^^^^^^^^^^^^^^^^^^^^^^^^^^^^^^^^^^^^^^
  File "/usr/lib/python3/dist-packages/discord/http.py", line 536, in ws_connect
    return await self.__session.ws_connect(url, **kwargs)
           ^^^^^^^^^^^^^^^^^^^^^^^^^^^^^^^^^^^^^^^^^^^^^^
  File "/usr/lib/python3/dist-packages/aiohttp/client.py", line 779, in _ws_connect
    resp = await self.request(
           ^^^^^^^^^^^^^^^^^^^
  File "/usr/lib/python3/dist-packages/aiohttp/client.py", line 536, in _request
    conn = await self._connector.connect(
           ^^^^^^^^^^^^^^^^^^^^^^^^^^^^^^
  File "/usr/lib/python3/dist-packages/aiohttp/connector.py", line 540, in connect
    proto = await self._create_connection(req, traces, timeout)
            ^^^^^^^^^^^^^^^^^^^^^^^^^^^^^^^^^^^^^^^^^^^^^^^^^^^
  File "/usr/lib/python3/dist-packages/aiohttp/connector.py", line 901, in _create_connection
    _, proto = await self._create_direct_connection(req, traces, timeout)
               ^^^^^^^^^^^^^^^^^^^^^^^^^^^^^^^^^^^^^^^^^^^^^^^^^^^^^^^^^^
  File "/usr/lib/python3/dist-packages/aiohttp/connector.py", line 1166, in _create_direct_connection
    raise ClientConnectorError(req.connection_key, exc) from exc
aiohttp.client_exceptions.ClientConnectorError: Cannot connect to host gateway-us-east1-c.discord.gg:443 ssl:default [Temporary failure in name resolution]
2024-06-06 01:39:38,737 - discord_bot - ERROR - Failed to purge or send message in people-in-studio: Cannot connect to host discord.com:443 ssl:default [Temporary failure in name resolution]
2024-06-06 01:41:38,743 - discord_bot - ERROR - Failed to purge or send message in people-in-studio: Cannot connect to host discord.com:443 ssl:default [Temporary failure in name resolution]
2024-06-06 01:43:38,746 - discord_bot - ERROR - Failed to purge or send message in people-in-studio: Cannot connect to host discord.com:443 ssl:default [Temporary failure in name resolution]
2024-06-06 01:45:38,749 - discord_bot - ERROR - Failed to purge or send message in people-in-studio: Cannot connect to host discord.com:443 ssl:default [Temporary failure in name resolution]
2024-06-06 01:47:38,753 - discord_bot - ERROR - Failed to purge or send message in people-in-studio: Cannot connect to host discord.com:443 ssl:default [Temporary failure in name resolution]
2024-06-06 01:48:57,555 - discord.client - ERROR - Attempting a reconnect in 267.77s
Traceback (most recent call last):
  File "/usr/lib/python3/dist-packages/aiohttp/connector.py", line 1152, in _create_direct_connection
    hosts = await asyncio.shield(host_resolved)
            ^^^^^^^^^^^^^^^^^^^^^^^^^^^^^^^^^^^
  File "/usr/lib/python3/dist-packages/aiohttp/connector.py", line 874, in _resolve_host
    addrs = await self._resolver.resolve(host, port, family=self._family)
            ^^^^^^^^^^^^^^^^^^^^^^^^^^^^^^^^^^^^^^^^^^^^^^^^^^^^^^^^^^^^^
  File "/usr/lib/python3/dist-packages/aiohttp/resolver.py", line 33, in resolve
    infos = await self._loop.getaddrinfo(
            ^^^^^^^^^^^^^^^^^^^^^^^^^^^^^
  File "/usr/lib/python3.11/asyncio/base_events.py", line 867, in getaddrinfo
    return await self.run_in_executor(
           ^^^^^^^^^^^^^^^^^^^^^^^^^^^
  File "/usr/lib/python3.11/concurrent/futures/thread.py", line 58, in run
    result = self.fn(*self.args, **self.kwargs)
             ^^^^^^^^^^^^^^^^^^^^^^^^^^^^^^^^^^
  File "/usr/lib/python3.11/socket.py", line 962, in getaddrinfo
    for res in _socket.getaddrinfo(host, port, family, type, proto, flags):
               ^^^^^^^^^^^^^^^^^^^^^^^^^^^^^^^^^^^^^^^^^^^^^^^^^^^^^^^^^^^
socket.gaierror: [Errno -3] Temporary failure in name resolution

The above exception was the direct cause of the following exception:

Traceback (most recent call last):
  File "/usr/lib/python3/dist-packages/discord/client.py", line 656, in connect
    self.ws = await asyncio.wait_for(coro, timeout=60.0)
              ^^^^^^^^^^^^^^^^^^^^^^^^^^^^^^^^^^^^^^^^^^
  File "/usr/lib/python3.11/asyncio/tasks.py", line 479, in wait_for
    return fut.result()
           ^^^^^^^^^^^^
  File "/usr/lib/python3/dist-packages/discord/gateway.py", line 372, in from_client
    socket = await client.http.ws_connect(str(url))
             ^^^^^^^^^^^^^^^^^^^^^^^^^^^^^^^^^^^^^^
  File "/usr/lib/python3/dist-packages/discord/http.py", line 536, in ws_connect
    return await self.__session.ws_connect(url, **kwargs)
           ^^^^^^^^^^^^^^^^^^^^^^^^^^^^^^^^^^^^^^^^^^^^^^
  File "/usr/lib/python3/dist-packages/aiohttp/client.py", line 779, in _ws_connect
    resp = await self.request(
           ^^^^^^^^^^^^^^^^^^^
  File "/usr/lib/python3/dist-packages/aiohttp/client.py", line 536, in _request
    conn = await self._connector.connect(
           ^^^^^^^^^^^^^^^^^^^^^^^^^^^^^^
  File "/usr/lib/python3/dist-packages/aiohttp/connector.py", line 540, in connect
    proto = await self._create_connection(req, traces, timeout)
            ^^^^^^^^^^^^^^^^^^^^^^^^^^^^^^^^^^^^^^^^^^^^^^^^^^^
  File "/usr/lib/python3/dist-packages/aiohttp/connector.py", line 901, in _create_connection
    _, proto = await self._create_direct_connection(req, traces, timeout)
               ^^^^^^^^^^^^^^^^^^^^^^^^^^^^^^^^^^^^^^^^^^^^^^^^^^^^^^^^^^
  File "/usr/lib/python3/dist-packages/aiohttp/connector.py", line 1166, in _create_direct_connection
    raise ClientConnectorError(req.connection_key, exc) from exc
aiohttp.client_exceptions.ClientConnectorError: Cannot connect to host gateway-us-east1-c.discord.gg:443 ssl:default [Temporary failure in name resolution]
2024-06-06 01:49:38,756 - discord_bot - ERROR - Failed to purge or send message in people-in-studio: Cannot connect to host discord.com:443 ssl:default [Temporary failure in name resolution]
2024-06-06 01:51:38,761 - discord_bot - ERROR - Failed to purge or send message in people-in-studio: Cannot connect to host discord.com:443 ssl:default [Temporary failure in name resolution]
2024-06-06 01:53:25,409 - discord.client - ERROR - Attempting a reconnect in 535.47s
Traceback (most recent call last):
  File "/usr/lib/python3/dist-packages/aiohttp/connector.py", line 1152, in _create_direct_connection
    hosts = await asyncio.shield(host_resolved)
            ^^^^^^^^^^^^^^^^^^^^^^^^^^^^^^^^^^^
  File "/usr/lib/python3/dist-packages/aiohttp/connector.py", line 874, in _resolve_host
    addrs = await self._resolver.resolve(host, port, family=self._family)
            ^^^^^^^^^^^^^^^^^^^^^^^^^^^^^^^^^^^^^^^^^^^^^^^^^^^^^^^^^^^^^
  File "/usr/lib/python3/dist-packages/aiohttp/resolver.py", line 33, in resolve
    infos = await self._loop.getaddrinfo(
            ^^^^^^^^^^^^^^^^^^^^^^^^^^^^^
  File "/usr/lib/python3.11/asyncio/base_events.py", line 867, in getaddrinfo
    return await self.run_in_executor(
           ^^^^^^^^^^^^^^^^^^^^^^^^^^^
  File "/usr/lib/python3.11/concurrent/futures/thread.py", line 58, in run
    result = self.fn(*self.args, **self.kwargs)
             ^^^^^^^^^^^^^^^^^^^^^^^^^^^^^^^^^^
  File "/usr/lib/python3.11/socket.py", line 962, in getaddrinfo
    for res in _socket.getaddrinfo(host, port, family, type, proto, flags):
               ^^^^^^^^^^^^^^^^^^^^^^^^^^^^^^^^^^^^^^^^^^^^^^^^^^^^^^^^^^^
socket.gaierror: [Errno -3] Temporary failure in name resolution

The above exception was the direct cause of the following exception:

Traceback (most recent call last):
  File "/usr/lib/python3/dist-packages/discord/client.py", line 656, in connect
    self.ws = await asyncio.wait_for(coro, timeout=60.0)
              ^^^^^^^^^^^^^^^^^^^^^^^^^^^^^^^^^^^^^^^^^^
  File "/usr/lib/python3.11/asyncio/tasks.py", line 479, in wait_for
    return fut.result()
           ^^^^^^^^^^^^
  File "/usr/lib/python3/dist-packages/discord/gateway.py", line 372, in from_client
    socket = await client.http.ws_connect(str(url))
             ^^^^^^^^^^^^^^^^^^^^^^^^^^^^^^^^^^^^^^
  File "/usr/lib/python3/dist-packages/discord/http.py", line 536, in ws_connect
    return await self.__session.ws_connect(url, **kwargs)
           ^^^^^^^^^^^^^^^^^^^^^^^^^^^^^^^^^^^^^^^^^^^^^^
  File "/usr/lib/python3/dist-packages/aiohttp/client.py", line 779, in _ws_connect
    resp = await self.request(
           ^^^^^^^^^^^^^^^^^^^
  File "/usr/lib/python3/dist-packages/aiohttp/client.py", line 536, in _request
    conn = await self._connector.connect(
           ^^^^^^^^^^^^^^^^^^^^^^^^^^^^^^
  File "/usr/lib/python3/dist-packages/aiohttp/connector.py", line 540, in connect
    proto = await self._create_connection(req, traces, timeout)
            ^^^^^^^^^^^^^^^^^^^^^^^^^^^^^^^^^^^^^^^^^^^^^^^^^^^
  File "/usr/lib/python3/dist-packages/aiohttp/connector.py", line 901, in _create_connection
    _, proto = await self._create_direct_connection(req, traces, timeout)
               ^^^^^^^^^^^^^^^^^^^^^^^^^^^^^^^^^^^^^^^^^^^^^^^^^^^^^^^^^^
  File "/usr/lib/python3/dist-packages/aiohttp/connector.py", line 1166, in _create_direct_connection
    raise ClientConnectorError(req.connection_key, exc) from exc
aiohttp.client_exceptions.ClientConnectorError: Cannot connect to host gateway-us-east1-c.discord.gg:443 ssl:default [Temporary failure in name resolution]
2024-06-06 01:53:38,763 - discord_bot - ERROR - Failed to purge or send message in people-in-studio: Cannot connect to host discord.com:443 ssl:default [Temporary failure in name resolution]
2024-06-06 01:55:38,770 - discord_bot - ERROR - Failed to purge or send message in people-in-studio: Cannot connect to host discord.com:443 ssl:default [Temporary failure in name resolution]
2024-06-06 01:57:38,776 - discord_bot - ERROR - Failed to purge or send message in people-in-studio: Cannot connect to host discord.com:443 ssl:default [Temporary failure in name resolution]
2024-06-06 01:59:38,780 - discord_bot - ERROR - Failed to purge or send message in people-in-studio: Cannot connect to host discord.com:443 ssl:default [Temporary failure in name resolution]
2024-06-06 02:01:38,776 - discord_bot - ERROR - Failed to purge or send message in people-in-studio: Cannot connect to host discord.com:443 ssl:default [Temporary failure in name resolution]
2024-06-06 02:02:20,936 - discord.client - ERROR - Attempting a reconnect in 196.72s
Traceback (most recent call last):
  File "/usr/lib/python3/dist-packages/aiohttp/connector.py", line 1152, in _create_direct_connection
    hosts = await asyncio.shield(host_resolved)
            ^^^^^^^^^^^^^^^^^^^^^^^^^^^^^^^^^^^
  File "/usr/lib/python3/dist-packages/aiohttp/connector.py", line 874, in _resolve_host
    addrs = await self._resolver.resolve(host, port, family=self._family)
            ^^^^^^^^^^^^^^^^^^^^^^^^^^^^^^^^^^^^^^^^^^^^^^^^^^^^^^^^^^^^^
  File "/usr/lib/python3/dist-packages/aiohttp/resolver.py", line 33, in resolve
    infos = await self._loop.getaddrinfo(
            ^^^^^^^^^^^^^^^^^^^^^^^^^^^^^
  File "/usr/lib/python3.11/asyncio/base_events.py", line 867, in getaddrinfo
    return await self.run_in_executor(
           ^^^^^^^^^^^^^^^^^^^^^^^^^^^
  File "/usr/lib/python3.11/concurrent/futures/thread.py", line 58, in run
    result = self.fn(*self.args, **self.kwargs)
             ^^^^^^^^^^^^^^^^^^^^^^^^^^^^^^^^^^
  File "/usr/lib/python3.11/socket.py", line 962, in getaddrinfo
    for res in _socket.getaddrinfo(host, port, family, type, proto, flags):
               ^^^^^^^^^^^^^^^^^^^^^^^^^^^^^^^^^^^^^^^^^^^^^^^^^^^^^^^^^^^
socket.gaierror: [Errno -3] Temporary failure in name resolution

The above exception was the direct cause of the following exception:

Traceback (most recent call last):
  File "/usr/lib/python3/dist-packages/discord/client.py", line 656, in connect
    self.ws = await asyncio.wait_for(coro, timeout=60.0)
              ^^^^^^^^^^^^^^^^^^^^^^^^^^^^^^^^^^^^^^^^^^
  File "/usr/lib/python3.11/asyncio/tasks.py", line 479, in wait_for
    return fut.result()
           ^^^^^^^^^^^^
  File "/usr/lib/python3/dist-packages/discord/gateway.py", line 372, in from_client
    socket = await client.http.ws_connect(str(url))
             ^^^^^^^^^^^^^^^^^^^^^^^^^^^^^^^^^^^^^^
  File "/usr/lib/python3/dist-packages/discord/http.py", line 536, in ws_connect
    return await self.__session.ws_connect(url, **kwargs)
           ^^^^^^^^^^^^^^^^^^^^^^^^^^^^^^^^^^^^^^^^^^^^^^
  File "/usr/lib/python3/dist-packages/aiohttp/client.py", line 779, in _ws_connect
    resp = await self.request(
           ^^^^^^^^^^^^^^^^^^^
  File "/usr/lib/python3/dist-packages/aiohttp/client.py", line 536, in _request
    conn = await self._connector.connect(
           ^^^^^^^^^^^^^^^^^^^^^^^^^^^^^^
  File "/usr/lib/python3/dist-packages/aiohttp/connector.py", line 540, in connect
    proto = await self._create_connection(req, traces, timeout)
            ^^^^^^^^^^^^^^^^^^^^^^^^^^^^^^^^^^^^^^^^^^^^^^^^^^^
  File "/usr/lib/python3/dist-packages/aiohttp/connector.py", line 901, in _create_connection
    _, proto = await self._create_direct_connection(req, traces, timeout)
               ^^^^^^^^^^^^^^^^^^^^^^^^^^^^^^^^^^^^^^^^^^^^^^^^^^^^^^^^^^
  File "/usr/lib/python3/dist-packages/aiohttp/connector.py", line 1166, in _create_direct_connection
    raise ClientConnectorError(req.connection_key, exc) from exc
aiohttp.client_exceptions.ClientConnectorError: Cannot connect to host gateway-us-east1-c.discord.gg:443 ssl:default [Temporary failure in name resolution]
2024-06-06 02:03:38,786 - discord_bot - ERROR - Failed to purge or send message in people-in-studio: Cannot connect to host discord.com:443 ssl:default [Temporary failure in name resolution]
